<?xml version="1.0" ?>
<!-- =================================================================================== -->
<!-- |    This document was autogenerated by xacro from cogimon_robot.urdf.xacro       | -->
<!-- |    EDITING THIS FILE BY HAND IS NOT RECOMMENDED                                 | -->
<!-- =================================================================================== -->
<robot name="cogimon" xmlns:xacro="http://ros.org/wiki/xacro">
  <!--
  ROS urdf definition of the COGIMON humanoid robot by Istituto Italiano di Tecnologia
  
  Author: Enrico Mingo
  
  This file groups files to use COGIMON in GAZEBO
  
  -->
  <!-- 
  ROS urdf definition of the COGIMON humanoid robot by Istituto Italiano di Tecnologia
  
  DO NOT INCLUDE THIS FILE DIRECTLY! USE cogimon_robot.urdf.xacro INSTEAD!

  Author: Enrico Mingo

  Inertial matrix has to be in CoM frame (URDF specs)
-->
  <!-- ************ SOME DEFS ********************** -->
  <!-- ************ MODEL CONFIGURATION ************ -->
  <!-- ************SELECT PARTS*************-->
  <!-- *************************************-->
  <!-- ************COGIMON_PENNACCHIO*******-->
  <!--
     This will add a fake torso link after the first
     torso joint (roll). If this is true, arms has
     to be false and torso has to be true.
-->
  <!-- *************************************-->
  <!-- ************FLOATING BASE*************-->
  <!-- ******************************************-->
  <!-- ************FIXED BASE*************-->
  <!-- ******************************************-->
  <!-- ************XBOT-GAZEBO FRAMEWORK*************-->
  <!-- *************************************-->
  <!-- ************OROCOS-GAZEBO FRAMEWORK*************-->
  <!-- *************************************-->
  <!-- ***********  MODEL COLORS *********** -->
  <material name="grey">
    <color rgba="0.5 0.5 0.5 1"/>
  </material>
  <material name="dark_grey">
    <color rgba="0.3 0.3 0.3 1"/>
  </material>
  <material name="red">
    <color rgba="1.0 0.0 0.0 1"/>
  </material>
  <material name="green">
    <color rgba="0.0 1.0 0.0 1"/>
  </material>
  <!-- Head -->
  <!-- This links are defined in order to be compliant with http://www.ros.org/reps/rep-0120.html#coordinate-frames
and to define the end effectors of the robot.
The coordinate frame called gaze defines the head position and orientation. The orientation indicates in which direction the head appears to be looking regardless of any sensors (camera for instance). -->
  <!--link name="gaze"/>

	<joint name="gaze_joint" type="fixed">
		<parent link="torso"/>
		<child link="gaze"/>
		<origin xyz="0 0 0.1" rpy="0 0 0" />
	</joint-->
  <!-- NECK -->
  <!--xacro:include filename="$(find cogimon_urdf)/urdf/parts/neck.urdf.xacro" /-->
  <!-- ************ COGIMON BASE ************** -->
  <!-- 
  ROS urdf definition of the COGIMON humanoid robot by Istituto Italiano di Tecnologia
  
  DO NOT INCLUDE THIS FILE DIRECTLY! USE cogimon_robot.urdf.xacro INSTEAD!

  Author: Enrico Mingo Hoffman

  Inertial matrix has to be in CoM frame (URDF specs)

-->
  <!-- This links are defined in order to be compliant with http://www.ros.org/reps/rep-0120.html#coordinate-frames
and to define the end effectors of the robot

The coordinate frame called base_link is rigidly attached to the robot root body. It is recommended to choose the robot waist as its root body. The base_link can be attached to the root in any arbitrary position or orientation; for every hardware platform there will be a different place on the base that provides an obvious point of reference. Note that REP 103 [1] specifies a preferred orientation for frames. -->
  <link name="base_link"/>
  <link name="Waist">
    <inertial>
      <origin rpy="0.0 0.0 0.0" xyz="-0.056796324 0.00045196345 -0.038136153"/>
      <mass value="3.4599462"/>
      <inertia ixx="0.038130318" ixy="9.5451056e-05" ixz="-8.2481481e-05" iyy="0.0089760596" iyz="9.1637353e-06" izz="0.039650845"/>
    </inertial>
    <visual>
      <origin rpy="0 0 0" xyz="0 0 0"/>
      <material name="dark_grey"/>
      <geometry name="Waist_visual">
        <mesh filename="model://iit-cogimon/meshes/Waist.stl" scale="0.001 0.001 0.001"/>
      </geometry>
    </visual>
    <collision>
      <origin rpy="0 0 0" xyz="0 0 0"/>
      <geometry name="Waist_collision">
        <mesh filename="model://iit-cogimon/meshes/simple/Waist.stl" scale="0.001 0.001 0.001"/>
      </geometry>
    </collision>
  </link>
  <joint name="base_joint" type="fixed">
    <parent link="base_link"/>
    <child link="Waist"/>
    <origin rpy="0 0 0" xyz="0 0 0"/>
  </joint>
  <!-- LINKS -->
  <link name="LHipMot">
    <inertial>
      <origin rpy="0 0 0" xyz="-0.041435899 -0.00024099021 -0.067437774"/>
      <mass value="2.0936467"/>
      <inertia ixx="0.010806924" ixy="3.3743172e-05" ixz="-0.0013329083" iyy="0.011288691" iyz="5.6918305e-05" izz="0.0053916798"/>
    </inertial>
    <visual>
      <origin rpy="0 0 0." xyz="0. 0. 0."/>
      <material name="green"/>
      <geometry name="RHipMot_visual">
        <mesh filename="model://iit-cogimon/meshes/HipRoll.stl" scale="0.001 0.001 0.001"/>
      </geometry>
    </visual>
    <collision>
      <origin rpy="0 0 0." xyz="0.0 0. 0"/>
      <geometry name="RHipMot_collision">
        <mesh filename="model://iit-cogimon/meshes/simple/HipRoll.stl" scale="0.001 0.001 0.001"/>
      </geometry>
    </collision>
  </link>
  <link name="LThighUpLeg">
    <inertial>
      <origin rpy="0 0 0" xyz="0.00058688639 -0.062440385 -0.085057072"/>
      <mass value="1.6115687"/>
      <inertia ixx="0.016169151" ixy="-2.1886129e-05" ixz="6.0058109e-05" iyy="0.0144378" iyz="-0.0027173225" izz="0.0039254506"/>
    </inertial>
    <visual>
      <origin rpy="0 0 0." xyz="0. 0. 0."/>
      <material name="dark_grey"/>
      <geometry name="LThighUpLeg_visual">
        <mesh filename="model://iit-cogimon/meshes/HipPitch.stl" scale="0.001 0.001 0.001"/>
      </geometry>
    </visual>
    <collision>
      <origin rpy="0 0 0." xyz="0.0 0. 0"/>
      <geometry name="LThighUpLeg_collision">
        <mesh filename="model://iit-cogimon/meshes/simple/HipPitch.stl" scale="0.001 0.001 0.001"/>
      </geometry>
    </collision>
  </link>
  <link name="LThighLowLeg">
    <inertial>
      <origin rpy="0 0 0" xyz="-0.02113641 -0.0042862386 -0.038232267"/>
      <mass value="1.7454681"/>
      <inertia ixx="0.0059857438" ixy="-4.0155441e-05" ixz="-0.00080168603" iyy="0.0066483492" iyz="-0.00011435964" izz="0.0044665032"/>
    </inertial>
    <visual>
      <origin rpy="0 0 0." xyz="0. 0. 0."/>
      <material name="green"/>
      <geometry name="LThighLowLeg_visual">
        <mesh filename="model://iit-cogimon/meshes/HipYaw.stl" scale="0.001 0.001 0.001"/>
      </geometry>
    </visual>
    <collision>
      <origin rpy="0 0 0." xyz="0.0 0. 0"/>
      <geometry name="LThighLowLeg_collision">
        <mesh filename="model://iit-cogimon/meshes/simple/HipYaw.stl" scale="0.001 0.001 0.001"/>
      </geometry>
    </collision>
  </link>
  <link name="LLowLeg">
    <inertial>
      <origin rpy="0 0 0" xyz="0.027363015 -0.05780207 -0.19306454"/>
      <mass value="3.7014912"/>
      <inertia ixx="0.064669769" ixy="0.00036914631" ixz="0.0053710941" iyy="0.063323486" iyz="-0.0027319883" izz="0.0081842652"/>
    </inertial>
    <visual>
      <origin rpy="0 0 0." xyz="0. 0. 0."/>
      <material name="dark_grey"/>
      <geometry name="LLowLeg_visual">
        <mesh filename="model://iit-cogimon/meshes/KneePitch.stl" scale="0.001 0.001 0.001"/>
      </geometry>
    </visual>
    <collision>
      <origin rpy="0 0 0." xyz="0.0 0. 0"/>
      <geometry name="LLowLeg_collision">
        <mesh filename="model://iit-cogimon/meshes/simple/KneePitch.stl" scale="0.001 0.001 0.001"/>
      </geometry>
    </collision>
  </link>
  <link name="LFootmot">
    <inertial>
      <origin rpy="0 0 0" xyz="0.0011213007 0.00046152281 -1.144967e-06"/>
      <mass value="1.7723821e-01"/>
      <inertia ixx="2.8142035e-05" ixy="9.1715528e-08" ixz="-2.1701012e-10" iyy="9.7378402e-05" iyz="3.7303915e-10" izz="0.00011570584"/>
    </inertial>
    <visual>
      <origin rpy="0 0 0" xyz="0 0 0"/>
      <geometry name="LFootmot_visual">
        <mesh filename="model://iit-cogimon/meshes/AnklePitch.stl" scale="0.001 0.001 0.001"/>
      </geometry>
      <material name="dark_grey"/>
    </visual>
    <collision>
      <origin rpy="0 0 0" xyz="0 0 0"/>
      <geometry name="LFootmot_collision">
        <mesh filename="model://iit-cogimon/meshes/simple/AnklePitch.stl" scale="0.001 0.001 0.001"/>
      </geometry>
    </collision>
  </link>
  <link name="LFoot">
    <inertial>
      <origin rpy="0 0 0" xyz="-0.0086960323 -6.6741928e-05 -0.041675435"/>
      <mass value="1.7819594e+00"/>
      <inertia ixx="0.0019182691" ixy="5.7926583e-06" ixz="0.00032836542" iyy="0.0053518735" iyz="-3.0518008e-06" izz="0.0064063918"/>
    </inertial>
    <visual>
      <origin rpy="0 0 0" xyz="0 0 0"/>
      <geometry name="LFoot_visual">
        <mesh filename="model://iit-cogimon/meshes/Foot.stl" scale="0.001 0.001 0.001"/>
      </geometry>
      <material name="dark_grey"/>
    </visual>
    <collision>
      <origin rpy="0 0 0" xyz="0.0 0.0 -0.046"/>
      <geometry>
        <box size="0.21 0.11 0.015"/>
      </geometry>
    </collision>
  </link>
  <!-- JOINTS -->
  <joint name="LHipLat" type="revolute">
    <parent link="Waist"/>
    <child link="LHipMot"/>
    <origin rpy="0 0 0" xyz="0.01545 0.112 -0.05"/>
    <axis xyz="1 0 0"/>
    <limit effort="235" lower="-0.523598775597" upper="1.65806278939" velocity="7.4"/>
    <dynamics damping="3.0" friction="0"/>
  </joint>
  <joint name="LHipSag" type="revolute">
    <parent link="LHipMot"/>
    <child link="LThighUpLeg"/>
    <origin rpy="0 0 0" xyz="-0.059 0.07865 -0.1185"/>
    <axis xyz="0 1 0"/>
    <limit effort="235" lower="-1.91986217719" upper="1.55334303427" velocity="7.4"/>
    <dynamics damping="3.0" friction="0"/>
  </joint>
  <joint name="LHipYaw" type="revolute">
    <parent link="LThighUpLeg"/>
    <child link="LThighLowLeg"/>
    <origin rpy="0 0 0" xyz="0.0 -0.09 -0.25645"/>
    <axis xyz="0 0 1"/>
    <limit effort="153" lower="-0.558505360637" upper="1.57079632679" velocity="4.6"/>
    <dynamics damping="3.0" friction="0"/>
  </joint>
  <joint name="LKneePitch" type="revolute">
    <parent link="LThighLowLeg"/>
    <child link="LLowLeg"/>
    <origin rpy="0 0 0" xyz="-0.039 0.0641 -0.0607"/>
    <axis xyz="0 1 0"/>
    <limit effort="313" lower="0.0" upper="2.44346095279" velocity="5.5"/>
    <dynamics damping="3.0" friction="0"/>
  </joint>
  <!-- Here we do an assumption: Ankle Pitch can go -50/+40 while Ankle Roll -15/+15-->
  <joint name="LAnklePitch" type="revolute">
    <parent link="LLowLeg"/>
    <child link="LFootmot"/>
    <origin rpy="0 0 0" xyz="0.039 -0.0616 -0.425294"/>
    <axis xyz="0 1 0"/>
    <limit effort="179" lower="-0.872664625995" upper="0.698131700796" velocity="4.9"/>
    <dynamics damping="0.1" friction="0"/>
  </joint>
  <joint name="LAnkleRoll" type="revolute">
    <parent link="LFootmot"/>
    <child link="LFoot"/>
    <origin rpy="0 0 0" xyz="0 0 0"/>
    <axis xyz="1 0 0"/>
    <limit effort="230" lower="-0.261799387798" upper="0.261799387798" velocity="3.2"/>
    <dynamics damping="3.0" friction="0"/>
  </joint>
  <!-- LINKS -->
  <link name="RHipMot">
    <inertial>
      <origin rpy="0 0 0" xyz="-0.041435899 0.00024099021 -0.067437774"/>
      <mass value="2.0936467"/>
      <inertia ixx="0.010806924" ixy="-3.3743172e-05" ixz="-0.0013329083" iyy="0.011288691" iyz="-5.6918305e-05" izz="0.0053916798"/>
    </inertial>
    <visual>
      <origin rpy="0 0 0" xyz="0.0 0 0"/>
      <material name="green"/>
      <geometry name="RHipMot_visual">
        <mesh filename="model://iit-cogimon/meshes/HipRoll.stl" scale="0.001 -0.001 0.001"/>
      </geometry>
    </visual>
    <collision>
      <origin rpy="0 0 0." xyz="0.0 0. 0"/>
      <geometry name="RHipMot_collision">
        <mesh filename="model://iit-cogimon/meshes/simple/HipRoll.stl" scale="0.001 -0.001 0.001"/>
      </geometry>
    </collision>
  </link>
  <link name="RThighUpLeg">
    <inertial>
      <origin rpy="0 0 0" xyz="0.00058688639 0.062440385 -0.085057072"/>
      <mass value="1.6115687"/>
      <inertia ixx="0.016169151" ixy="2.1886129e-05" ixz="6.0058109e-05" iyy="0.0144378" iyz="0.0027173225" izz="0.0039254506"/>
    </inertial>
    <visual>
      <origin rpy="0 0 0." xyz="0. 0. 0."/>
      <material name="dark_grey"/>
      <geometry name="RThighUpLeg_visual">
        <mesh filename="model://iit-cogimon/meshes/HipPitch.stl" scale="0.001 -0.001 0.001"/>
      </geometry>
    </visual>
    <collision>
      <origin rpy="0 0 0." xyz="0.0 0. 0"/>
      <geometry name="RThighUpLeg_collision">
        <mesh filename="model://iit-cogimon/meshes/simple/HipPitch.stl" scale="0.001 -0.001 0.001"/>
      </geometry>
    </collision>
  </link>
  <link name="RThighLowLeg">
    <inertial>
      <origin rpy="0 0 0" xyz="-0.02113641 0.0042862386 -0.038232267"/>
      <mass value="1.7454681"/>
      <inertia ixx="0.0059857438" ixy="4.0155441e-05" ixz="-0.00080168603" iyy="0.0066483492" iyz="0.00011435964" izz="0.0044665032"/>
    </inertial>
    <visual>
      <origin rpy="0 0 0." xyz="0. 0. 0."/>
      <material name="green"/>
      <geometry name="RThighLowLeg_visual">
        <mesh filename="model://iit-cogimon/meshes/HipYaw.stl" scale="0.001 -0.001 0.001"/>
      </geometry>
    </visual>
    <collision>
      <origin rpy="0 0 0." xyz="0.0 0. 0"/>
      <geometry name="RThighLowLeg_collision">
        <mesh filename="model://iit-cogimon/meshes/simple/HipYaw.stl" scale="0.001 -0.001 0.001"/>
      </geometry>
    </collision>
  </link>
  <link name="RLowLeg">
    <inertial>
      <origin rpy="0 0 0" xyz="0.027363015 0.05780207 -0.19306454"/>
      <mass value="3.7014912"/>
      <inertia ixx="0.064669769" ixy="-0.00036914631" ixz="0.0053710941" iyy="0.063323486" iyz="0.0027319883" izz="0.0081842652"/>
    </inertial>
    <visual>
      <origin rpy="0 0 0." xyz="0. 0. 0."/>
      <material name="dark_grey"/>
      <geometry name="RLowLeg_visual">
        <mesh filename="model://iit-cogimon/meshes/KneePitch.stl" scale="0.001 -0.001 0.001"/>
      </geometry>
    </visual>
    <collision>
      <origin rpy="0 0 0." xyz="0.0 0. 0"/>
      <geometry name="RLowLeg_collision">
        <mesh filename="model://iit-cogimon/meshes/simple/KneePitch.stl" scale="0.001 -0.001 0.001"/>
      </geometry>
    </collision>
  </link>
  <link name="RFootmot">
    <inertial>
      <origin rpy="0 0 0" xyz="0.0011213007 0.00046152281 -1.144967e-06"/>
      <mass value="1.7723821e-01"/>
      <inertia ixx="2.8142035e-05" ixy="9.1715528e-08" ixz="-2.1701012e-10" iyy="9.7378402e-05" iyz="3.7303915e-10" izz="0.00011570584"/>
    </inertial>
    <visual>
      <origin rpy="0 0 0" xyz="0 0 0"/>
      <geometry name="RFootmot_visual">
        <mesh filename="model://iit-cogimon/meshes/AnklePitch.stl" scale="0.001 0.001 0.001"/>
      </geometry>
      <material name="dark_grey"/>
    </visual>
    <collision>
      <origin rpy="0 0 0" xyz="0 0 0"/>
      <geometry name="RFootmot_collision">
        <mesh filename="model://iit-cogimon/meshes/simple/AnklePitch.stl" scale="0.001 0.001 0.001"/>
      </geometry>
    </collision>
  </link>
  <link name="RFoot">
    <inertial>
      <origin rpy="0 0 0" xyz="-0.0086960323 -6.6741928e-05 -0.041675435"/>
      <mass value="1.7819594e+00"/>
      <inertia ixx="0.0019182691" ixy="5.7926583e-06" ixz="0.00032836542" iyy="0.0053518735" iyz="-3.0518008e-06" izz="0.0064063918"/>
    </inertial>
    <visual>
      <origin rpy="0 0 0" xyz="0 0 0"/>
      <geometry name="RFoot_visual">
        <mesh filename="model://iit-cogimon/meshes/Foot.stl" scale="0.001 0.001 0.001"/>
      </geometry>
      <material name="dark_grey"/>
    </visual>
    <collision>
      <origin rpy="0 0 0" xyz="0.0 0.0 -0.046"/>
      <geometry>
        <box size="0.21 0.11 0.015"/>
      </geometry>
    </collision>
  </link>
  <!-- JOINTS -->
  <joint name="RHipLat" type="revolute">
    <parent link="Waist"/>
    <child link="RHipMot"/>
    <origin rpy="0 0 0" xyz="0.01545 -0.112 -0.05"/>
    <axis xyz="1 0 0"/>
    <limit effort="235" lower="-1.65806278939" upper="0.523598775597" velocity="7.4"/>
    <dynamics damping="3.0" friction="0"/>
  </joint>
  <joint name="RHipSag" type="revolute">
    <parent link="RHipMot"/>
    <child link="RThighUpLeg"/>
    <origin rpy="0 0 0" xyz="-0.059 -0.07865 -0.1185"/>
    <axis xyz="0 1 0"/>
    <limit effort="235" lower="-1.91986217719" upper="1.55334303427" velocity="7.4"/>
    <dynamics damping="3.0" friction="0"/>
  </joint>
  <joint name="RHipYaw" type="revolute">
    <parent link="RThighUpLeg"/>
    <child link="RThighLowLeg"/>
    <origin rpy="0 0 0" xyz="0.0 0.09 -0.25645"/>
    <axis xyz="0 0 1"/>
    <limit effort="153" lower="-1.57079632679" upper="0.558505360637" velocity="4.9"/>
    <dynamics damping="3.0" friction="0"/>
  </joint>
  <joint name="RKneePitch" type="revolute">
    <parent link="RThighLowLeg"/>
    <child link="RLowLeg"/>
    <origin rpy="0 0 0" xyz="-0.039 -0.0641 -0.0607"/>
    <axis xyz="0 1 0"/>
    <limit effort="313" lower="0.0" upper="2.44346095279" velocity="5.5"/>
    <dynamics damping="3.0" friction="0"/>
  </joint>
  <!-- Here we do an assumption: Ankle Pitch can go -50/+40 while Ankle Roll -15/+15-->
  <joint name="RAnklePitch" type="revolute">
    <parent link="RLowLeg"/>
    <child link="RFootmot"/>
    <origin rpy="0 0 0" xyz="0.039 0.0616 -0.425294"/>
    <axis xyz="0 1 0"/>
    <limit effort="179" lower="-0.872664625995" upper="0.698131700796" velocity="4.9"/>
    <dynamics damping="0.1" friction="0"/>
  </joint>
  <joint name="RAnkleRoll" type="revolute">
    <parent link="RFootmot"/>
    <child link="RFoot"/>
    <origin rpy="0 0 0" xyz="0 0 0"/>
    <axis xyz="1 0 0"/>
    <limit effort="230" lower="-0.261799387798" upper="0.261799387798" velocity="3.2"/>
    <dynamics damping="3.0" friction="0"/>
  </joint>
  <!-- weight diameter -->
  <!-- weight radius -->
  <!-- weight height, here we consider three discs -->
  <!-- weight mass -->
  <!-- weight position -->
  <!-- LINKS -->
  <link name="DWL">
    <inertial>
      <origin rpy="0 0 0" xyz="0.039412845 0.00031221526 0.0056331027 "/>
      <mass value="7.4182685e-01"/>
      <inertia ixx="0.00094437073" ixy="4.8511769e-06" ixz="0.00010757639" iyy="0.0015988107" iyz="-1.104754e-05" izz="0.0015042997"/>
    </inertial>
    <visual>
      <origin rpy="0 0 0" xyz="0.0 0.0 0.0"/>
      <geometry name="DWL_visual">
        <mesh filename="model://iit-cogimon/meshes/TorsoRoll.stl" scale="0.001 0.001 0.001"/>
      </geometry>
      <material name="dark_grey"/>
    </visual>
    <collision>
      <origin rpy="0 0 0" xyz="0.0 0.0 0.0"/>
      <geometry name="DWL_collision">
        <mesh filename="model://iit-cogimon/meshes/simple/TorsoRoll.stl" scale="0.001 0.001 0.001"/>
      </geometry>
    </collision>
  </link>
  <link name="weight">
    <inertial>
      <origin rpy="0 0 0" xyz="0 0 0 "/>
      <mass value="30.0"/>
      <inertia ixx="0.0316875" ixy="0" ixz="0" iyy="0.0316875" iyz="0" izz="0.045375"/>
    </inertial>
    <visual>
      <origin rpy="0 0 0" xyz="0 0 0"/>
      <geometry>
        <cylinder length="0.06" radius="0.055"/>
      </geometry>
    </visual>
    <collision>
      <origin rpy="0 0 0" xyz="0 0 0"/>
      <geometry>
        <cylinder length="0.06" radius="0.055"/>
      </geometry>
    </collision>
  </link>
  <link name="pennacchio">
    <inertial>
      <origin rpy="0 0 0" xyz="-3.4081174e-06 -3.4081174e-06 0.17247336 "/>
      <mass value="2.1651618"/>
      <inertia ixx="0.045713534" ixy="1.9747985e-08" ixz="5.9794097e-07" iyy="0.045712755" iyz="-2.6722676e-07" izz="0.00060311791"/>
    </inertial>
    <visual>
      <origin rpy="0 0 0" xyz="0.0 0.0 0.0"/>
      <geometry name="pennacchio_visual">
        <mesh filename="model://iit-cogimon/meshes/Pennacchio.stl" scale="0.001 0.001 0.001"/>
      </geometry>
      <material name="dark_grey"/>
    </visual>
    <collision>
      <origin rpy="0 0 0" xyz="0.0 0.0 0.0"/>
      <geometry name="pennacchio_collision">
        <mesh filename="model://iit-cogimon/meshes/simple/Pennacchio.stl" scale="0.001 0.001 0.001"/>
      </geometry>
    </collision>
  </link>
  <!-- JOINTS -->
  <joint name="WaistLat" type="revolute">
    <parent link="Waist"/>
    <child link="DWL"/>
    <origin rpy="0 0 0" xyz="0.012 0.0 0.0"/>
    <axis xyz="1 0 0"/>
    <limit effort="150" lower="-0.523598775597" upper="0.523598775597" velocity="7.4"/>
    <dynamics damping="3.0" friction="0"/>
  </joint>
  <joint name="pennacchio_frame" type="fixed">
    <parent link="DWL"/>
    <child link="pennacchio"/>
    <origin rpy="0 0 0" xyz="-0.0540957 0.0 0.0665"/>
  </joint>
  <joint name="weight_frame" type="fixed">
    <parent link="pennacchio"/>
    <child link="weight"/>
    <origin rpy="0 0 0" xyz="0. 0. 0.2"/>
  </joint>
  <!-- ************ REF FRAMES **************** -->
  <link name="l_ankle"/>
  <link name="l_sole"/>
  <link name="l_toe"/>
  <link name="l_heel"/>
  <link name="l_leg_ft"/>
  <joint name="l_leg_ft_joint" type="fixed">
    <origin rpy="0 0 0" xyz="0 0 -0.035"/>
    <parent link="LFoot"/>
    <child link="l_leg_ft"/>
  </joint>
  <joint name="l_ankle_joint" type="fixed">
    <origin rpy="0 0 0" xyz="0 0 0"/>
    <parent link="LFoot"/>
    <child link="l_ankle"/>
  </joint>
  <joint name="l_sole_joint" type="fixed">
    <origin rpy="0 0 0" xyz="0 0 -0.054"/>
    <parent link="l_ankle"/>
    <child link="l_sole"/>
  </joint>
  <joint name="l_toe_joint" type="fixed">
    <origin rpy="0 0 0" xyz="0.107 0 0"/>
    <parent link="l_sole"/>
    <child link="l_toe"/>
  </joint>
  <joint name="l_heel_joint" type="fixed">
    <origin rpy="0 0 0" xyz="-0.1035 0 0"/>
    <parent link="l_sole"/>
    <child link="l_heel"/>
  </joint>
  <link name="l_foot_upper_right_link"/>
  <joint name="l_foot_upper_right_joint" type="fixed">
    <origin rpy="0 0 0" xyz="0.107 -0.055 0"/>
    <parent link="l_sole"/>
    <child link="l_foot_upper_right_link"/>
  </joint>
  <link name="l_foot_upper_left_link"/>
  <joint name="l_foot_upper_left_joint" type="fixed">
    <origin rpy="0 0 0" xyz="0.107 0.055 0"/>
    <parent link="l_sole"/>
    <child link="l_foot_upper_left_link"/>
  </joint>
  <link name="l_foot_lower_right_link"/>
  <joint name="l_foot_lower_right_joint" type="fixed">
    <origin rpy="0 0 0" xyz="-0.1035 -0.055 0"/>
    <parent link="l_sole"/>
    <child link="l_foot_lower_right_link"/>
  </joint>
  <link name="l_foot_lower_left_link"/>
  <joint name="l_foot_lower_left_joint" type="fixed">
    <origin rpy="0 0 0" xyz="-0.1035 0.055 0"/>
    <parent link="l_sole"/>
    <child link="l_foot_lower_left_link"/>
  </joint>
  <link name="r_ankle"/>
  <link name="r_sole"/>
  <link name="r_toe"/>
  <link name="r_heel"/>
  <link name="r_leg_ft"/>
  <joint name="r_leg_ft_joint" type="fixed">
    <origin rpy="0 0 0" xyz="0 0 -0.035"/>
    <parent link="RFoot"/>
    <child link="r_leg_ft"/>
  </joint>
  <joint name="r_ankle_joint" type="fixed">
    <origin rpy="0 0 0" xyz="0 0 0"/>
    <parent link="RFoot"/>
    <child link="r_ankle"/>
  </joint>
  <joint name="r_sole_joint" type="fixed">
    <origin rpy="0 0 0" xyz="0 0 -0.054"/>
    <parent link="r_ankle"/>
    <child link="r_sole"/>
  </joint>
  <joint name="r_toe_joint" type="fixed">
    <origin rpy="0 0 0" xyz="0.107 0 0"/>
    <parent link="r_sole"/>
    <child link="r_toe"/>
  </joint>
  <joint name="r_heel_joint" type="fixed">
    <origin rpy="0 0 0" xyz="-0.1035 0 0"/>
    <parent link="r_sole"/>
    <child link="r_heel"/>
  </joint>
  <link name="r_foot_upper_right_link"/>
  <joint name="r_foot_upper_right_joint" type="fixed">
    <origin rpy="0 0 0" xyz="0.107 -0.055 0"/>
    <parent link="r_sole"/>
    <child link="r_foot_upper_right_link"/>
  </joint>
  <link name="r_foot_upper_left_link"/>
  <joint name="r_foot_upper_left_joint" type="fixed">
    <origin rpy="0 0 0" xyz="0.107 0.055 0"/>
    <parent link="r_sole"/>
    <child link="r_foot_upper_left_link"/>
  </joint>
  <link name="r_foot_lower_right_link"/>
  <joint name="r_foot_lower_right_joint" type="fixed">
    <origin rpy="0 0 0" xyz="-0.1035 -0.055 0"/>
    <parent link="r_sole"/>
    <child link="r_foot_lower_right_link"/>
  </joint>
  <link name="r_foot_lower_left_link"/>
  <joint name="r_foot_lower_left_joint" type="fixed">
    <origin rpy="0 0 0" xyz="-0.1035 0.055 0"/>
    <parent link="r_sole"/>
    <child link="r_foot_lower_left_link"/>
  </joint>
  <link name="world"/>
  <joint name="reference" type="floating">
    <parent link="world"/>
    <child link="base_link"/>
  </joint>
  <!-- contact model for foot surface -->
  <gazebo reference="LFoot">
    <kp>1000000.0</kp>
    <kd>100.0</kd>
    <mu1>1.0</mu1>
    <mu2>1.0</mu2>
    <fdir1>1 0 0</fdir1>
    <maxVel>1.0</maxVel>
    <minDepth>0.0</minDepth>
  </gazebo>
  <gazebo reference="RFoot">
    <kp>1000000.0</kp>
    <kd>100.0</kd>
    <mu1>1.0</mu1>
    <mu2>1.0</mu2>
    <fdir1>1 0 0</fdir1>
    <maxVel>1.0</maxVel>
    <minDepth>0.00</minDepth>
  </gazebo>
  <!-- Other parameters... -->
  <gazebo reference="RHipSag">
    <implicitSpringDamper>1</implicitSpringDamper>
    <provideFeedback>true</provideFeedback>
  </gazebo>
  <gazebo reference="RHipLat">
    <implicitSpringDamper>1</implicitSpringDamper>
    <provideFeedback>true</provideFeedback>
  </gazebo>
  <gazebo reference="RHipYaw">
    <implicitSpringDamper>1</implicitSpringDamper>
    <provideFeedback>true</provideFeedback>
  </gazebo>
  <gazebo reference="RKneePitch">
    <implicitSpringDamper>1</implicitSpringDamper>
    <provideFeedback>true</provideFeedback>
  </gazebo>
  <gazebo reference="RAnkleRoll">
    <implicitSpringDamper>1</implicitSpringDamper>
    <provideFeedback>true</provideFeedback>
  </gazebo>
  <gazebo reference="RAnklePitch">
    <implicitSpringDamper>1</implicitSpringDamper>
    <provideFeedback>true</provideFeedback>
  </gazebo>
  <gazebo reference="LHipSag">
    <implicitSpringDamper>1</implicitSpringDamper>
    <provideFeedback>true</provideFeedback>
  </gazebo>
  <gazebo reference="LHipLat">
    <implicitSpringDamper>1</implicitSpringDamper>
    <provideFeedback>true</provideFeedback>
  </gazebo>
  <gazebo reference="LHipYaw">
    <implicitSpringDamper>1</implicitSpringDamper>
    <provideFeedback>true</provideFeedback>
  </gazebo>
  <gazebo reference="LKneePitch">
    <implicitSpringDamper>1</implicitSpringDamper>
    <provideFeedback>true</provideFeedback>
  </gazebo>
  <gazebo reference="LAnkleRoll">
    <implicitSpringDamper>1</implicitSpringDamper>
    <provideFeedback>true</provideFeedback>
  </gazebo>
  <gazebo reference="LAnklePitch">
    <implicitSpringDamper>1</implicitSpringDamper>
    <provideFeedback>true</provideFeedback>
  </gazebo>
  <gazebo reference="WaistLat">
    <implicitSpringDamper>1</implicitSpringDamper>
    <provideFeedback>true</provideFeedback>
  </gazebo>
  <gazebo reference="Waist">
    <material>Gazebo/DarkGrey</material>
  </gazebo>
  <gazebo reference="RHipMot">
    <material>Gazebo/Green</material>
  </gazebo>
  <gazebo reference="RThighUpLeg">
    <material>Gazebo/DarkGrey</material>
  </gazebo>
  <gazebo reference="RThighLowLeg">
    <material>Gazebo/Green</material>
  </gazebo>
  <gazebo reference="RLowLeg">
    <material>Gazebo/DarkGrey</material>
  </gazebo>
  <gazebo reference="RFootmot">
    <material>Gazebo/DarkGrey</material>
  </gazebo>
  <gazebo reference="RFoot">
    <material>Gazebo/DarkGrey</material>
  </gazebo>
  <gazebo reference="LHipMot">
    <material>Gazebo/Green</material>
  </gazebo>
  <gazebo reference="LThighUpLeg">
    <material>Gazebo/DarkGrey</material>
  </gazebo>
  <gazebo reference="LThighLowLeg">
    <material>Gazebo/Green</material>
  </gazebo>
  <gazebo reference="LLowLeg">
    <material>Gazebo/DarkGrey</material>
  </gazebo>
  <gazebo reference="LFootmot">
    <material>Gazebo/DarkGrey</material>
  </gazebo>
  <gazebo reference="LFoot">
    <material>Gazebo/DarkGrey</material>
  </gazebo>
  <gazebo reference="DWL">
    <material>Gazebo/DarkGrey</material>
  </gazebo>
  <gazebo reference="pennacchio">
    <material>Gazebo/DarkGrey</material>
  </gazebo>
  <gazebo reference="LAnkleRoll">
    <sensor name="left_leg" type="force_torque">
      <force_torque>
        <frame>sensor</frame>
        <measure_direction>child_to_parent</measure_direction>
      </force_torque>
      <always_on>true</always_on>
      <visualize>true</visualize>
      <update_rate>1000</update_rate>
      <pose>0 0 -0.035 0 0 0</pose>
      <!-- check! -->
    </sensor>
  </gazebo>
  <gazebo reference="RAnkleRoll">
    <sensor name="right_leg" type="force_torque">
      <force_torque>
        <frame>sensor</frame>
        <measure_direction>child_to_parent</measure_direction>
      </force_torque>
      <always_on>true</always_on>
      <visualize>true</visualize>
      <update_rate>1000</update_rate>
      <pose>0 0 -0.035 0 0 0</pose>
      <!-- check! -->
    </sensor>
  </gazebo>
  <origin rpy="0 0 0" xyz="0.0 0.0 0.97"/>
</robot>

