<?xml version='1.0'?>
<sdf version='1.4'>
  <model name='ur5'>
    <link name='base_link'>
      <pose>0 0 0 0 -0 0</pose>
      <inertial>
        <pose>0 0 0 0 -0 0</pose>
        <mass>4</mass>
        <inertia>
          <ixx>1</ixx>
          <ixy>0</ixy>
          <ixz>0</ixz>
          <iyy>1</iyy>
          <iyz>0</iyz>
          <izz>1</izz>
        </inertia>
      </inertial>
      <collision name='base_link_collision'>
        <pose>0 0 0 0 -0 0</pose>
        <geometry>
          <mesh>
            <scale>1 1 1</scale>
            <uri>model://universal-robot-ur5/meshes/ur5/collision/Base.dae</uri>
          </mesh>
        </geometry>
      </collision>
      <visual name='base_link_visual'>
        <pose>0 0 0.003 0 -0 2.35619</pose>
        <geometry>
          <mesh>
            <scale>1 1 1</scale>
            <uri>model://universal-robot-ur5/meshes/ur5/visual/Base.dae</uri>
          </mesh>
        </geometry>
      </visual>
      <velocity_decay>
        <linear>0</linear>
        <angular>0</angular>
      </velocity_decay>
    </link>
    <joint name='arm_world_joint' type='revolute'>
      <child>base_link</child>
      <parent>world</parent>
      <axis>
        <limit>
          <lower>0</lower>
          <upper>0</upper>
        </limit>
        <dynamics>
          <damping>0</damping>
          <friction>0</friction>
          <spring_reference>0</spring_reference>
          <spring_stiffness>0</spring_stiffness>
        </dynamics>
        <xyz>0 0 1</xyz>
      </axis>
    </joint>
    <link name='shoulder_link'>
      <pose>0 0 0.089159 0 -0 0</pose>
      <inertial>
        <pose>0 0.00193 -0.02561 0 -0 0</pose>
        <mass>3.7</mass>
        <inertia>
          <ixx>1</ixx>
          <ixy>0</ixy>
          <ixz>0</ixz>
          <iyy>1</iyy>
          <iyz>0</iyz>
          <izz>1</izz>
        </inertia>
      </inertial>
      <collision name='shoulder_link_collision'>
        <pose>0 0 0 0 -0 0</pose>
        <geometry>
          <mesh>
            <scale>1 1 1</scale>
            <uri>model://universal-robot-ur5/meshes/ur5/collision/Shoulder.dae</uri>
          </mesh>
        </geometry>
      </collision>
      <visual name='shoulder_link_visual'>
        <pose>0 0 0 0 -0 0</pose>
        <geometry>
          <mesh>
            <scale>1 1 1</scale>
            <uri>model://universal-robot-ur5/meshes/ur5/visual/Shoulder.dae</uri>
          </mesh>
        </geometry>
      </visual>
      <velocity_decay>
        <linear>0</linear>
        <angular>0</angular>
      </velocity_decay>
    </link>
    <joint name='shoulder_pan_joint' type='revolute'>
      <child>shoulder_link</child>
      <parent>base_link</parent>
      <axis>
        <xyz>0 0 1</xyz>
        <limit>
          <lower>-6.28319</lower>
          <upper>6.28319</upper>
          <effort>10</effort>
          <velocity>3.14159</velocity>
        </limit>
        <dynamics>
          <damping>10</damping>
        </dynamics>
      </axis>
    </joint>
    <link name='upper_arm_link'>
      <pose>0 0.13585 0.089159 3.14159 1.57079 3.14159</pose>
      <inertial>
        <pose>0 -0.024201 0.2125 0 -0 0</pose>
        <mass>8.393</mass>
        <inertia>
          <ixx>1</ixx>
          <ixy>0</ixy>
          <ixz>0</ixz>
          <iyy>1</iyy>
          <iyz>0</iyz>
          <izz>1</izz>
        </inertia>
      </inertial>
      <collision name='upper_arm_link_collision'>
        <pose>0 0 0 0 -0 0</pose>
        <geometry>
          <mesh>
            <scale>1 1 1</scale>
            <uri>model://universal-robot-ur5/meshes/ur5/collision/UpperArm.dae</uri>
          </mesh>
        </geometry>
      </collision>
      <visual name='upper_arm_link_visual'>
        <pose>0 0 0 0 -0 0</pose>
        <geometry>
          <mesh>
            <scale>1 1 1</scale>
            <uri>model://universal-robot-ur5/meshes/ur5/visual/UpperArm.dae</uri>
          </mesh>
        </geometry>
      </visual>
      <velocity_decay>
        <linear>0</linear>
        <angular>0</angular>
      </velocity_decay>
    </link>
    <joint name='shoulder_lift_joint' type='revolute'>
      <child>upper_arm_link</child>
      <parent>shoulder_link</parent>
      <axis>
        <xyz>0 1 0</xyz>
        <limit>
          <lower>-6.28319</lower>
          <upper>6.28319</upper>
          <effort>10</effort>
          <velocity>3.14159</velocity>
        </limit>
        <dynamics>
          <damping>10</damping>
        </dynamics>
      </axis>
    </joint>
    <link name='forearm_link'>
      <pose>0.425 0.01615 0.089159 3.14159 1.57079 3.14159</pose>
      <inertial>
        <pose>0 0.0265 0.11993 0 -0 0</pose>
        <mass>2.275</mass>
        <inertia>
          <ixx>1</ixx>
          <ixy>0</ixy>
          <ixz>0</ixz>
          <iyy>1</iyy>
          <iyz>0</iyz>
          <izz>1</izz>
        </inertia>
      </inertial>
      <collision name='forearm_link_collision'>
        <pose>0 0 0 0 -0 0</pose>
        <geometry>
          <mesh>
            <scale>1 1 1</scale>
            <uri>model://universal-robot-ur5/meshes/ur5/collision/Forearm.dae</uri>
          </mesh>
        </geometry>
      </collision>
      <visual name='forearm_link_visual'>
        <pose>0 0 0 0 -0 0</pose>
        <geometry>
          <mesh>
            <scale>1 1 1</scale>
            <uri>model://universal-robot-ur5/meshes/ur5/visual/Forearm.dae</uri>
          </mesh>
        </geometry>
      </visual>
      <velocity_decay>
        <linear>0</linear>
        <angular>0</angular>
      </velocity_decay>
    </link>
    <joint name='elbow_joint' type='revolute'>
      <child>forearm_link</child>
      <parent>upper_arm_link</parent>
      <axis>
        <xyz>0 1 0</xyz>
        <limit>
          <lower>-6.28319</lower>
          <upper>6.28319</upper>
          <effort>10</effort>
          <velocity>3.14159</velocity>
        </limit>
        <dynamics>
          <damping>10</damping>
        </dynamics>
      </axis>
    </joint>
    <link name='wrist_1_link'>
      <pose>0.81725 0.01615 0.089159 3.14159 3.58979e-09 3.14159</pose>
      <inertial>
        <pose>0 0.110949 0.01634 0 -0 0</pose>
        <mass>1.219</mass>
        <inertia>
          <ixx>1</ixx>
          <ixy>0</ixy>
          <ixz>0</ixz>
          <iyy>1</iyy>
          <iyz>0</iyz>
          <izz>1</izz>
        </inertia>
      </inertial>
      <collision name='wrist_1_link_collision'>
        <pose>0 0.093 0 3.14159 1.57079 3.14159</pose>
        <geometry>
          <mesh>
            <scale>1 1 1</scale>
            <uri>model://universal-robot-ur5/meshes/ur5/collision/Wrist1.dae</uri>
          </mesh>
        </geometry>
      </collision>
      <visual name='wrist_1_link_visual'>
        <pose>0 0.093 0 3.14159 1.57079 3.14159</pose>
        <geometry>
          <mesh>
            <scale>1 1 1</scale>
            <uri>model://universal-robot-ur5/meshes/ur5/visual/Wrist1.dae</uri>
          </mesh>
        </geometry>
      </visual>
      <velocity_decay>
        <linear>0</linear>
        <angular>0</angular>
      </velocity_decay>
    </link>
    <joint name='wrist_1_joint' type='revolute'>
      <child>wrist_1_link</child>
      <parent>forearm_link</parent>
      <axis>
        <xyz>0 1 0</xyz>
        <limit>
          <lower>-3.14159</lower>
          <upper>0.785398</upper>
          <effort>10</effort>
          <velocity>3.14159</velocity>
        </limit>
        <dynamics>
          <damping>10</damping>
        </dynamics>
      </axis>
    </joint>
    <link name='wrist_2_link'>
      <pose>0.81725 0.10915 0.089159 3.14159 3.58979e-09 3.14159</pose>
      <inertial>
        <pose>0 0.0018 0.11099 0 -0 0</pose>
        <mass>1.219</mass>
        <inertia>
          <ixx>1</ixx>
          <ixy>0</ixy>
          <ixz>0</ixz>
          <iyy>1</iyy>
          <iyz>0</iyz>
          <izz>1</izz>
        </inertia>
      </inertial>
      <collision name='wrist_2_link_collision'>
        <pose>0 0 0.09465 0 -0 0</pose>
        <geometry>
          <mesh>
            <scale>1 1 1</scale>
            <uri>model://universal-robot-ur5/meshes/ur5/collision/Wrist2.dae</uri>
          </mesh>
        </geometry>
      </collision>
      <visual name='wrist_2_link_visual'>
        <pose>0 0 0.09465 0 -0 0</pose>
        <geometry>
          <mesh>
            <scale>1 1 1</scale>
            <uri>model://universal-robot-ur5/meshes/ur5/visual/Wrist2.dae</uri>
          </mesh>
        </geometry>
      </visual>
      <velocity_decay>
        <linear>0</linear>
        <angular>0</angular>
      </velocity_decay>
    </link>
    <joint name='wrist_2_joint' type='revolute'>
      <child>wrist_2_link</child>
      <parent>wrist_1_link</parent>
      <axis>
        <xyz>3.58979e-09 0 -1</xyz>
        <limit>
          <lower>-3.14159</lower>
          <upper>3.14159</upper>
          <effort>10</effort>
          <velocity>3.14159</velocity>
        </limit>
        <dynamics>
          <damping>10</damping>
        </dynamics>
      </axis>
    </joint>
    <link name='wrist_3_link'>
      <pose>0.81725 0.10915 -0.005491 3.14159 3.58979e-09 3.14159</pose>
      <inertial>
        <pose>0 0.001159 0 0 -0 0</pose>
        <mass>0.1879</mass>
        <inertia>
          <ixx>1</ixx>
          <ixy>0</ixy>
          <ixz>0</ixz>
          <iyy>1</iyy>
          <iyz>0</iyz>
          <izz>1</izz>
        </inertia>
      </inertial>
      <collision name='wrist_3_link_collision'>
        <pose>0 0 0 0 -0 0</pose>
        <geometry>
          <mesh>
            <scale>1 1 1</scale>
            <uri>model://universal-robot-ur5/meshes/ur5/collision/Wrist3.dae</uri>
          </mesh>
        </geometry>
      </collision>
      <visual name='wrist_3_link_visual'>
        <pose>0 0 0 0 -0 0</pose>
        <geometry>
          <mesh>
            <scale>1 1 1</scale>
            <uri>model://universal-robot-ur5/meshes/ur5/visual/Wrist3.dae</uri>
          </mesh>
        </geometry>
      </visual>
      <velocity_decay>
        <linear>0</linear>
        <angular>0</angular>
      </velocity_decay>
    </link>
    <joint name='wrist_3_joint' type='revolute'>
      <child>wrist_3_link</child>
      <parent>wrist_2_link</parent>
      <axis>
        <xyz>0 1 0</xyz>
        <limit>
          <lower>-3.14159</lower>
          <upper>3.14159</upper>
          <effort>10</effort>
          <velocity>3.14159</velocity>
        </limit>
        <dynamics>
          <damping>10</damping>
        </dynamics>
      </axis>
    </joint>
<link name='ee_link'>
<pose>0 0 -0 0 0 0</pose>
      <inertial>
        <pose>0 0 1 0 -0 0</pose>
        <mass>0</mass>
        <inertia>
          <ixx>0</ixx>
          <ixy>0</ixy>
          <ixz>0</ixz>
          <iyy>0</iyy>
          <iyz>0</iyz>
          <izz>0</izz>
        </inertia>
      </inertial>
      <collision name='ee_link_collision'>
        <pose>0.025 0 0 0 -0 0</pose>
        <geometry>
          <box size="0.05 0.05 0.05"/>
        </geometry>
      </collision>
      <visual name='ee_link_visual'>
        <pose>0.025 0 0 0 -0 0</pose>
        <geometry>
        <box size="0.05 0.05 0.05"/>
      </geometry>
      </visual>
      <velocity_decay>
        <linear>0</linear>
        <angular>0</angular>
      </velocity_decay>
  </link>



     <pose frame=''>0 0 0 0 -0 0</pose>
  </model>
</sdf>

