<?xml version="1.0" ?>
<!-- =================================================================================== -->
<!-- |    This document was autogenerated by xacro from ur5_robot.urdf.xacro           | -->
<!-- |    EDITING THIS FILE BY HAND IS NOT RECOMMENDED                                 | -->
<!-- |    Forked from: https://github.com/cpaxton/universal_robot                      | -->
<!-- |    Origin from: https://github.com/ros-industrial/universal_robot               | -->
<!-- =================================================================================== -->
<robot name="universal-robot-ur5" xmlns:controller="http://playerstage.sourceforge.net/gazebo/xmlschema/#controller" xmlns:interface="http://playerstage.sourceforge.net/gazebo/xmlschema/#interface" xmlns:sensor="http://playerstage.sourceforge.net/gazebo/xmlschema/#sensor" xmlns:xacro="http://ros.org/wiki/xacro">
  <material name="UR/Blue">
    <color rgba="0.0 0.0 0.8 1.0"/>
  </material>
  <material name="UR/Grey">
    <color rgba="0.7 0.7 0.7 1.0"/>
  </material>
 <!-- world -->
  <!-- Used for fixing robots 'base_link' to Gazebos 'world' -->
  <link name="world"/>
  <joint name="fixed" type="fixed">
    <parent link="world"/>
    <child link="base_link"/>
  </joint>
<!-- arm -->
  <link name="base_link">
    <visual>
      <geometry>
        <mesh filename="package://./meshes/ur5/visual/Base.dae"/>
      </geometry>
      <origin rpy="0.0 0.0 2.3561944875" xyz="0.0 0.0 0.0"/>
    </visual>
    <collision>
      <geometry>
        <mesh filename="package://./meshes/ur5/collision/Base.dae"/>
      </geometry>
      <!-- <origin rpy="0.0 0.0 0.0" xyz="0.0 0.0 -0.009159"/> -->
    </collision>
    <inertial>
      <mass value="4.0"/>
      <inertia ixx="0.004433" ixy="0.0" ixz="0.0" iyy="0.00443333156" iyz="0.0" izz="0.0072"/>
    </inertial>
  </link> 
<!-- <inertia ixx="0.0833333 * 4.0 * (3 * 0.06 * 0.06 + 0.05 * 0.05)" ixy="0.0" ixz="0.0"
        iyy="0.0833333 * 4.0 * (3 * 0.06 * 0.06 + 0.05 * 0.05)" iyz="0.0"
        izz="0.5 * 4.0 * 0.06 * 0.06" /> -->
  <joint name="shoulder_pan_joint" type="revolute">
    <parent link="base_link"/>
    <child link="shoulder_link"/>
    <origin rpy="0.0 0.0 0.0" xyz="0.0 0.0 0.089159"/>
    <axis xyz="0 0 1"/>
    <limit effort="150.0" lower="-6.2831853" upper="6.2831853" velocity="3.14159265"/>
    <dynamics damping="0.5" friction="0.0"/>
  </joint>
  <link name="shoulder_link">
    <visual>
      <geometry>
        <mesh filename="package://./meshes/ur5/visual/Shoulder.dae"/>
      </geometry>
    </visual>
    <collision>
      <geometry>
        <mesh filename="package://./meshes/ur5/collision/Shoulder.dae"/>
      </geometry>
      <!-- <origin rpy="0.0 0.0 0.0" xyz="0.0 0.0 -0.009159"/> -->
    </collision>
    <inertial>
      <mass value="3.7"/>
      <inertia ixx="0.010267495893" ixy="0.0" ixz="0.0" iyy="0.010267495893" iyz="0.0" izz="0.00666"/>
      <origin rpy="0.0 0.0 0.0" xyz="0.0 0.00 -0.0"/>
    </inertial>
  </link>
<!--<inertia ixx="0.0833333 * 3.7 * (3 * 0.06 * 0.06 + 0.15 * 0.15)" ixy="0.0" ixz="0.0"
        iyy="0.0833333 * 3.7 * (3 * 0.06 * 0.06 + 0.15 * 0.15)" iyz="0.0"
        izz="0.5 * 3.7 * 0.06 * 0.06" /> -->
  <joint name="shoulder_lift_joint" type="revolute">
    <parent link="shoulder_link"/>
    <child link="upper_arm_link"/>
    <origin rpy="0.0 1.570796325 0.0" xyz="0.0 0.13585 0.0"/>
    <axis xyz="0 1 0"/>
    <limit effort="150.0" lower="-6.2831853" upper="6.2831853" velocity="3.14159265"/>
    <dynamics damping="0.5" friction="0.0"/>
  </joint>
  <link name="upper_arm_link">
    <visual>
      <geometry>
        <mesh filename="package://./meshes/ur5/visual/UpperArm.dae"/>
      </geometry>
      <origin rpy="0.0 0.0 0.0" xyz="0.0 0.0 0.0"/>
    </visual>
    <collision>
      <geometry>
        <mesh filename="package://./meshes/ur5/collision/UpperArm.dae"/>
      </geometry>
      <!--       <origin rpy="0.0 0.0 0.0" xyz="0.0 0.0 0.2125"/> -->
    </collision>
    <inertial>
      <mass value="8.393"/>
      <inertia ixx="0.22689067591036" ixy="0.0" ixz="0.0" iyy="0.22689067591036" iyz="0.0" izz="0.0151074" />
      <origin rpy="0.0 0.0 0.0" xyz="0.0 0.0 0.28"/>
    </inertial>
  </link>
 <!--    <inertia ixx="0.0833333 * 8.393 * (3 * 0.06 * 0.06 + 0.56 * 0.56)" ixy="0.0" ixz="0.0"
        iyy="0.0833333 * 8.393 * (3 * 0.06 * 0.06 + 0.56 * 0.56)" iyz="0.0"
        izz="0.5 * 8.393 * 0.06 * 0.06" />-->
  <joint name="elbow_joint" type="revolute">
    <parent link="upper_arm_link"/>
    <child link="forearm_link"/>
    <origin rpy="0.0 0.0 0.0" xyz="0.0 -0.1197 0.425"/>
    <axis xyz="0 1 0"/>
    <limit effort="150.0" lower="-6.2831853" upper="6.2831853" velocity="3.14159265"/>
    <dynamics damping="0.5" friction="0.0"/>
  </joint>
  <link name="forearm_link">
    <visual>
      <geometry>
        <mesh filename="package://./meshes/ur5/visual/Forearm.dae"/>
      </geometry>
    </visual>
    <collision>
      <geometry>
        <mesh filename="package://./meshes/ur5/collision/Forearm.dae"/>
      </geometry>
      <!--       <origin rpy="0.0 0.0 0.0" xyz="0.0 0.0 0.196125"/> -->
    </collision>
    <inertial>
      <mass value="2.275"/>
      <origin rpy="0.0 0.0 0.0" xyz="0.0 0.0265 0.11993"/> 
      <inertia ixx="0.049443313556" ixy="0.0" ixz="0.0" iyy="0.049443313556" iyz="0.0" izz="0.004095" />
    </inertial>
  </link>
 <!--    <inertia ixx="0.0833333 * 2.275 * (3 * 0.06 * 0.06 + 0.5 * 0.5)" ixy="0.0" ixz="0.0"
        iyy="0.0833333 * 2.275 * (3 * 0.06 * 0.06 + 0.5 * 0.5)" iyz="0.0"
        izz="0.5 * 2.275 * 0.06 * 0.06" /> -->
  <joint name="wrist_1_joint" type="revolute">
    <parent link="forearm_link"/>
    <child link="wrist_1_link"/>
    <origin rpy="0.0 1.570796325 0.0" xyz="0.0 0.0 0.39225"/>
    <axis xyz="0 1 0"/>
    <limit effort="28.0" lower="-3.14159265" upper="0.7853981625" velocity="3.14159265"/>
    <dynamics damping="0.5" friction="0.0"/>
  </joint>
  <link name="wrist_1_link">
    <visual>
      <geometry>
        <mesh filename="package://./meshes/ur5/visual/Wrist1.dae"/>
      </geometry>
      <origin rpy="0.0 1.570796325 0.0" xyz="0.0 0.093 0.0"/>
    </visual>
    <collision>
      <geometry>
        <mesh filename="package://./meshes/ur5/collision/Wrist1.dae"/>
      </geometry>
      <origin rpy="0.0 1.570796325 0.0" xyz="0.0 0.093 0.0"/>
    </collision>
    <inertial>
      <mass value="1.219"/>
      <origin rpy="0.0 0.0 0.0" xyz="0.0 0.0 0.0"/>
       <inertia ixx="0.11117275553088" ixy="0.0" ixz="0.0" iyy="0.11117275553088" iyz="0.0" izz="0.21942" />
    </inertial>
  </link>
<!--    <inertia ixx="0.0833333 * 1.219 * (3 * 0.6 * 0.6 + 0.12 * 0.12)" ixy="0.0" ixz="0.0"
        iyy="0.0833333 * 1.219 * (3 * 0.6 * 0.6 + 0.12 * 0.12)" iyz="0.0"
        izz="0.5 * 1.219 * 0.6 * 0.6" /> -->
  <joint name="wrist_2_joint" type="revolute">
    <parent link="wrist_1_link"/>
    <child link="wrist_2_link"/>
    <origin rpy="0.0 0.0 0.0" xyz="0.0 0.093 0.0"/>
    <axis xyz="0 0 1"/>
    <limit effort="28.0" lower="-3.14159265" upper="3.14159265" velocity="3.14159265"/>
    <dynamics damping="0.5" friction="0.0"/>
  </joint>
  <link name="wrist_2_link">
    <visual>
      <geometry>
        <mesh filename="package://./meshes/ur5/visual/Wrist2.dae"/>
      </geometry>
      <origin rpy="0.0 0.0 0.0" xyz="0.0 0.0 0.09465"/>
    </visual>
    <collision>
      <geometry>
        <mesh filename="package://./meshes/ur5/collision/Wrist2.dae"/>
      </geometry>
      <origin rpy="0.0 0.0 0.0" xyz="0.0 0.0 0.09465"/>
    </collision>
    <inertial>
      <mass value="1.219"/>
      <origin rpy="0.0 0.0 0.0" xyz="0.0 0.0 0.0"/>
      <inertia ixx="0.11117275553088" ixy="0.0" ixz="0.0" iyy="0.11117275553088" iyz="0.0" izz="0.21942" />
    </inertial>
  </link>
<!--    <inertia ixx="0.0833333 * 1.219 * (3 * 0.6 * 0.6 + 0.12 * 0.12)" ixy="0.0" ixz="0.0"
        iyy="0.0833333 * 1.219 * (3 * 0.6 * 0.6 + 0.12 * 0.12)" iyz="0.0"
        izz="0.5 * 1.219 * 0.6 * 0.6" /> -->
  <joint name="wrist_3_joint" type="revolute">
    <parent link="wrist_2_link"/>
    <child link="wrist_3_link"/>
    <origin rpy="0.0 0.0 0.0" xyz="0.0 0.0 0.09465"/>
    <axis xyz="0 1 0"/>
    <limit effort="28.0" lower="-3.14159265" upper="3.14159265" velocity="3.14159265"/>
    <dynamics damping="0.5" friction="0.0"/>
  </joint>
  <link name="wrist_3_link">
    <visual>
      <geometry>
        <mesh filename="package://./meshes/ur5/visual/Wrist3.dae"/>
      </geometry>
    </visual>
    <collision>
      <geometry>
        <mesh filename="package://./meshes/ur5/collision/Wrist3.dae"/>
      </geometry>
    </collision>
    <inertial>
      <mass value="0.1879"/>
      <origin rpy="0.0 0.0 0.0" xyz="0.0 0.0 0.0"/>
      <inertia ixx="0.017136473145408" ixy="0.0" ixz="0.0" iyy="0.017136473145408" iyz="0.0" izz="0.033822" />
    </inertial>
  </link>
<!--     <inertia ixx="0.0833333 * 0.1879 * (3 * 0.6 * 0.6 + 0.12 * 0.12)" ixy="0.0" ixz="0.0"
        iyy="0.0833333 * 0.1879 * (3 * 0.6 * 0.6 + 0.12 * 0.12)" iyz="0.0"
        izz="0.5 * 0.1879 * 0.6 * 0.6" />-->
  <joint name="ee_fixed_joint" type="fixed">
    <parent link="wrist_3_link"/>
    <child link="ee_link"/>
    <origin rpy="0.0 0.0 1.570796325" xyz="0.0 0.0823 0.0"/>
  </joint>
  <link name="ee_link"/>
  <xacro:ur_arm_transmission name=""/>
  <!--gazebo reference="universal_robot">
    <material>Gazebo/Blue</material>
  </gazebo-->
</robot>


