<?xml version="1.0" ?>
<!-- =================================================================================== -->
<!-- |    This document was autogenerated by xacro from panda_arm.urdf.xacro           | -->
<!-- |    EDITING THIS FILE BY HAND IS NOT RECOMMENDED                                 | -->
<!-- =================================================================================== -->
<robot name="panda" xmlns:xacro="http://www.ros.org/wiki/xacro">
  <link name="panda_link0">
    <inertial>
      <mass value="1.2"/>
      <com rpy="0 0 0" xyz="0 0 0.055"/>
      <inertia ixx="0.00229" ixy="0" ixz="0" iyy="0.00216" iyz="0" izz="0.00229"/>
    </inertial>
    <visual>
      <geometry>
        <mesh filename="model://franka_panda_arm/meshes/visual/link0.dae"/>
      </geometry>
    </visual>
    <collision>
      <geometry>
        <mesh filename="model://franka_panda_arm/meshes/collision/link0.stl"/>
      </geometry>
    </collision>
  </link>
  <link name="panda_link1">
    <inertial>
      <mass value="2.0" />
      <origin rpy="0 0 0" xyz="0 0 0.130" />
      <inertia ixx="0.0136666666667" ixy="0" ixz="0" iyy="0.0118666666667" iyz="0" izz="0.003" />
    </inertial>
    <visual>
      <geometry>
        <mesh filename="model://franka_panda_arm/meshes/visual/link1.dae"/>
      </geometry>
    </visual>
    <collision>
      <geometry>
        <mesh filename="model://franka_panda_arm/meshes/collision/link1.stl"/>
      </geometry>
    </collision>
  </link>
  <joint name="panda_joint1" type="revolute">
    <safety_controller k_position="100.0" k_velocity="40.0" soft_lower_limit="-2.8973" soft_upper_limit="2.8973"/>
    <origin rpy="0 0 0" xyz="0 0 0.333"/>
    <parent link="panda_link0"/>
    <child link="panda_link1"/>
    <axis xyz="0 0 1"/>
    <limit effort="87" lower="-2.9671" upper="2.9671" velocity="2.3925"/>
  </joint>
  <link name="panda_link2">
    <inertial>
      <mass value="2.0" />
      <origin rpy="0 0 0" xyz="0 -0.06 0.07" />
      <inertia ixx="0.0136666666667" ixy="0" ixz="0" iyy="0.0118666666667" iyz="0" izz="0.003" />
    </inertial>
    <visual>
      <geometry>
        <mesh filename="model://franka_panda_arm/meshes/visual/link2.dae"/>
      </geometry>
    </visual>
    <collision>
      <geometry>
        <mesh filename="model://franka_panda_arm/meshes/collision/link2.stl"/>
      </geometry>
    </collision>
  </link>
  <joint name="panda_joint2" type="revolute">
    <safety_controller k_position="100.0" k_velocity="40.0" soft_lower_limit="-1.7628" soft_upper_limit="1.7628"/>
    <origin rpy="-1.57079632679 0 0" xyz="0 0 0"/>
    <parent link="panda_link1"/>
    <child link="panda_link2"/>
    <axis xyz="0 0 1"/>
    <limit effort="87" lower="-1.8326" upper="1.8326" velocity="2.3925"/>
  </joint>
  <link name="panda_link3">
    <inertial>
      <mass value="2.0" />
      <origin rpy="0 0 0" xyz="0 -0.06 0.130" />
      <inertia ixx="0.0136666666667" ixy="0" ixz="0" iyy="0.0118666666667" iyz="0" izz="0.003" />
    </inertial>
    <visual>
      <geometry>
        <mesh filename="model://franka_panda_arm/meshes/visual/link3.dae"/>
      </geometry>
    </visual>
    <collision>
      <geometry>
        <mesh filename="model://franka_panda_arm/meshes/collision/link3.stl"/>
      </geometry>
    </collision>
  </link>
  <joint name="panda_joint3" type="revolute">
    <safety_controller k_position="100.0" k_velocity="40.0" soft_lower_limit="-2.8973" soft_upper_limit="2.8973"/>
    <origin rpy="1.57079632679 0 0" xyz="0 -0.316 0"/>
    <parent link="panda_link2"/>
    <child link="panda_link3"/>
    <axis xyz="0 0 1"/>
    <limit effort="87" lower="-2.9671" upper="2.9671" velocity="2.3925"/>
  </joint>
  <link name="panda_link4">
    <inertial>
      <mass value="2.0" />
      <origin rpy="0 0 0" xyz="0 0.06 0.07" />
      <inertia ixx="0.0136666666667" ixy="0" ixz="0" iyy="0.0118666666667" iyz="0" izz="0.003" />
    </inertial>
    <visual>
      <geometry>
        <mesh filename="model://franka_panda_arm/meshes/visual/link4.dae"/>
      </geometry>
    </visual>
    <collision>
      <geometry>
        <mesh filename="model://franka_panda_arm/meshes/collision/link4.stl"/>
      </geometry>
    </collision>
  </link>
  <joint name="panda_joint4" type="revolute">
    <safety_controller k_position="100.0" k_velocity="40.0" soft_lower_limit="-3.0718" soft_upper_limit="0.0175"/>
    <origin rpy="1.57079632679 0 0" xyz="0.0825 0 0"/>
    <parent link="panda_link3"/>
    <child link="panda_link4"/>
    <axis xyz="0 0 1"/>
    <limit effort="87" lower="-3.1416" upper="0.0873" velocity="2.3925"/>
  </joint>
  <link name="panda_link5">
    <inertial>
      <mass value="2.0" />
      <origin rpy="0 0 0" xyz="0 0 0.124" />
      <inertia ixx="0.0126506666667" ixy="0" ixz="0" iyy="0.0108506666667" iyz="0" izz="0.003" />
    </inertial>
    <visual>
      <geometry>
        <mesh filename="model://franka_panda_arm/meshes/visual/link5.dae"/>
      </geometry>
    </visual>
    <collision>
      <geometry>
        <mesh filename="model://franka_panda_arm/meshes/collision/link5.stl"/>
      </geometry>
    </collision>
  </link>
  <joint name="panda_joint5" type="revolute">
    <safety_controller k_position="100.0" k_velocity="40.0" soft_lower_limit="-2.8973" soft_upper_limit="2.8973"/>
    <origin rpy="-1.57079632679 0 0" xyz="-0.0825 0.384 0"/>
    <parent link="panda_link4"/>
    <child link="panda_link5"/>
    <axis xyz="0 0 1"/>
    <limit effort="12" lower="-2.9671" upper="2.9671" velocity="2.8710"/>
  </joint>
  <link name="panda_link6">
    <inertial>
      <mass value="1.0" />
      <origin rpy="0 0 0" xyz="0 0 0.0" />
      <inertia ixx="0.00260416666667" ixy="0" ixz="0" iyy="0.00260416666667" iyz="0" izz="0.00260416666667" />
    </inertial>
    <visual>
      <geometry>
        <mesh filename="model://franka_panda_arm/meshes/visual/link6.dae"/>
      </geometry>
    </visual>
    <collision>
      <geometry>
        <mesh filename="model://franka_panda_arm/meshes/collision/link6.stl"/>
      </geometry>
    </collision>
  </link>
  <joint name="panda_joint6" type="revolute">
    <safety_controller k_position="100.0" k_velocity="40.0" soft_lower_limit="-0.0175" soft_upper_limit="3.7525"/>
    <origin rpy="1.57079632679 0 0" xyz="0 0 0"/>
    <parent link="panda_link5"/>
    <child link="panda_link6"/>
    <axis xyz="0 0 1"/>
    <limit effort="12" lower="-0.0873" upper="3.8223" velocity="2.8710"/>
  </joint>
  <link name="panda_link7">
    <inertial>
      <mass value="0.2" />
      <origin xyz="0 0 0" />
      <inertia ixx="6.66666666667e-05" ixy="0" ixz="0" iyy="6.66666666667e-05" iyz="0" izz="0.00012" />
    </inertial>
    <visual>
      <geometry>
        <mesh filename="model://franka_panda_arm/meshes/visual/link7.dae"/>
      </geometry>
    </visual>
    <collision>
      <geometry>
        <mesh filename="model://franka_panda_arm/meshes/collision/link7.stl"/>
      </geometry>
    </collision>
  </link>
  <joint name="panda_joint7" type="revolute">
    <safety_controller k_position="100.0" k_velocity="40.0" soft_lower_limit="-2.8973" soft_upper_limit="2.8973"/>
    <origin rpy="1.57079632679 0 0" xyz="0.088 0 0"/>
    <parent link="panda_link6"/>
    <child link="panda_link7"/>
    <axis xyz="0 0 1"/>
    <limit effort="12" lower="-2.9671" upper="2.9671" velocity="2.8710"/>
  </joint>
  <link name="panda_link8"/>
  <joint name="panda_joint8" type="fixed">
    <origin rpy="0 0 0" xyz="0 0 0.107"/>
    <parent link="panda_link7"/>
    <child link="panda_link8"/>
    <axis xyz="0 0 0"/>
  </joint>
</robot>
