<?xml version="1.0" ?>
<robot name="kuka-omnirob" xmlns:controller="http://playerstage.sourceforge.net/gazebo/xmlschema/#controller" xmlns:interface="http://playerstage.sourceforge.net/gazebo/xmlschema/#interface" xmlns:sensor="http://playerstage.sourceforge.net/gazebo/xmlschema/#sensor" xmlns:xacro="http://www.ros.org/wiki/xacro">
	<material name="DarkGrey">
        <color rgba="0.3 0.3 0.3 1.0" />
    </material>
    <material name="Red">
        <color rgba="0.3 0.3 0.3 1.0" />
    </material>
    <material name="Black">
        <color rgba="0 0 0 1.0" />
    </material>
    <material name="Orange">
        <color rgba="1.0 0.487 0 1.0" />
    </material>
    <material name="Silver">
        <color rgba="1.0 1.0 1.0 1.0" />
    </material>
    <material name="Grey">
        <color rgba="0.7 0.7 0.7 1.0" />
    </material>
    <material name="Blue">
        <color rgba="0.0 0.0 0.8 1.0" />
    </material>
    <material name="HandGray">
        <color rgba="0.953 0.996 0.694 1.0" />
    </material>
    <material name="SickBlue">
        <color rgba="0.3058 0.5921 0.7294 1.0" />
    </material>
    <!--static>true</static-->
    <link name="base_link">
        <inertial>
			<mass value="250" />
			<origin rpy="0 .0 0" xyz="0 -0.00000 0.24" />
			<inertia ixx="25.77086" ixy="-0.0" ixz="-0.0" iyy="53.79704" iyz="-0.0" izz="58.79601" />
		</inertial>
		<visual>
			<origin rpy="0 0 0" xyz="0 0 0" />
			<geometry>
				<mesh filename="model://kuka-omnirob/meshes/omnirobBaseRot.dae" scale="1 1 1" />
			</geometry>
		</visual>
		<collision>
			<!--<origin rpy="0 0 0" xyz="0 0 0" />
			<geometry>
				<mesh filename="model://kuka-omnirob/meshes/omnirobBaseRot.dae" scale="1 1 1" />
			</geometry> -->
			<origin rpy="0 0 0" xyz="0 0 0.35" />
			<geometry>
				<box size="0.915855 0.547 0.585000"/>
         	</geometry>
		</collision>
	</link>
    <gazebo reference="base_link">
    </gazebo>

	<link name="fr_laser_link">
		<inertial>
			<mass value="0.01" />
			<origin rpy="0 0 0" xyz="0.0 0.0 0.0" />
			<inertia ixx="1" ixy="0" ixz="0" iyy="1" iyz="0" izz="1" />
		</inertial>
		<visual>
			<origin rpy="0 0 0" xyz="0 0 0" />
			<geometry>
				<mesh filename="model://kuka-omnirob/meshes/hokuyo.dae" scale="1 1 1" />
			</geometry>
		</visual>
		<collision>
			<origin rpy="0 0 0" xyz="0 0 0" />
			<geometry>
				<mesh filename="model://kuka-omnirob/meshes/hokuyo.dae" scale="1 1 1" />
			</geometry>
		</collision>
	</link>
	<gazebo reference="fr_laser_link">
      <sensor type="ray" name="laser_front">
        <pose>0 0 0 0 0 0</pose>
        <visualize>false</visualize>
        <update_rate>40</update_rate>
        <ray>
          <scan>
            <horizontal>
              <samples>350</samples>
              <resolution>1</resolution>
              <min_angle>-3.141593</min_angle>
              <max_angle>1.570796</max_angle>
            </horizontal>
          </scan>
          <range>
            <min>0.10</min>
            <max>30.0</max>
            <resolution>0.01</resolution>
          </range>
          <noise>
            <type>gaussian</type>
            <mean>0.0</mean>
            <stddev>0.01</stddev>
          </noise>
        </ray>
		<plugin name="fr_laser_link" filename="libRayPlugin.so" />
      </sensor>
    </gazebo>

	<joint name="fr_laser_joint" type="fixed">
		<origin rpy="0 0 0" xyz="0.56029 -0.33 0.13937" />
		<parent link="base_link" />
		<child link="fr_laser_link" />
	</joint>
	<gazebo reference="fr_laser_joint">
	</gazebo>

	<link name="bl_laser_link">
		<inertial>
			<mass value="0.01" />
			<origin rpy="0 0 -1.570796" xyz="0.0 0.0 0.0" />
			<inertia ixx="1" ixy="0" ixz="0" iyy="1" iyz="0" izz="1" />
		</inertial>
		<visual>
			<origin rpy="0 0 0" xyz="0 0 0" />
			<geometry>
				<mesh filename="model://kuka-omnirob/meshes/hokuyo.dae" scale="1 1 1" />
			</geometry>
		</visual>
		<collision>
			<origin rpy="0 0 0" xyz="0 0 0" />
			<geometry>
				<mesh filename="model://kuka-omnirob/meshes/hokuyo.dae" scale="1 1 1" />
			</geometry>
		</collision>
	</link>
	<gazebo reference="bl_laser_link">
      <sensor type="ray" name="laser_back">
        <pose>0 0 0 0 0 0</pose>
        <visualize>false</visualize>
        <update_rate>40</update_rate>
        <ray>
          <scan>
            <horizontal>
              <samples>350</samples>
              <resolution>1</resolution>
              <min_angle>0</min_angle>
              <max_angle>4.71239</max_angle>
            </horizontal>
          </scan>
          <range>
            <min>0.10</min>
            <max>30.0</max>
            <resolution>0.01</resolution>
          </range>
          <noise>
            <type>gaussian</type>
            <mean>0.0</mean>
            <stddev>0.01</stddev>
          </noise>
        </ray>
		<plugin name="bl_laser_link" filename="libRayPlugin.so" />
      </sensor>
    </gazebo> 

	<joint name="bl_laser_joint" type="fixed">
		<origin rpy="0 0 0" xyz="-0.56029 0.33 0.13937" />
		<parent link="base_link" />
		<child link="bl_laser_link" />
	</joint>
	<gazebo reference="bl_laser_joint">
	</gazebo>


  <link name="bl_wheel">
		<inertial>
			<origin rpy="0 0 0" xyz="0 0 0" />
			<inertia ixx="0.012412" ixy="-0.000712" ixz="0.000503" iyy="0.015218" iyz="-0.000004" izz="0.011764" />
			<mass value="0.400000" />
		</inertial>
		<visual>
			<origin rpy="0 0 0" xyz="0 0.037 0" />
			<geometry>
				<mesh filename="model://kuka-omnirob/meshes/omnirobBLWheelRot.dae" scale="1 1 1" />
			</geometry>
		</visual>
		<collision>
			<origin rpy="1.5708 0 0" xyz="0 0 0" />
			<geometry>
				<cylinder length="0.005" radius="0.125"/>
			</geometry>
			<surface>
			<friction>
				<ode>
				<mu>0</mu>
				<mu2>0</mu2>
				<fdir1>0 0 0</fdir1>
				<slip1>0</slip1>
				<slip2>0</slip2>
				</ode>
			</friction>
			<bounce>
				<restitution_coefficient>0</restitution_coefficient>
				<threshold>0</threshold>
			</bounce>
			<contact>
				<ode>
				<soft_cfm>0</soft_cfm>
				<soft_erp>0.200000</soft_erp>
				<kp>10000000000000.000000</kp>
				<kd>100000000000.000000</kd>
				<min_depth>0</min_depth>
				</ode>
			</contact>
			</surface>
			<laser_retro>0</laser_retro>
		</collision>
	</link>
	<gazebo reference="bl_wheel_link">
	</gazebo>

	<joint name="bl_wheel_joint" type="continuous">
		<origin rpy="0 3.14159 0" xyz="-0.347000 0.242000 0.130000" />
		<axis xyz="0 1 0" />
		<parent link="base_link" />
		<child link="bl_wheel" />
	</joint>
	<gazebo reference="bl_wheel_joint">
	</gazebo>

	<origin xyz="0 0 0" rpy="0 0 0" />

	<link name="br_wheel">
		<inertial>
			<origin rpy="0 0 0" xyz="0 0 0" />
			<inertia ixx="0.012412" ixy="-0.000712" ixz="0.000503" iyy="0.015218" iyz="-0.000004" izz="0.011764" />
			<mass value="0.400000" />
		</inertial>
		<visual>
			<origin rpy="0 0 0" xyz="0 -0.0 0" />
			<geometry>
				<mesh filename="model://kuka-omnirob/meshes/omnirobBRWheelRot.dae" scale="1 1 1" />
			</geometry>
		</visual>
		<collision>
			<origin rpy="1.5708 0 0" xyz="0 0 0" />
			<geometry>
				<cylinder length="0.005" radius="0.125"/>
			</geometry>
			<surface>
			<friction>
				<ode>
				<mu>0</mu>
				<mu2>0</mu2>
				<fdir1>0 0 0</fdir1>
				<slip1>0</slip1>
				<slip2>0</slip2>
				</ode>
			</friction>
			<bounce>
				<restitution_coefficient>0</restitution_coefficient>
				<threshold>0</threshold>
			</bounce>
			<contact>
				<ode>
				<soft_cfm>0</soft_cfm>
				<soft_erp>0.200000</soft_erp>
				<kp>10000000000000.000000</kp>
				<kd>100000000000.000000</kd>
				<min_depth>0</min_depth>
				</ode>
			</contact>
			</surface>
			<laser_retro>0</laser_retro>
		</collision>
	</link>
	<gazebo reference="br_wheel_link">
	</gazebo>

	<joint name="br_wheel_joint" type="continuous">
		<origin rpy="0 0 0" xyz="-0.347000 -0.242000 0.130000" />
		<axis xyz="0 1 0" />
		<parent link="base_link" />
		<child link="br_wheel" />
	</joint>
	<gazebo reference="br_wheel_joint">
	</gazebo>

	<link name="fr_wheel">
		<inertial>
			<origin rpy="0 0 0" xyz="0 0 0" />
			<inertia ixx="0.012412" ixy="-0.000712" ixz="0.000503" iyy="0.015218" iyz="-0.000004" izz="0.011764" />
			<mass value="0.400000" />
		</inertial>
		<visual>
			<origin rpy="0 0 0" xyz="0 -0.0 0" />
			<geometry>
				<mesh filename="model://kuka-omnirob/meshes/omnirobFRWheelRot.dae" scale="1 1 1" />
			</geometry>
		</visual>
		<collision>
			<origin rpy="1.5708 0 0" xyz="0 0 0" />
			<geometry>
				<cylinder length="0.005" radius="0.125"/>
			</geometry>
			<surface>
			<friction>
				<ode>
				<mu>0</mu>
				<mu2>0</mu2>
				<fdir1>0 0 0</fdir1>
				<slip1>0</slip1>
				<slip2>0</slip2>
				</ode>
			</friction>
			<bounce>
				<restitution_coefficient>0</restitution_coefficient>
				<threshold>0</threshold>
			</bounce>
			<contact>
				<ode>
				<soft_cfm>0</soft_cfm>
				<soft_erp>0.200000</soft_erp>
				<kp>10000000000000.000000</kp>
				<kd>100000000000.000000</kd>
				<min_depth>0</min_depth>
				</ode>
			</contact>
			</surface>
			<laser_retro>0</laser_retro>
		</collision>
	</link>
	<gazebo reference="fr_wheel_link">
	</gazebo>

	<joint name="fr_wheel_joint" type="continuous">
		<origin rpy="0 0 0" xyz="0.347000 -0.242000 0.130000" />
		<axis xyz="0 1 0" />
		<parent link="base_link" />
		<child link="fr_wheel" />
	</joint>
	<gazebo reference="fr_wheel_joint">
	</gazebo>

	<link name="fl_wheel">
		<inertial>
			<origin rpy="0 0 0" xyz="0 0 0" />
			<inertia ixx="0.012412" ixy="-0.000712" ixz="0.000503" iyy="0.015218" iyz="-0.000004" izz="0.011764" />
			<mass value="0.400000" />
		</inertial>
		<visual>
			<origin rpy="0 0 0" xyz="0 0.0 0" />
			<geometry>
				<mesh filename="model://kuka-omnirob/meshes/omnirobFLWheelRot.dae" scale="1 1 1" />
			</geometry>
		</visual>
		<collision>
			<origin rpy="1.5708 0 0" xyz="0 0 0" />
			<geometry>
				<cylinder length="0.005" radius="0.125"/>
			</geometry>
			<surface>
			<friction>
				<ode>
				<mu>0</mu>
				<mu2>0</mu2>
				<fdir1>0 0 0</fdir1>
				<slip1>0</slip1>
				<slip2>0</slip2>
				</ode>
			</friction>
			<bounce>
				<restitution_coefficient>0</restitution_coefficient>
				<threshold>0</threshold>
			</bounce>
			<contact>
				<ode>
				<soft_cfm>0</soft_cfm>
				<soft_erp>0.200000</soft_erp>
				<kp>10000000000000.000000</kp>
				<kd>100000000000.000000</kd>
				<min_depth>0</min_depth>
				</ode>
			</contact>
			</surface>
			<laser_retro>0</laser_retro>
		</collision>
	</link>
	<gazebo reference="fl_wheel_link">
	</gazebo>

	<joint name="fl_wheel_joint" type="continuous">
		<origin rpy="0 0 0" xyz="0.347000 0.242000 0.130000" />
		<axis xyz="0 1 0" />
		<parent link="base_link" />
		<child link="fl_wheel" />
	</joint>
	<gazebo reference="fl_wheel_joint">
	</gazebo>



<!-- kuka left -->
<link name="left_lwr_arm_base_link">
        <inertial>
            <mass value="1.2" />
            <origin rpy="0 0 0" xyz="0 0 0.055" />
            <inertia ixx="0.00229" ixy="0" ixz="0" iyy="0.00216" iyz="0" izz="0.00229" />
        </inertial>
        <visual>
            <origin rpy="0 0 0" xyz="0 0 0" />
            <geometry>
                <mesh filename="model://kuka-lwr-4plus/meshes/arm_base.dae" scale="100 100 100" />
            </geometry>
            <material name="Orange" />
        </visual>
        <collision>
            <origin rpy="0 0 0" xyz="0 0 0.01" />
            <geometry>
                <mesh filename="model://kuka-lwr-4plus/meshes/convex/arm_base_convex.stl" scale="0.9 0.9 0.9" />
            </geometry>
        </collision>
    </link>
    <gazebo reference="left_lwr_arm_base_link">
        <!--<material value="kuka-lwr.material"/>-->
    </gazebo>
    <joint name="left_lwr_arm_0_joint" type="revolute">
        <origin rpy="0 0 0" xyz="0 0 0.11" />
        <axis xyz="0 0 1" />
        <limit effort="204" lower="-2.96705972839" upper="2.96705972839" velocity="1.91986217719" />
        <safety_controller k_position="100" k_velocity="2" soft_lower_limit="-2.93215314335" soft_upper_limit="2.93215314335" />
        <dynamics damping="5.0" />
        <parent link="left_lwr_arm_base_link" />
        <child link="left_lwr_arm_1_link" />
    </joint>
    <gazebo reference="left_lwr_arm_0_joint">
        <provideFeedback>1</provideFeedback>
        <implicitSpringDamper>1</implicitSpringDamper>
    </gazebo>
    <transmission name="left_lwr_arm_0_trans" type="SimpleTransmission">
        <actuator name="left_lwr_arm_0_motor" />
        <joint name="left_lwr_arm_0_joint" />
        <mechanicalReduction>1.0</mechanicalReduction>
    </transmission>
    <link name="left_lwr_arm_1_link">
        <inertial>
            <mass value="2.0" />
            <origin rpy="0 0 0" xyz="0 0 0.130" />
            <inertia ixx="0.0136666666667" ixy="0" ixz="0" iyy="0.0118666666667" iyz="0" izz="0.003" />
        </inertial>
        <visual>
            <origin rpy="0 0 3.14159265359" xyz="0 0 0" />
            <geometry>
                <mesh filename="model://kuka-lwr-4plus/meshes/arm_segment_a.dae" scale="100 100 100" />
            </geometry>
            <material name="Orange" />
        </visual>
        <collision>
            <origin rpy="0 0 3.14159265359" xyz="0 0 0" />
            <geometry>
                <mesh filename="model://kuka-lwr-4plus/meshes/convex/arm_segment_a_convex.stl" scale="1.0 1.0 1.0" />
            </geometry>
        </collision>
    </link>
    <gazebo reference="left_lwr_arm_1_link">
        <!--<material value="kuka-lwr.material"/>-->
    </gazebo>
    <joint name="left_lwr_arm_1_joint" type="revolute">
        <origin rpy="0 0 0" xyz="0 0 0.20" />
        <axis xyz="0 -1 0" />
        <limit effort="306" lower="-2.09439510239" upper="2.09439510239" velocity="1.91986217719" />
        <safety_controller k_position="100" k_velocity="2" soft_lower_limit="-2.05948851735" soft_upper_limit="2.05948851735" />
        <dynamics damping="5.0" />
        <parent link="left_lwr_arm_1_link" />
        <child link="left_lwr_arm_2_link" />
    </joint>
    <gazebo reference="left_lwr_arm_1_joint">
        <provideFeedback>1</provideFeedback>
        <implicitSpringDamper>1</implicitSpringDamper>
    </gazebo>
    <transmission name="left_lwr_arm_1_trans" type="pr2_mechanism_model/SimpleTransmission">
        <actuator name="left_lwr_arm_1_motor" />
        <joint name="left_lwr_arm_1_joint" />
        <mechanicalReduction>1.0</mechanicalReduction>
    </transmission>
    <link name="left_lwr_arm_2_link">
        <inertial>
            <mass value="2.0" />
            <origin rpy="0 0 0" xyz="0 -0.06 0.07" />
            <inertia ixx="0.0136666666667" ixy="0" ixz="0" iyy="0.0118666666667" iyz="0" izz="0.003" />
        </inertial>
        <visual>
            <origin rpy="3.14159265359 0 3.14159265359" xyz="0 0 0.2" />
            <geometry>
                <mesh filename="model://kuka-lwr-4plus/meshes/arm_segment_b.dae" scale="100 100 100" />
            </geometry>
            <material name="Orange" />
        </visual>
        <collision>
            <origin rpy="3.14159265359 0 3.14159265359" xyz="0 0 0.2" />
            <geometry>
                <mesh filename="model://kuka-lwr-4plus/meshes/convex/arm_segment_b_convex.stl" scale="1.0 1.0 1.0" />
            </geometry>
        </collision>
    </link>
    <gazebo reference="left_lwr_arm_2_link">
        <!--<material value="kuka-lwr.material"/>-->
    </gazebo>
    <joint name="left_lwr_arm_2_joint" type="revolute">
        <origin rpy="0 0 0" xyz="0 0 0.20" />
        <axis xyz="0 0 1" />
        <limit effort="204" lower="-2.96705972839" upper="2.96705972839" velocity="2.26892802759" />
        <safety_controller k_position="100" k_velocity="2" soft_lower_limit="-2.93215314335" soft_upper_limit="2.93215314335" />
        <dynamics damping="3.0" />
        <parent link="left_lwr_arm_2_link" />
        <child link="left_lwr_arm_3_link" />
    </joint>
    <gazebo reference="left_lwr_arm_2_joint">
        <provideFeedback>1</provideFeedback>
        <implicitSpringDamper>1</implicitSpringDamper>
    </gazebo>
    <transmission name="left_lwr_arm_2_trans" type="SimpleTransmission">
        <actuator name="left_lwr_arm_2_motor" />
        <joint name="left_lwr_arm_2_joint" />
        <mechanicalReduction>1.0</mechanicalReduction>
    </transmission>
    <link name="left_lwr_arm_3_link">
        <inertial>
            <mass value="2.0" />
            <origin rpy="0 0 0" xyz="0 -0.06 0.130" />
            <inertia ixx="0.0136666666667" ixy="0" ixz="0" iyy="0.0118666666667" iyz="0" izz="0.003" />
        </inertial>
        <visual>
            <origin rpy="0 0 0" xyz="0 0 0" />
            <geometry>
                <mesh filename="model://kuka-lwr-4plus/meshes/arm_segment_a.dae" scale="100 100 100" />
            </geometry>
            <material name="Orange" />
        </visual>
        <collision>
            <origin rpy="0 0 0" xyz="0 0 0" />
            <geometry>
                <mesh filename="model://kuka-lwr-4plus/meshes/convex/arm_segment_a_convex.stl" scale="1.0 1.0 1.0" />
            </geometry>
        </collision>
    </link>
    <gazebo reference="left_lwr_arm_3_link">
        <!--<material value="kuka-lwr.material"/>-->
    </gazebo>
    <joint name="left_lwr_arm_3_joint" type="revolute">
        <origin rpy="0 0 0" xyz="0 0 0.20" />
        <axis xyz="0 1 0" />
        <limit effort="306" lower="-2.09439510239" upper="2.09439510239" velocity="2.26892802759" />
        <safety_controller k_position="100" k_velocity="2" soft_lower_limit="-2.05948851735" soft_upper_limit="2.05948851735" />
        <dynamics damping="3.0" />
        <parent link="left_lwr_arm_3_link" />
        <child link="left_lwr_arm_4_link" />
    </joint>
    <gazebo reference="left_lwr_arm_3_joint">
        <provideFeedback>1</provideFeedback>
        <implicitSpringDamper>1</implicitSpringDamper>
    </gazebo>
    <transmission name="left_lwr_arm_3_trans" type="SimpleTransmission">
        <actuator name="left_lwr_arm_3_motor" />
        <joint name="left_lwr_arm_3_joint" />
        <mechanicalReduction>1.0</mechanicalReduction>
    </transmission>
    <link name="left_lwr_arm_4_link">
        <inertial>
            <mass value="2.0" />
            <origin rpy="0 0 0" xyz="0 0.06 0.07" />
            <inertia ixx="0.0136666666667" ixy="0" ixz="0" iyy="0.0118666666667" iyz="0" izz="0.003" />
        </inertial>
        <visual>
            <origin rpy="0 3.14159265359 3.14159265359" xyz="0 0 0.2" />
            <geometry>
                <mesh filename="model://kuka-lwr-4plus/meshes/arm_segment_b.dae" scale="100 100 100" />
            </geometry>
            <material name="Orange" />
        </visual>
        <collision>
            <origin rpy="0 3.14159265359 3.14159265359" xyz="0 0 0.2" />
            <geometry>
                <mesh filename="model://kuka-lwr-4plus/meshes/convex/arm_segment_b_convex.stl" scale="1.0 1.0 1.0" />
            </geometry>
        </collision>
    </link>
    <gazebo reference="left_lwr_arm_4_link">
        <!--<material value="kuka-lwr.material"/>-->
    </gazebo>
    <joint name="left_lwr_arm_4_joint" type="revolute">
        <origin rpy="0 0 0" xyz="0 0 0.20" />
        <axis xyz="0 0 1" />
        <limit effort="204" lower="-2.96705972839" upper="2.96705972839" velocity="2.26892802759" />
        <safety_controller k_position="100" k_velocity="2" soft_lower_limit="-2.93215314335" soft_upper_limit="2.93215314335" />
        <dynamics damping="1.0" />
        <parent link="left_lwr_arm_4_link" />
        <child link="left_lwr_arm_5_link" />
    </joint>
    <gazebo reference="left_lwr_arm_4_joint">
        <provideFeedback>1</provideFeedback>
        <implicitSpringDamper>1</implicitSpringDamper>
    </gazebo>
    <transmission name="left_lwr_arm_4_trans" type="SimpleTransmission">
        <actuator name="left_lwr_arm_4_motor" />
        <joint name="left_lwr_arm_4_joint" />
        <mechanicalReduction>1.0</mechanicalReduction>
    </transmission>
    <link name="left_lwr_arm_5_link">
        <inertial>
            <mass value="2.0" />
            <origin rpy="0 0 0" xyz="0 0 0.124" />
            <inertia ixx="0.0126506666667" ixy="0" ixz="0" iyy="0.0108506666667" iyz="0" izz="0.003" />
        </inertial>
        <visual>
            <origin rpy="0 0 3.14159265359" xyz="0 0 0" />
            <geometry name="left_lwr_arm_5_geom">
                <mesh filename="model://kuka-lwr-4plus/meshes/arm_segment_last.dae" scale="100 100 100" />
            </geometry>
            <material name="Orange" />
        </visual>
        <collision>
            <origin rpy="0 0 3.14159265359" xyz="0 0 0" />
            <geometry>
                <mesh filename="model://kuka-lwr-4plus/meshes/convex/arm_segment_last_convex.stl" scale="1.0 1.0 1.0" />
            </geometry>
        </collision>
    </link>
    <gazebo reference="left_lwr_arm_5_link">
        <!--<material value="kuka-lwr.material"/>-->
    </gazebo>
    <joint name="left_lwr_arm_5_joint" type="revolute">
        <origin rpy="0 0 0" xyz="0 0 0.19" />
        <axis xyz="0 -1 0" />
        <limit effort="306" lower="-2.09439510239" upper="2.09439510239" velocity="3.14159265359" />
        <safety_controller k_position="100" k_velocity="2" soft_lower_limit="-2.05948851735" soft_upper_limit="2.05948851735" />
        <dynamics damping="1.0" />
        <parent link="left_lwr_arm_5_link" />
        <child link="left_lwr_arm_6_link" />
    </joint>
    <gazebo reference="left_lwr_arm_5_joint">
        <provideFeedback>1</provideFeedback>
        <implicitSpringDamper>1</implicitSpringDamper>
    </gazebo>
    <transmission name="left_lwr_arm_5_trans" type="SimpleTransmission">
        <actuator name="left_lwr_arm_5_motor" />
        <joint name="left_lwr_arm_5_joint" />
        <mechanicalReduction>1.0</mechanicalReduction>
    </transmission>
    <link name="left_lwr_arm_6_link">
        <inertial>
            <mass value="1.0" />
            <origin rpy="0 0 0" xyz="0 0 0.0" />
            <inertia ixx="0.00260416666667" ixy="0" ixz="0" iyy="0.00260416666667" iyz="0" izz="0.00260416666667" />
        </inertial>
        <visual>
            <origin rpy="0 0 3.14159265359" xyz="0 0 0" />
            <geometry>
                <mesh filename="model://kuka-lwr-4plus/meshes/arm_wrist.dae" scale="100 100 100" />
            </geometry>
            <material name="Grey" />
        </visual>
        <collision>
            <origin rpy="0 0 3.14159265359" xyz="0 0 0" />
            <geometry>
                <mesh filename="model://kuka-lwr-4plus/meshes/convex/arm_wrist_convex.stl" scale="1.0 1.0 1.0" />
            </geometry>
        </collision>
    </link>
    <gazebo reference="left_lwr_arm_6_link">
        <!--<material value="kuka-lwr.material"/>-->
    </gazebo>
    <joint name="left_lwr_arm_6_joint" type="revolute">
        <origin rpy="0 0 0" xyz="0 0 0.078" />
        <axis xyz="0 0 1" />
        <limit effort="204" lower="-2.96705972839" upper="2.96705972839" velocity="3.14159265359" />
        <safety_controller k_position="100" k_velocity="2" soft_lower_limit="-2.93215314335" soft_upper_limit="2.93215314335" />
        <dynamics damping="1.0" />
        <parent link="left_lwr_arm_6_link" />
        <child link="left_lwr_arm_7_link" />
    </joint>
    <gazebo reference="left_lwr_arm_6_joint">
        <provideFeedback>1</provideFeedback>
        <implicitSpringDamper>1</implicitSpringDamper>
    </gazebo>
    <transmission name="left_lwr_arm_6_trans" type="SimpleTransmission">
        <actuator name="left_lwr_arm_6_motor" />
        <joint name="left_lwr_arm_6_joint" />
        <mechanicalReduction>1.0</mechanicalReduction>
    </transmission>
    <link name="left_lwr_arm_7_link">
        <inertial>
            <mass value="0.2" />
            <origin xyz="0 0 0" />
            <inertia ixx="6.66666666667e-05" ixy="0" ixz="0" iyy="6.66666666667e-05" iyz="0" izz="0.00012" />
        </inertial>
        <visual>
            <origin rpy="0 0 0" xyz="0 0 0" />
            <geometry>
                <mesh filename="model://kuka-lwr-4plus/meshes/arm_flanche.dae" scale="100 100 100" />
            </geometry>
            <material name="Grey" />
        </visual>
        <collision>
            <origin rpy="0 0 0" xyz="0 0 0" />
            <geometry>
                <!--mesh filename="model://kuka-lwr-4plus/meshes/convex/arm_flanche_convex.stl" scale="1.0 1.0 1.0"/-->
                <mesh filename="model://kuka-lwr-4plus/meshes/arm_flanche.dae" scale="100 100 100" />
            </geometry>
            <surface>
                <friction>
                    <ode>
                        <mu>0.0</mu>
                        <mu2>0.0</mu2>
                    </ode>
                </friction>
            </surface>
        </collision>
    </link>
    <gazebo reference="left_lwr_arm_7_link">
        <!--<material value="kuka-lwr.material"/>-->
    </gazebo>
<joint name="left_lwr_arm_7_tool_joint" type="fixed">
	<origin rpy="0 0 0" xyz="0 0 0.045" />
	<limit effort="0" lower="0" upper="0" velocity="0" />
    <parent link="left_lwr_arm_7_link"/>
    <child link="left_lwr_tool_link"/>
</joint>
<gazebo reference="left_lwr_arm_7_tool_joint">
<provideFeedback>1</provideFeedback>
<!--<sensor name="force_torque" type="force_torque">
          <always_on>true</always_on>
          <visualize>true</visualize>
          <update_rate>100</update_rate>
		  <force_torque>
			<frame>child</frame>
			<measure_direction>child_to_parent</measure_direction>
		  </force_torque>
        </sensor>-->
</gazebo>

<link name="left_lwr_tool_link">
			<collision name="tool_collision">
				<origin rpy="0 0 0" xyz="0 0 -0.045" />
				<geometry>
					<mesh filename="model://kuka-lwr-4plus-triangle/TriangleFoot.stl" scale="0.01 0.01 0.01" />
				</geometry>
            <surface>
                <friction>
                    <ode>
                        <mu>10.0</mu>
                        <mu2>10.0</mu2>
                    </ode>
                </friction>
            </surface>
			</collision>
			<visual name="tool_visual">
				<origin rpy="0 0 0" xyz="0 0 -0.045" />
				<geometry>
					<mesh filename="model://kuka-lwr-4plus-triangle/TriangleFoot.stl" scale="0.01 0.01 0.01" />
				</geometry>
			</visual>
			<inertial>
       <mass value="0.355"/>
<origin xyz="0 -0.000511 0.017079" />
       <inertia ixx="0.0003608" ixy="0.0" ixz="0.0" iyy="0.0003456" iyz="0.0000021" izz="0.0005754"/>
     </inertial>
			<!--<sensor name='ft_sensor' type='ForceTorque'/><- maybe?
			<sensor type='force_torque' name='ft_sensor'>"0.037"
				<update_rate>1000</update_rate>
			</sensor>-->
</link> 
<gazebo reference="left_lwr_tool_link">
        <!--<material value="kuka-lwr.material"/>-->
</gazebo>

<!-- dlw left -->
<joint name="left_lwr_base_joint" type="fixed">
		<origin rpy="0 0 0" xyz="0.56029 -0.25 0.4" />
		<parent link="base_link" />
		<child link="left_lwr_arm_base_link" />
</joint>
<gazebo reference="left_lwr_base_joint">
</gazebo>


<!-- kuka right -->
<link name="right_lwr_arm_base_link">
        <inertial>
            <mass value="1.2" />
            <origin rpy="0 0 0" xyz="0 0 0.055" />
            <inertia ixx="0.00229" ixy="0" ixz="0" iyy="0.00216" iyz="0" izz="0.00229" />
        </inertial>
        <visual>
            <origin rpy="0 0 0" xyz="0 0 0" />
            <geometry>
                <mesh filename="model://kuka-lwr-4plus/meshes/arm_base.dae" scale="100 100 100" />
            </geometry>
            <material name="Orange" />
        </visual>
        <collision>
            <origin rpy="0 0 0" xyz="0 0 0.01" />
            <geometry>
                <mesh filename="model://kuka-lwr-4plus/meshes/convex/arm_base_convex.stl" scale="0.9 0.9 0.9" />
            </geometry>
        </collision>
    </link>
    <gazebo reference="right_lwr_arm_base_link">
        <!--<material value="kuka-lwr.material"/>-->
    </gazebo>
    <joint name="right_lwr_arm_0_joint" type="revolute">
        <origin rpy="0 0 0" xyz="0 0 0.11" />
        <axis xyz="0 0 1" />
        <limit effort="204" lower="-2.96705972839" upper="2.96705972839" velocity="1.91986217719" />
        <safety_controller k_position="100" k_velocity="2" soft_lower_limit="-2.93215314335" soft_upper_limit="2.93215314335" />
        <dynamics damping="5.0" />
        <parent link="right_lwr_arm_base_link" />
        <child link="right_lwr_arm_1_link" />
    </joint>
    <gazebo reference="right_lwr_arm_0_joint">
        <provideFeedback>1</provideFeedback>
        <implicitSpringDamper>1</implicitSpringDamper>
    </gazebo>
    <transmission name="right_lwr_arm_0_trans" type="SimpleTransmission">
        <actuator name="right_lwr_arm_0_motor" />
        <joint name="right_lwr_arm_0_joint" />
        <mechanicalReduction>1.0</mechanicalReduction>
    </transmission>
    <link name="right_lwr_arm_1_link">
        <inertial>
            <mass value="2.0" />
            <origin rpy="0 0 0" xyz="0 0 0.130" />
            <inertia ixx="0.0136666666667" ixy="0" ixz="0" iyy="0.0118666666667" iyz="0" izz="0.003" />
        </inertial>
        <visual>
            <origin rpy="0 0 3.14159265359" xyz="0 0 0" />
            <geometry>
                <mesh filename="model://kuka-lwr-4plus/meshes/arm_segment_a.dae" scale="100 100 100" />
            </geometry>
            <material name="Orange" />
        </visual>
        <collision>
            <origin rpy="0 0 3.14159265359" xyz="0 0 0" />
            <geometry>
                <mesh filename="model://kuka-lwr-4plus/meshes/convex/arm_segment_a_convex.stl" scale="1.0 1.0 1.0" />
            </geometry>
        </collision>
    </link>
    <gazebo reference="right_lwr_arm_1_link">
        <!--<material value="kuka-lwr.material"/>-->
    </gazebo>
    <joint name="right_lwr_arm_1_joint" type="revolute">
        <origin rpy="0 0 0" xyz="0 0 0.20" />
        <axis xyz="0 -1 0" />
        <limit effort="306" lower="-2.09439510239" upper="2.09439510239" velocity="1.91986217719" />
        <safety_controller k_position="100" k_velocity="2" soft_lower_limit="-2.05948851735" soft_upper_limit="2.05948851735" />
        <dynamics damping="5.0" />
        <parent link="right_lwr_arm_1_link" />
        <child link="right_lwr_arm_2_link" />
    </joint>
    <gazebo reference="right_lwr_arm_1_joint">
        <provideFeedback>1</provideFeedback>
        <implicitSpringDamper>1</implicitSpringDamper>
    </gazebo>
    <transmission name="right_lwr_arm_1_trans" type="pr2_mechanism_model/SimpleTransmission">
        <actuator name="right_lwr_arm_1_motor" />
        <joint name="right_lwr_arm_1_joint" />
        <mechanicalReduction>1.0</mechanicalReduction>
    </transmission>
    <link name="right_lwr_arm_2_link">
        <inertial>
            <mass value="2.0" />
            <origin rpy="0 0 0" xyz="0 -0.06 0.07" />
            <inertia ixx="0.0136666666667" ixy="0" ixz="0" iyy="0.0118666666667" iyz="0" izz="0.003" />
        </inertial>
        <visual>
            <origin rpy="3.14159265359 0 3.14159265359" xyz="0 0 0.2" />
            <geometry>
                <mesh filename="model://kuka-lwr-4plus/meshes/arm_segment_b.dae" scale="100 100 100" />
            </geometry>
            <material name="Orange" />
        </visual>
        <collision>
            <origin rpy="3.14159265359 0 3.14159265359" xyz="0 0 0.2" />
            <geometry>
                <mesh filename="model://kuka-lwr-4plus/meshes/convex/arm_segment_b_convex.stl" scale="1.0 1.0 1.0" />
            </geometry>
        </collision>
    </link>
    <gazebo reference="right_lwr_arm_2_link">
        <!--<material value="kuka-lwr.material"/>-->
    </gazebo>
    <joint name="right_lwr_arm_2_joint" type="revolute">
        <origin rpy="0 0 0" xyz="0 0 0.20" />
        <axis xyz="0 0 1" />
        <limit effort="204" lower="-2.96705972839" upper="2.96705972839" velocity="2.26892802759" />
        <safety_controller k_position="100" k_velocity="2" soft_lower_limit="-2.93215314335" soft_upper_limit="2.93215314335" />
        <dynamics damping="3.0" />
        <parent link="right_lwr_arm_2_link" />
        <child link="right_lwr_arm_3_link" />
    </joint>
    <gazebo reference="right_lwr_arm_2_joint">
        <provideFeedback>1</provideFeedback>
        <implicitSpringDamper>1</implicitSpringDamper>
    </gazebo>
    <transmission name="right_lwr_arm_2_trans" type="SimpleTransmission">
        <actuator name="right_lwr_arm_2_motor" />
        <joint name="right_lwr_arm_2_joint" />
        <mechanicalReduction>1.0</mechanicalReduction>
    </transmission>
    <link name="right_lwr_arm_3_link">
        <inertial>
            <mass value="2.0" />
            <origin rpy="0 0 0" xyz="0 -0.06 0.130" />
            <inertia ixx="0.0136666666667" ixy="0" ixz="0" iyy="0.0118666666667" iyz="0" izz="0.003" />
        </inertial>
        <visual>
            <origin rpy="0 0 0" xyz="0 0 0" />
            <geometry>
                <mesh filename="model://kuka-lwr-4plus/meshes/arm_segment_a.dae" scale="100 100 100" />
            </geometry>
            <material name="Orange" />
        </visual>
        <collision>
            <origin rpy="0 0 0" xyz="0 0 0" />
            <geometry>
                <mesh filename="model://kuka-lwr-4plus/meshes/convex/arm_segment_a_convex.stl" scale="1.0 1.0 1.0" />
            </geometry>
        </collision>
    </link>
    <gazebo reference="right_lwr_arm_3_link">
        <!--<material value="kuka-lwr.material"/>-->
    </gazebo>
    <joint name="right_lwr_arm_3_joint" type="revolute">
        <origin rpy="0 0 0" xyz="0 0 0.20" />
        <axis xyz="0 1 0" />
        <limit effort="306" lower="-2.09439510239" upper="2.09439510239" velocity="2.26892802759" />
        <safety_controller k_position="100" k_velocity="2" soft_lower_limit="-2.05948851735" soft_upper_limit="2.05948851735" />
        <dynamics damping="3.0" />
        <parent link="right_lwr_arm_3_link" />
        <child link="right_lwr_arm_4_link" />
    </joint>
    <gazebo reference="right_lwr_arm_3_joint">
        <provideFeedback>1</provideFeedback>
        <implicitSpringDamper>1</implicitSpringDamper>
    </gazebo>
    <transmission name="right_lwr_arm_3_trans" type="SimpleTransmission">
        <actuator name="right_lwr_arm_3_motor" />
        <joint name="right_lwr_arm_3_joint" />
        <mechanicalReduction>1.0</mechanicalReduction>
    </transmission>
    <link name="right_lwr_arm_4_link">
        <inertial>
            <mass value="2.0" />
            <origin rpy="0 0 0" xyz="0 0.06 0.07" />
            <inertia ixx="0.0136666666667" ixy="0" ixz="0" iyy="0.0118666666667" iyz="0" izz="0.003" />
        </inertial>
        <visual>
            <origin rpy="0 3.14159265359 3.14159265359" xyz="0 0 0.2" />
            <geometry>
                <mesh filename="model://kuka-lwr-4plus/meshes/arm_segment_b.dae" scale="100 100 100" />
            </geometry>
            <material name="Orange" />
        </visual>
        <collision>
            <origin rpy="0 3.14159265359 3.14159265359" xyz="0 0 0.2" />
            <geometry>
                <mesh filename="model://kuka-lwr-4plus/meshes/convex/arm_segment_b_convex.stl" scale="1.0 1.0 1.0" />
            </geometry>
        </collision>
    </link>
    <gazebo reference="right_lwr_arm_4_link">
        <!--<material value="kuka-lwr.material"/>-->
    </gazebo>
    <joint name="right_lwr_arm_4_joint" type="revolute">
        <origin rpy="0 0 0" xyz="0 0 0.20" />
        <axis xyz="0 0 1" />
        <limit effort="204" lower="-2.96705972839" upper="2.96705972839" velocity="2.26892802759" />
        <safety_controller k_position="100" k_velocity="2" soft_lower_limit="-2.93215314335" soft_upper_limit="2.93215314335" />
        <dynamics damping="1.0" />
        <parent link="right_lwr_arm_4_link" />
        <child link="right_lwr_arm_5_link" />
    </joint>
    <gazebo reference="right_lwr_arm_4_joint">
        <provideFeedback>1</provideFeedback>
        <implicitSpringDamper>1</implicitSpringDamper>
    </gazebo>
    <transmission name="right_lwr_arm_4_trans" type="SimpleTransmission">
        <actuator name="right_lwr_arm_4_motor" />
        <joint name="right_lwr_arm_4_joint" />
        <mechanicalReduction>1.0</mechanicalReduction>
    </transmission>
    <link name="right_lwr_arm_5_link">
        <inertial>
            <mass value="2.0" />
            <origin rpy="0 0 0" xyz="0 0 0.124" />
            <inertia ixx="0.0126506666667" ixy="0" ixz="0" iyy="0.0108506666667" iyz="0" izz="0.003" />
        </inertial>
        <visual>
            <origin rpy="0 0 3.14159265359" xyz="0 0 0" />
            <geometry name="right_lwr_arm_5_geom">
                <mesh filename="model://kuka-lwr-4plus/meshes/arm_segment_last.dae" scale="100 100 100" />
            </geometry>
            <material name="Orange" />
        </visual>
        <collision>
            <origin rpy="0 0 3.14159265359" xyz="0 0 0" />
            <geometry>
                <mesh filename="model://kuka-lwr-4plus/meshes/convex/arm_segment_last_convex.stl" scale="1.0 1.0 1.0" />
            </geometry>
        </collision>
    </link>
    <gazebo reference="right_lwr_arm_5_link">
        <!--<material value="kuka-lwr.material"/>-->
    </gazebo>
    <joint name="right_lwr_arm_5_joint" type="revolute">
        <origin rpy="0 0 0" xyz="0 0 0.19" />
        <axis xyz="0 -1 0" />
        <limit effort="306" lower="-2.09439510239" upper="2.09439510239" velocity="3.14159265359" />
        <safety_controller k_position="100" k_velocity="2" soft_lower_limit="-2.05948851735" soft_upper_limit="2.05948851735" />
        <dynamics damping="1.0" />
        <parent link="right_lwr_arm_5_link" />
        <child link="right_lwr_arm_6_link" />
    </joint>
    <gazebo reference="right_lwr_arm_5_joint">
        <provideFeedback>1</provideFeedback>
        <implicitSpringDamper>1</implicitSpringDamper>
    </gazebo>
    <transmission name="right_lwr_arm_5_trans" type="SimpleTransmission">
        <actuator name="right_lwr_arm_5_motor" />
        <joint name="right_lwr_arm_5_joint" />
        <mechanicalReduction>1.0</mechanicalReduction>
    </transmission>
    <link name="right_lwr_arm_6_link">
        <inertial>
            <mass value="1.0" />
            <origin rpy="0 0 0" xyz="0 0 0.0" />
            <inertia ixx="0.00260416666667" ixy="0" ixz="0" iyy="0.00260416666667" iyz="0" izz="0.00260416666667" />
        </inertial>
        <visual>
            <origin rpy="0 0 3.14159265359" xyz="0 0 0" />
            <geometry>
                <mesh filename="model://kuka-lwr-4plus/meshes/arm_wrist.dae" scale="100 100 100" />
            </geometry>
            <material name="Grey" />
        </visual>
        <collision>
            <origin rpy="0 0 3.14159265359" xyz="0 0 0" />
            <geometry>
                <mesh filename="model://kuka-lwr-4plus/meshes/convex/arm_wrist_convex.stl" scale="1.0 1.0 1.0" />
            </geometry>
        </collision>
    </link>
    <gazebo reference="right_lwr_arm_6_link">
        <!--<material value="kuka-lwr.material"/>-->
    </gazebo>
    <joint name="right_lwr_arm_6_joint" type="revolute">
        <origin rpy="0 0 0" xyz="0 0 0.078" />
        <axis xyz="0 0 1" />
        <limit effort="204" lower="-2.96705972839" upper="2.96705972839" velocity="3.14159265359" />
        <safety_controller k_position="100" k_velocity="2" soft_lower_limit="-2.93215314335" soft_upper_limit="2.93215314335" />
        <dynamics damping="1.0" />
        <parent link="right_lwr_arm_6_link" />
        <child link="right_lwr_arm_7_link" />
    </joint>
    <gazebo reference="right_lwr_arm_6_joint">
        <provideFeedback>1</provideFeedback>
        <implicitSpringDamper>1</implicitSpringDamper>
    </gazebo>
    <transmission name="right_lwr_arm_6_trans" type="SimpleTransmission">
        <actuator name="right_lwr_arm_6_motor" />
        <joint name="right_lwr_arm_6_joint" />
        <mechanicalReduction>1.0</mechanicalReduction>
    </transmission>
    <link name="right_lwr_arm_7_link">
        <inertial>
            <mass value="0.2" />
            <origin xyz="0 0 0" />
            <inertia ixx="6.66666666667e-05" ixy="0" ixz="0" iyy="6.66666666667e-05" iyz="0" izz="0.00012" />
        </inertial>
        <visual>
            <origin rpy="0 0 0" xyz="0 0 0" />
            <geometry>
                <mesh filename="model://kuka-lwr-4plus/meshes/arm_flanche.dae" scale="100 100 100" />
            </geometry>
            <material name="Grey" />
        </visual>
        <collision>
            <origin rpy="0 0 0" xyz="0 0 0" />
            <geometry>
                <!--mesh filename="model://kuka-lwr-4plus/meshes/convex/arm_flanche_convex.stl" scale="1.0 1.0 1.0"/-->
                <mesh filename="model://kuka-lwr-4plus/meshes/arm_flanche.dae" scale="100 100 100" />
            </geometry>
            <surface>
                <friction>
                    <ode>
                        <mu>0.0</mu>
                        <mu2>0.0</mu2>
                    </ode>
                </friction>
            </surface>
        </collision>
    </link>
    <gazebo reference="right_lwr_arm_7_link">
        <!--<material value="kuka-lwr.material"/>-->
    </gazebo>
<joint name="right_lwr_arm_7_tool_joint" type="fixed">
	<origin rpy="0 0 0" xyz="0 0 0.045" />
	<limit effort="0" lower="0" upper="0" velocity="0" />
    <parent link="right_lwr_arm_7_link"/>
    <child link="right_lwr_tool_link"/>
</joint>
<gazebo reference="right_lwr_arm_7_tool_joint">
<provideFeedback>1</provideFeedback>
<!--<sensor name="force_torque" type="force_torque">
          <always_on>true</always_on>
          <visualize>true</visualize>
          <update_rate>100</update_rate>
		  <force_torque>
			<frame>child</frame>
			<measure_direction>child_to_parent</measure_direction>
		  </force_torque>
        </sensor>-->
</gazebo>

<link name="right_lwr_tool_link">
			<collision name="tool_collision">
				<origin rpy="0 0 0" xyz="0 0 -0.045" />
				<geometry>
					<mesh filename="model://kuka-lwr-4plus-triangle/TriangleFoot.stl" scale="0.01 0.01 0.01" />
				</geometry>
            <surface>
                <friction>
                    <ode>
                        <mu>10.0</mu>
                        <mu2>10.0</mu2>
                    </ode>
                </friction>
            </surface>
			</collision>
			<visual name="tool_visual">
				<origin rpy="0 0 0" xyz="0 0 -0.045" />
				<geometry>
					<mesh filename="model://kuka-lwr-4plus-triangle/TriangleFoot.stl" scale="0.01 0.01 0.01" />
				</geometry>
			</visual>
			<inertial>
       <mass value="0.355"/>
<origin xyz="0 -0.000511 0.017079" />
       <inertia ixx="0.0003608" ixy="0.0" ixz="0.0" iyy="0.0003456" iyz="0.0000021" izz="0.0005754"/>
     </inertial>
			<!--<sensor name='ft_sensor' type='ForceTorque'/><- maybe?
			<sensor type='force_torque' name='ft_sensor'>"0.037"
				<update_rate>1000</update_rate>
			</sensor>-->
</link> 
<gazebo reference="right_lwr_tool_link">
        <!--<material value="kuka-lwr.material"/>-->
</gazebo>

<!-- dlw right -->
<joint name="right_lwr_base_joint" type="fixed">
		<origin rpy="0 0 0" xyz="0.5 0.25 0.4" />
		<parent link="base_link" />
		<child link="right_lwr_arm_base_link" />
</joint>
<gazebo reference="right_lwr_base_joint">
</gazebo>

</robot>