<?xml version="1.0"?>
<sdf version='1.5'>
  <model name='kuka-festo-8dof'>
    <link name='axis_link'>
      <pose frame=''>0 0 0 0 0 0</pose>
      <inertial>
        <mass>56.4</mass>
        <inertia>
          <ixx>9.463375975</ixx>     <!-- for a box: ixx = mass / 12 * (y² + z²) = 4.7 * (1.993744 + 0.01974025) -->
          <ixy>0.0</ixy>             <!-- for a box: ixy = 0 -->
          <ixz>0.0</ixz>             <!-- for a box: ixz = 0 -->
          <iyy>0.255380375</iyy>     <!-- for a box: iyy = mass / 12 * (x² + z²) = 4.7 * (0.034596 + 0.01974025) -->
          <iyz>0.0</iyz>             <!-- for a box: iyz = 0 -->
          <izz>9.533198</izz>        <!-- for a box: izz = mass / 12 * (x² + y²) = 4.7 * (0.034596 + 1.993744) -->
        </inertia>
      </inertial>
      <collision name="collision">
        <pose frame=''>0 -0.003 0.07125 0 0 0</pose>
        <geometry>
          <box>
            <size>0.186 1.412 0.1405</size>
          </box>
        </geometry>
      </collision>
      <visual name='visual'>
        <geometry>
          <mesh>
            <uri>model://kuka-lwr-4plus-8dof/meshes/axis.dae</uri>
          </mesh>
        </geometry>
      </visual>
      <gravity>1</gravity>
      <velocity_decay/>
      <self_collide>0</self_collide>
    </link>
    <link name='slide_link'>
      <pose frame=''>0 0 0 0 0 0</pose>
      <inertial>
        <mass>12.6</mass>
        <inertia>
          <ixx>0.0845903625</ixx>    <!-- for a box: ixx = mass / 12 * (y² + z²) = 1.05 * (0.0784 + 0.00216225) -->
          <ixy>0.0</ixy>             <!-- for a box: ixy = 0 -->
          <ixz>0.0</ixz>             <!-- for a box: ixz = 0 -->
          <iyy>0.0322594125</iyy>    <!-- for a box: iyy = mass / 12 * (x² + z²) = 1.05 * (0.028561 + 0.00216225) -->
          <iyz>0.0</iyz>             <!-- for a box: iyz = 0 -->
          <izz>0.11230905</izz>      <!-- for a box: izz = mass / 12 * (x² + y²) = 1.05 * (0.028561 + 0.0784) -->
        </inertia>
      </inertial>
      <collision name="collision">
        <geometry>
          <box>
            <size>0.169 0.280 0.0465</size>
          </box>
        </geometry>
      </collision>
      <visual name='visual'>
        <pose frame=''>0 -0.0708 0 0 0 0</pose>
        <geometry>
          <mesh>
            <uri>model://kuka-lwr-4plus-8dof/meshes/slide.stl</uri>
          </mesh>
        </geometry>
      </visual>
      <gravity>1</gravity>
      <velocity_decay/>
      <self_collide>0</self_collide>
    </link>
    <link name='lwr_arm_base_link'>
      <pose frame=''>0 0 0.01 0 -0 0</pose>
      <inertial>
        <pose frame=''>0 0 0.055 0 -0 0</pose>
        <mass>1.2</mass>
        <inertia>
          <ixx>0.00229</ixx>
          <ixy>0</ixy>
          <ixz>0</ixz>
          <iyy>0.00216</iyy>
          <iyz>0</iyz>
          <izz>0.00229</izz>
        </inertia>
      </inertial>
      <collision name='lwr_arm_base_link_collision'>
        <pose frame=''>0 0 0.01 0 -0 0</pose>
        <geometry>
          <mesh>
            <scale>0.9 0.9 0.9</scale>
            <uri>model://kuka-lwr-4plus-8dof/meshes/convex/arm_base_convex.stl</uri>
          </mesh>
        </geometry>
      </collision>
      <visual name='lwr_arm_base_link_visual'>
        <pose frame=''>0 0 0 0 -0 0</pose>
        <geometry>
          <mesh>
            <scale>100 100 100</scale>
            <uri>model://kuka-lwr-4plus-8dof/meshes/arm_base.dae</uri>
          </mesh>
        </geometry>
      </visual>
      <gravity>1</gravity>
      <velocity_decay/>
      <self_collide>0</self_collide>
    </link>
    <joint name='slide_arm_joint' type='revolute'>
      <child>lwr_arm_base_link</child>
      <parent>slide</parent>
      <axis>
        <limit>
          <lower>0</lower>
          <upper>0</upper>
        </limit>
        <dynamics>
          <damping>0</damping>
          <friction>0</friction>
          <spring_reference>0</spring_reference>
          <spring_stiffness>0</spring_stiffness>
        </dynamics>
        <use_parent_model_frame>1</use_parent_model_frame>
        <xyz>0 0 0</xyz>
      </axis>
    </joint>
    <link name='lwr_arm_1_link'>
      <pose frame=''>0 0 0.12 0 -0 0</pose>
      <inertial>
        <pose frame=''>0 0 0.13 0 -0 0</pose>
        <mass>2</mass>
        <inertia>
          <ixx>0.0136667</ixx>
          <ixy>0</ixy>
          <ixz>0</ixz>
          <iyy>0.0118667</iyy>
          <iyz>0</iyz>
          <izz>0.003</izz>
        </inertia>
      </inertial>
      <collision name='lwr_arm_1_link_collision'>
        <pose frame=''>0 0 0 0 -0 -3.14159</pose>
        <geometry>
          <mesh>
            <scale>1 1 1</scale>
            <uri>model://kuka-lwr-4plus-8dof/meshes/convex/arm_segment_a_convex.stl</uri>
          </mesh>
        </geometry>
      </collision>
      <visual name='lwr_arm_1_link_visual'>
        <pose frame=''>0 0 0 0 -0 -3.14159</pose>
        <geometry>
          <mesh>
            <scale>100 100 100</scale>
            <uri>model://kuka-lwr-4plus-8dof/meshes/arm_segment_a.dae</uri>
          </mesh>
        </geometry>
      </visual>
      <gravity>1</gravity>
      <velocity_decay/>
      <self_collide>0</self_collide>
    </link>
    <joint name='lwr_arm_0_joint' type='revolute'>
      <child>lwr_arm_1_link</child>
      <parent>lwr_arm_base_link</parent>
      <axis>
        <xyz>0 0 1</xyz>
        <limit>
          <lower>-2.96706</lower>
          <upper>2.96706</upper>
          <effort>204</effort>
          <velocity>1.91986</velocity>
        </limit>
        <dynamics>
          <damping>5</damping>
          <friction>0</friction>
          <spring_reference>0</spring_reference>
          <spring_stiffness>0</spring_stiffness>
        </dynamics>
        <use_parent_model_frame>1</use_parent_model_frame>
      </axis>
      <physics>
        <provide_feedback>1</provide_feedback>
        <ode>
          <provide_feedback>1</provide_feedback>
          <implicit_spring_damper>1</implicit_spring_damper>
          <cfm_damping>1</cfm_damping>
          <limit>
            <cfm>0</cfm>
            <erp>0.2</erp>
          </limit>
        </ode>
      </physics>
    </joint>
    <link name='lwr_arm_2_link'>
      <pose frame=''>0 0 0.32 0 -0 0</pose>
      <inertial>
        <pose frame=''>0 -0.06 0.07 0 -0 0</pose>
        <mass>2</mass>
        <inertia>
          <ixx>0.0136667</ixx>
          <ixy>0</ixy>
          <ixz>0</ixz>
          <iyy>0.0118667</iyy>
          <iyz>0</iyz>
          <izz>0.003</izz>
        </inertia>
      </inertial>
      <collision name='lwr_arm_2_link_collision'>
        <pose frame=''>0 0 0.2 -3.14159 -0 -3.14159</pose>
        <geometry>
          <mesh>
            <scale>1 1 1</scale>
            <uri>model://kuka-lwr-4plus-8dof/meshes/convex/arm_segment_b_convex.stl</uri>
          </mesh>
        </geometry>
      </collision>
      <visual name='lwr_arm_2_link_visual'>
        <pose frame=''>0 0 0.2 -3.14159 -0 -3.14159</pose>
        <geometry>
          <mesh>
            <scale>100 100 100</scale>
            <uri>model://kuka-lwr-4plus-8dof/meshes/arm_segment_b.dae</uri>
          </mesh>
        </geometry>
      </visual>
      <gravity>1</gravity>
      <velocity_decay/>
      <self_collide>0</self_collide>
    </link>
    <joint name='lwr_arm_1_joint' type='revolute'>
      <child>lwr_arm_2_link</child>
      <parent>lwr_arm_1_link</parent>
      <axis>
        <xyz>0 -1 0</xyz>
        <limit>
          <lower>-2.0944</lower>
          <upper>2.0944</upper>
          <effort>306</effort>
          <velocity>1.91986</velocity>
        </limit>
        <dynamics>
          <damping>5</damping>
          <friction>0</friction>
          <spring_reference>0</spring_reference>
          <spring_stiffness>0</spring_stiffness>
        </dynamics>
        <use_parent_model_frame>1</use_parent_model_frame>
      </axis>
      <physics>
        <provide_feedback>1</provide_feedback>
        <ode>
          <provide_feedback>1</provide_feedback>
          <implicit_spring_damper>1</implicit_spring_damper>
          <cfm_damping>1</cfm_damping>
          <limit>
            <cfm>0</cfm>
            <erp>0.2</erp>
          </limit>
        </ode>
      </physics>
    </joint>
    <link name='lwr_arm_3_link'>
      <pose frame=''>0 0 0.52 0 -0 0</pose>
      <inertial>
        <pose frame=''>0 -0.06 0.13 0 -0 0</pose>
        <mass>2</mass>
        <inertia>
          <ixx>0.0136667</ixx>
          <ixy>0</ixy>
          <ixz>0</ixz>
          <iyy>0.0118667</iyy>
          <iyz>0</iyz>
          <izz>0.003</izz>
        </inertia>
      </inertial>
      <collision name='lwr_arm_3_link_collision'>
        <pose frame=''>0 0 0 0 -0 0</pose>
        <geometry>
          <mesh>
            <scale>1 1 1</scale>
            <uri>model://kuka-lwr-4plus-8dof/meshes/convex/arm_segment_a_convex.stl</uri>
          </mesh>
        </geometry>
      </collision>
      <visual name='lwr_arm_3_link_visual'>
        <pose frame=''>0 0 0 0 -0 0</pose>
        <geometry>
          <mesh>
            <scale>100 100 100</scale>
            <uri>model://kuka-lwr-4plus-8dof/meshes/arm_segment_a.dae</uri>
          </mesh>
        </geometry>
      </visual>
      <gravity>1</gravity>
      <velocity_decay/>
      <self_collide>0</self_collide>
    </link>
    <joint name='lwr_arm_2_joint' type='revolute'>
      <child>lwr_arm_3_link</child>
      <parent>lwr_arm_2_link</parent>
      <axis>
        <xyz>0 0 1</xyz>
        <limit>
          <lower>-2.96706</lower>
          <upper>2.96706</upper>
          <effort>204</effort>
          <velocity>2.26893</velocity>
        </limit>
        <dynamics>
          <damping>3</damping>
          <friction>0</friction>
          <spring_reference>0</spring_reference>
          <spring_stiffness>0</spring_stiffness>
        </dynamics>
        <use_parent_model_frame>1</use_parent_model_frame>
      </axis>
      <physics>
        <provide_feedback>1</provide_feedback>
        <ode>
          <provide_feedback>1</provide_feedback>
          <implicit_spring_damper>1</implicit_spring_damper>
          <cfm_damping>1</cfm_damping>
          <limit>
            <cfm>0</cfm>
            <erp>0.2</erp>
          </limit>
        </ode>
      </physics>
    </joint>
    <link name='lwr_arm_4_link'>
      <pose frame=''>0 0 0.72 0 -0 0</pose>
      <inertial>
        <pose frame=''>0 0.06 0.07 0 -0 0</pose>
        <mass>2</mass>
        <inertia>
          <ixx>0.0136667</ixx>
          <ixy>0</ixy>
          <ixz>0</ixz>
          <iyy>0.0118667</iyy>
          <iyz>0</iyz>
          <izz>0.003</izz>
        </inertia>
      </inertial>
      <collision name='lwr_arm_4_link_collision'>
        <pose frame=''>0 0 0.2 3.14159 -0 0</pose>
        <geometry>
          <mesh>
            <scale>1 1 1</scale>
            <uri>model://kuka-lwr-4plus-8dof/meshes/convex/arm_segment_b_convex.stl</uri>
          </mesh>
        </geometry>
      </collision>
      <visual name='lwr_arm_4_link_visual'>
        <pose frame=''>0 0 0.2 3.14159 -0 0</pose>
        <geometry>
          <mesh>
            <scale>100 100 100</scale>
            <uri>model://kuka-lwr-4plus-8dof/meshes/arm_segment_b.dae</uri>
          </mesh>
        </geometry>
      </visual>
      <gravity>1</gravity>
      <velocity_decay/>
      <self_collide>0</self_collide>
    </link>
    <joint name='lwr_arm_3_joint' type='revolute'>
      <child>lwr_arm_4_link</child>
      <parent>lwr_arm_3_link</parent>
      <axis>
        <xyz>0 1 0</xyz>
        <limit>
          <lower>-2.0944</lower>
          <upper>2.0944</upper>
          <effort>306</effort>
          <velocity>2.26893</velocity>
        </limit>
        <dynamics>
          <damping>3</damping>
          <friction>0</friction>
          <spring_reference>0</spring_reference>
          <spring_stiffness>0</spring_stiffness>
        </dynamics>
        <use_parent_model_frame>1</use_parent_model_frame>
      </axis>
      <physics>
        <provide_feedback>1</provide_feedback>
        <ode>
          <provide_feedback>1</provide_feedback>
          <implicit_spring_damper>1</implicit_spring_damper>
          <cfm_damping>1</cfm_damping>
          <limit>
            <cfm>0</cfm>
            <erp>0.2</erp>
          </limit>
        </ode>
      </physics>
    </joint>
    <link name='lwr_arm_5_link'>
      <pose frame=''>0 0 0.92 0 -0 0</pose>
      <inertial>
        <pose frame=''>0 0 0.124 0 -0 0</pose>
        <mass>2</mass>
        <inertia>
          <ixx>0.0126507</ixx>
          <ixy>0</ixy>
          <ixz>0</ixz>
          <iyy>0.0108507</iyy>
          <iyz>0</iyz>
          <izz>0.003</izz>
        </inertia>
      </inertial>
      <collision name='lwr_arm_5_link_collision'>
        <pose frame=''>0 0 0 0 -0 -3.14159</pose>
        <geometry>
          <mesh>
            <scale>1 1 1</scale>
            <uri>model://kuka-lwr-4plus-8dof/meshes/convex/arm_segment_last_convex.stl</uri>
          </mesh>
        </geometry>
      </collision>
      <visual name='lwr_arm_5_link_visual'>
        <pose frame=''>0 0 0 0 -0 -3.14159</pose>
        <geometry>
          <mesh>
            <scale>100 100 100</scale>
            <uri>model://kuka-lwr-4plus-8dof/meshes/arm_segment_last.dae</uri>
          </mesh>
        </geometry>
      </visual>
      <gravity>1</gravity>
      <velocity_decay/>
      <self_collide>0</self_collide>
    </link>
    <joint name='lwr_arm_4_joint' type='revolute'>
      <child>lwr_arm_5_link</child>
      <parent>lwr_arm_4_link</parent>
      <axis>
        <xyz>0 0 1</xyz>
        <limit>
          <lower>-2.96706</lower>
          <upper>2.96706</upper>
          <effort>204</effort>
          <velocity>2.26893</velocity>
        </limit>
        <dynamics>
          <damping>1</damping>
          <friction>0</friction>
          <spring_reference>0</spring_reference>
          <spring_stiffness>0</spring_stiffness>
        </dynamics>
        <use_parent_model_frame>1</use_parent_model_frame>
      </axis>
      <physics>
        <provide_feedback>1</provide_feedback>
        <ode>
          <provide_feedback>1</provide_feedback>
          <implicit_spring_damper>1</implicit_spring_damper>
          <cfm_damping>1</cfm_damping>
          <limit>
            <cfm>0</cfm>
            <erp>0.2</erp>
          </limit>
        </ode>
      </physics>
    </joint>
    <link name='lwr_arm_6_link'>
      <pose frame=''>0 0 1.11 0 -0 0</pose>
      <inertial>
        <pose frame=''>0 0 0 0 -0 0</pose>
        <mass>1</mass>
        <inertia>
          <ixx>0.00260417</ixx>
          <ixy>0</ixy>
          <ixz>0</ixz>
          <iyy>0.00260417</iyy>
          <iyz>0</iyz>
          <izz>0.00260417</izz>
        </inertia>
      </inertial>
      <collision name='lwr_arm_6_link_collision'>
        <pose frame=''>0 0 0 0 -0 -3.14159</pose>
        <geometry>
          <mesh>
            <scale>1 1 1</scale>
            <uri>model://kuka-lwr-4plus-8dof/meshes/convex/arm_wrist_convex.stl</uri>
          </mesh>
        </geometry>
      </collision>
      <visual name='lwr_arm_6_link_visual'>
        <pose frame=''>0 0 0 0 -0 -3.14159</pose>
        <geometry>
          <mesh>
            <scale>100 100 100</scale>
            <uri>model://kuka-lwr-4plus-8dof/meshes/arm_wrist.dae</uri>
          </mesh>
        </geometry>
      </visual>
      <gravity>1</gravity>
      <velocity_decay/>
      <self_collide>0</self_collide>
    </link>
    <joint name='lwr_arm_5_joint' type='revolute'>
      <child>lwr_arm_6_link</child>
      <parent>lwr_arm_5_link</parent>
      <axis>
        <xyz>0 -1 0</xyz>
        <limit>
          <lower>-2.0944</lower>
          <upper>2.0944</upper>
          <effort>306</effort>
          <velocity>3.14159</velocity>
        </limit>
        <dynamics>
          <damping>1</damping>
          <friction>0</friction>
          <spring_reference>0</spring_reference>
          <spring_stiffness>0</spring_stiffness>
        </dynamics>
        <use_parent_model_frame>1</use_parent_model_frame>
      </axis>
      <physics>
        <provide_feedback>1</provide_feedback>
        <ode>
          <provide_feedback>1</provide_feedback>
          <implicit_spring_damper>1</implicit_spring_damper>
          <cfm_damping>1</cfm_damping>
          <limit>
            <cfm>0</cfm>
            <erp>0.2</erp>
          </limit>
        </ode>
      </physics>
    </joint>
    <link name='lwr_arm_7_link'>
      <pose frame=''>0 0 1.188 0 -0 0</pose>
      <inertial>
        <pose frame=''>0 0 0 0 -0 0</pose>
        <mass>0.2</mass>
        <inertia>
          <ixx>6.66667e-05</ixx>
          <ixy>0</ixy>
          <ixz>0</ixz>
          <iyy>6.66667e-05</iyy>
          <iyz>0</iyz>
          <izz>0.00012</izz>
        </inertia>
      </inertial>
      <collision name='lwr_arm_7_link_collision'>
        <pose frame=''>0 0 0 0 -0 0</pose>
        <geometry>
          <mesh>
            <scale>100 100 100</scale>
            <uri>model://kuka-lwr-4plus-8dof/meshes/arm_flanche.dae</uri>
          </mesh>
        </geometry>
      </collision>
      <visual name='lwr_arm_7_link_visual'>
        <pose frame=''>0 0 0 0 -0 0</pose>
        <geometry>
          <mesh>
            <scale>100 100 100</scale>
            <uri>model://kuka-lwr-4plus-8dof/meshes/arm_flanche.dae</uri>
          </mesh>
        </geometry>
      </visual>
      <gravity>1</gravity>
      <velocity_decay/>
      <self_collide>0</self_collide>
    </link>
    <joint name='lwr_arm_6_joint' type='revolute'>
      <child>lwr_arm_7_link</child>
      <parent>lwr_arm_6_link</parent>
      <axis>
        <xyz>0 0 1</xyz>
        <limit>
          <lower>-2.96706</lower>
          <upper>2.96706</upper>
          <effort>204</effort>
          <velocity>3.14159</velocity>
        </limit>
        <dynamics>
          <damping>1</damping>
          <friction>0</friction>
          <spring_reference>0</spring_reference>
          <spring_stiffness>0</spring_stiffness>
        </dynamics>
        <use_parent_model_frame>1</use_parent_model_frame>
      </axis>
      <physics>
        <provide_feedback>1</provide_feedback>
        <ode>
          <provide_feedback>1</provide_feedback>
          <implicit_spring_damper>1</implicit_spring_damper>
          <cfm_damping>1</cfm_damping>
          <limit>
            <cfm>0</cfm>
            <erp>0.2</erp>
          </limit>
        </ode>
      </physics>
    </joint>
    <pose frame=''>0 0 0 0 -0 0</pose>
  </model>
</sdf>
