<?xml version="1.0" ?>
<!-- =================================================================================== -->
<!-- |    This document was autogenerated by xacro from kuka_lwr_arm.urdf.xml          | -->
<!-- |    EDITING THIS FILE BY HAND IS NOT RECOMMENDED                                 | -->
<!-- =================================================================================== -->
<robot name="lwr-3" xmlns:controller="http://playerstage.sourceforge.net/gazebo/xmlschema/#controller" xmlns:interface="http://playerstage.sourceforge.net/gazebo/xmlschema/#interface" xmlns:sensor="http://playerstage.sourceforge.net/gazebo/xmlschema/#sensor" xmlns:xacro="http://www.ros.org/wiki/xacro">
  <material name="DarkGrey">
    <color rgba="0.3 0.3 0.3 1.0"/>
  </material>
  <material name="Red">
    <color rgba="0.3 0.3 0.3 1.0"/>
  </material>
  <material name="Black">
    <color rgba="0 0 0 1.0"/>
  </material>
  <material name="Orange">
    <color rgba="1.0 0.487 0 1.0"/>
  </material>
  <material name="Silver">
    <color rgba="1.0 1.0 1.0 1.0"/>
  </material>
  <material name="Grey">
    <color rgba="0.7 0.7 0.7 1.0"/>
  </material>
  <material name="Blue">
    <color rgba="0.0 0.0 0.8 1.0"/>
  </material>
  <material name="HandGray">
    <color rgba="0.953 0.996 0.694 1.0"/>
  </material>
  <material name="SickBlue">
    <color rgba="0.3058 0.5921 0.7294 1.0"/>
  </material>

<link name="world"/>
<joint name="world_base_joint" type="fixed">
    <origin rpy="0 0 0" xyz="0 0 0.02"/>
    <parent link="world"/>
    <child link="base"/>
  </joint>

   <link name="base">
    <inertial>
      <mass value="50.0"/>
      <com xyz="0 0 0"/>
      <inertia ixx="0.01" ixy="0.00" ixz="0.00" iyy="0.01" iyz="0.00" izz="0.01"/>
    </inertial>
    <visual>
      <origin rpy="0 0 0" xyz="0 0 0"/>
      <geometry>
        <box size=".7 .75 0.04"/>
      </geometry>
      <material name="DarkGrey"/>
    </visual>
    <collision>
      <origin rpy="0 0 0" xyz="0 0 0"/>
      <geometry>
        <box size=".8 .85 0.04"/>
      </geometry>
    </collision>
  </link>

  <joint name="base_lwr_arm_0_joint" type="fixed">
    <origin rpy="0 0 0" xyz="0 0 0"/>
    <parent link="base"/>
    <child link="lwr_arm_0_link"/>
  </joint>
  <link name="lwr_arm_0_link">
    <inertial>
      <mass value="2.0"/>
      <origin xyz="0 0 0.055"/>
      <inertia ixx="0.00381666666667" ixy="0" ixz="0" iyy="0.0036" iyz="0" izz="0.00381666666667"/>
    </inertial>
    <visual>
      <origin rpy="0 0 3.14159265359" xyz="0 0 0"/>
      <geometry>
        <mesh filename="model://kuka-lwr-3/meshes/lwr/base.stl"/>
      </geometry>
      <material name="Orange"/>
    </visual>
    <collision>
      <origin rpy="0 0 0" xyz="0 0 0.055"/>
      <geometry>
        <cylinder length="0.11" radius="0.07"/>
      </geometry>
    </collision>
  </link>
  <joint name="lwr_arm_0_joint" type="revolute">
    <origin rpy="0 0 3.14159265359" xyz="0 0 0.11"/>
    <axis xyz="0 0 1"/>
    <limit effort="204" lower="-2.96705972839" upper="2.96705972839" velocity="1.91986217719"/>
    <safety_controller k_position="30" k_velocity="30" soft_lower_limit="-2.93215314335" soft_upper_limit="2.93215314335"/>
    <dynamics damping="1.0"/>
    <parent link="lwr_arm_0_link"/>
    <child link="lwr_arm_1_link"/>
  </joint>
  <link name="lwr_arm_1_link">
    <inertial>
      <mass value="2.0"/>
      <origin rpy="0 0 0" xyz="0 -0.06 0.130"/>
      <inertia ixx="0.0136666666667" ixy="0" ixz="0" iyy="0.003" iyz="0" izz="0.0118666666667"/>
    </inertial>
    <visual>
      <origin rpy="0 0 0" xyz="0 0 -0.008"/>
      <geometry>
        <mesh filename="model://kuka-lwr-3/meshes/lwr/link_1.stl"/>
      </geometry>
      <material name="Orange"/>
    </visual>
    <collision>
      <origin rpy="0 0 0" xyz="0 0 0.0"/>
      <geometry>
        <sphere radius="0.07"/>
      </geometry>
    </collision>
    <collision>
      <origin rpy="0 0 0" xyz="0 -0.06 0.2"/>
      <geometry>
        <sphere radius="0.07"/>
      </geometry>
    </collision>
    <collision>
      <origin rpy="0.291 0 0" xyz="0 -0.03 0.1"/>
      <geometry>
        <cylinder length="0.208" radius="0.07"/>
      </geometry>
    </collision>
  </link>
  <gazebo reference="lwr_arm_1_link">
    <gravity>false</gravity>
  </gazebo>
  <transmission name="lwr_arm_0_trans" type="SimpleTransmission">
    <actuator name="lwr_arm_0_motor"/>
    <joint name="lwr_arm_0_joint"/>
    <mechanicalReduction>1.0</mechanicalReduction>
  </transmission>
  <joint name="lwr_arm_1_joint" type="revolute">
    <origin rpy="0 0 0" xyz="0 0 0.2"/>
    <axis xyz="0 1 0"/>
    <limit effort="306" lower="-2.09439510239" upper="2.09439510239" velocity="1.91986217719"/>
    <safety_controller k_position="30" k_velocity="30" soft_lower_limit="-2.05948851735" soft_upper_limit="2.05948851735"/>
    <dynamics damping="1.0" friction="10"/>
    <parent link="lwr_arm_1_link"/>
    <child link="lwr_arm_2_link"/>
  </joint>
  <link name="lwr_arm_2_link">
    <inertial>
      <mass value="2.0"/>
      <origin rpy="0 0 0" xyz="0 0.06 0.07"/>
      <inertia ixx="0.0136666666667" ixy="0" ixz="0" iyy="0.003" iyz="0" izz="0.0118666666667"/>
    </inertial>
    <visual>
      <origin rpy="0 0 0" xyz="0 0 0.0"/>
      <geometry>
        <mesh filename="model://kuka-lwr-3/meshes/lwr/link_2.stl"/>
      </geometry>
      <material name="Orange"/>
    </visual>
    <collision>
      <origin rpy="0 0 0" xyz="0 0 0.2"/>
      <geometry>
        <sphere radius="0.07"/>
      </geometry>
    </collision>
    <collision>
      <origin rpy="0 0 0" xyz="0 0.06 0.0"/>
      <geometry>
        <sphere radius="0.07"/>
      </geometry>
    </collision>
    <collision>
      <origin rpy="0.291 0 0" xyz="0 0.03 0.1"/>
      <geometry>
        <cylinder length="0.208" radius="0.07"/>
      </geometry>
    </collision>
  </link>
  <gazebo reference="lwr_arm_2_link">
    <gravity>false</gravity>
  </gazebo>
  <transmission name="lwr_arm_1_trans" type="SimpleTransmission">
    <actuator name="lwr_arm_1_motor"/>
    <joint name="lwr_arm_1_joint"/>
    <mechanicalReduction>1.0</mechanicalReduction>
  </transmission>
  <joint name="lwr_arm_2_joint" type="revolute">
    <origin rpy="0 0 0" xyz="0 0 0.20"/>
    <axis xyz="0 0 1"/>
    <limit effort="204" lower="-2.96705972839" upper="2.96705972839" velocity="2.26892802759"/>
    <safety_controller k_position="30" k_velocity="30" soft_lower_limit="-2.93215314335" soft_upper_limit="2.93215314335"/>
    <dynamics damping="1.0"/>
    <parent link="lwr_arm_2_link"/>
    <child link="lwr_arm_3_link"/>
  </joint>
  <link name="lwr_arm_3_link">
    <inertial>
      <mass value="2.0"/>
      <origin rpy="0 0 0" xyz="0 0.06 0.130"/>
      <inertia ixx="0.0136666666667" ixy="0" ixz="0" iyy="0.003" iyz="0" izz="0.0118666666667"/>
    </inertial>
    <visual>
      <origin rpy="0 0 0" xyz="0 0 -0.008"/>
      <geometry>
        <mesh filename="model://kuka-lwr-3/meshes/lwr/link_3.stl"/>
      </geometry>
      <material name="Orange"/>
    </visual>
    <collision>
      <origin rpy="0 0 0" xyz="0 0 0.0"/>
      <geometry>
        <sphere radius="0.07"/>
      </geometry>
    </collision>
    <collision>
      <origin rpy="0 0 0" xyz="0 0.06 0.2"/>
      <geometry>
        <sphere radius="0.07"/>
      </geometry>
    </collision>
    <collision>
      <origin rpy="-0.291 0 0" xyz="0 0.03 0.1"/>
      <geometry>
        <cylinder length="0.208" radius="0.07"/>
      </geometry>
    </collision>
  </link>
  <gazebo reference="lwr_arm_3_link">
    <gravity>false</gravity>
  </gazebo>
  <transmission name="lwr_arm_2_trans" type="SimpleTransmission">
    <actuator name="lwr_arm_2_motor"/>
    <joint name="lwr_arm_2_joint"/>
    <mechanicalReduction>1.0</mechanicalReduction>
  </transmission>
  <joint name="lwr_arm_3_joint" type="revolute">
    <origin rpy="0 0 0" xyz="0 0 0.20"/>
    <axis xyz="0 -1 0"/>
    <limit effort="306" lower="-2.09439510239" upper="2.09439510239" velocity="2.26892802759"/>
    <safety_controller k_position="30" k_velocity="30" soft_lower_limit="-2.05948851735" soft_upper_limit="2.05948851735"/>
    <dynamics damping="1.0"/>
    <parent link="lwr_arm_3_link"/>
    <child link="lwr_arm_4_link"/>
  </joint>
  <link name="lwr_arm_4_link">
    <inertial>
      <mass value="2.0"/>
      <origin rpy="0 0 0" xyz="0 -0.06 0.07"/>
      <inertia ixx="0.0136666666667" ixy="0" ixz="0" iyy="0.003" iyz="0" izz="0.0118666666667"/>
    </inertial>
    <visual>
      <origin rpy="0 0 0" xyz="0 0 0.0"/>
      <geometry>
        <mesh filename="model://kuka-lwr-3/meshes/lwr/link_4.stl"/>
      </geometry>
      <material name="Orange"/>
    </visual>
    <collision>
      <origin rpy="0 0 0" xyz="0 0 0.2"/>
      <geometry>
        <sphere radius="0.07"/>
      </geometry>
    </collision>
    <collision>
      <origin rpy="0 0 0" xyz="0 -0.06 0.0"/>
      <geometry>
        <sphere radius="0.07"/>
      </geometry>
    </collision>
    <collision>
      <origin rpy="-0.291 0 0" xyz="0 -0.03 0.1"/>
      <geometry>
        <cylinder length="0.208" radius="0.07"/>
      </geometry>
    </collision>
  </link>
  <gazebo reference="lwr_arm_4_link">
    <gravity>false</gravity>
  </gazebo>
  <transmission name="lwr_arm_3_trans" type="SimpleTransmission">
    <actuator name="lwr_arm_3_motor"/>
    <joint name="lwr_arm_3_joint"/>
    <mechanicalReduction>1.0</mechanicalReduction>
  </transmission>
  <joint name="lwr_arm_4_joint" type="revolute">
    <origin rpy="0 0 0" xyz="0 0 0.20"/>
    <axis xyz="0 0 1"/>
    <limit effort="204" lower="-2.96705972839" upper="2.96705972839" velocity="2.26892802759"/>
    <safety_controller k_position="30" k_velocity="30" soft_lower_limit="-2.93215314335" soft_upper_limit="2.93215314335"/>
    <dynamics damping="1.0"/>
    <parent link="lwr_arm_4_link"/>
    <child link="lwr_arm_5_link"/>
  </joint>
  <link name="lwr_arm_5_link">
    <inertial>
      <mass value="2.0"/>
      <origin rpy="0 0 0" xyz="0 0 0.124"/>
      <inertia ixx="0.0126506666667" ixy="0" ixz="0" iyy="0.003" iyz="0" izz="0.0108506666667"/>
    </inertial>
    <visual>
      <origin rpy="0 0 0" xyz="0 0 -0.008"/>
      <geometry name="lwr_arm_5_geom">
        <mesh filename="model://kuka-lwr-3/meshes/lwr/link_5.stl"/>
      </geometry>
      <material name="Orange"/>
    </visual>
    <collision>
      <origin rpy="0 0 0" xyz="0 0 0.0"/>
      <geometry>
        <sphere radius="0.07"/>
      </geometry>
    </collision>
    <collision>
      <origin rpy="0 0 0" xyz="0 -0.04 0.19"/>
      <geometry>
        <sphere radius="0.07"/>
      </geometry>
    </collision>
    <collision>
      <origin rpy="0.207 0 0" xyz="0 -0.02 0.095"/>
      <geometry>
        <cylinder length="0.198" radius="0.07"/>
      </geometry>
    </collision>
  </link>
  <gazebo reference="lwr_arm_5_link">
    <gravity>false</gravity>
  </gazebo>
  <transmission name="lwr_arm_4_trans" type="SimpleTransmission">
    <actuator name="lwr_arm_4_motor"/>
    <joint name="lwr_arm_4_joint"/>
    <mechanicalReduction>1.0</mechanicalReduction>
  </transmission>
  <joint name="lwr_arm_5_joint" type="revolute">
    <origin rpy="0 0 0" xyz="0 0 0.19"/>
    <axis xyz="0 1 0"/>
    <limit effort="306" lower="-2.09439510239" upper="2.09439510239" velocity="3.14159265359"/>
    <safety_controller k_position="30" k_velocity="30" soft_lower_limit="-2.05948851735" soft_upper_limit="2.05948851735"/>
    <dynamics damping="1.0"/>
    <parent link="lwr_arm_5_link"/>
    <child link="lwr_arm_6_link"/>
  </joint>
  <link name="lwr_arm_6_link">
    <inertial>
      <mass value="0.2"/>
      <origin rpy="0 0 0" xyz="0 0 0.0625"/>
      <inertia ixx="0.000520833333333" ixy="0" ixz="0" iyy="0.000520833333333" iyz="0" izz="0.000520833333333"/>
    </inertial>
    <visual>
      <origin rpy="0 0 0" xyz="0 0 0"/>
      <geometry>
        <mesh filename="model://kuka-lwr-3/meshes/lwr/link_6.stl"/>
      </geometry>
      <material name="Grey"/>
    </visual>
    <collision>
      <origin rpy="0 0 0" xyz="0 0 0"/>
      <geometry>
        <mesh filename="model://kuka-lwr-3/meshes/lwr/convex/arm_wrist_convex.stl"/>
      </geometry>
    </collision>
  </link>
  <gazebo reference="lwr_arm_6_link">
    <gravity>false</gravity>
  </gazebo>
  <transmission name="lwr_arm_5_trans" type="SimpleTransmission">
    <actuator name="lwr_arm_5_motor"/>
    <joint name="lwr_arm_5_joint"/>
    <mechanicalReduction>1.0</mechanicalReduction>
  </transmission>
  <joint name="lwr_arm_6_joint" type="revolute">
    <origin rpy="0 0 3.14159265359" xyz="0 0 0.108"/><!--0.078-->
    <axis xyz="0 0 1"/>
    <limit effort="204" lower="-2.96705972839" upper="2.96705972839" velocity="3.14159265359"/>
    <safety_controller k_position="30" k_velocity="30" soft_lower_limit="-2.93215314335" soft_upper_limit="2.93215314335"/>
    <dynamics damping="1.0"/>
    <parent link="lwr_arm_6_link"/>
    <child link="lwr_arm_7_link"/>
  </joint>
  <link name="lwr_arm_7_link">
    <inertial>
      <mass value="0.2"/>
      <origin xyz="0 0 -0.03"/>
      <inertia ixx="0.0333333333333" ixy="0" ixz="0" iyy="0.0333333333333" iyz="0" izz="0.0333333333333"/>
    </inertial>
    <visual>
      <origin rpy="0 0 0" xyz="0 0 -0.03"/>
      <geometry>
        <mesh filename="model://kuka-lwr-3/meshes/lwr/link_7.stl"/>
      </geometry>
      <material name="Grey"/>
    </visual>
    <collision>
      <origin rpy="0 0 -0.785398163397" xyz="0 0 -0.015"/>
      <geometry>
        <cylinder length="0.03" radius="0.04"/>
      </geometry>
    </collision>
  </link>
  <gazebo reference="lwr_arm_7_link">
    <gravity>false</gravity>
  </gazebo>

  <transmission name="lwr_arm_6_trans" type="SimpleTransmission">
    <actuator name="lwr_arm_6_motor"/>
    <joint name="lwr_arm_6_joint"/>
    <mechanicalReduction>1.0</mechanicalReduction>
  </transmission>

  <!--<link name="force_torque_sensor">
    <inertial>
      <mass value="0.2"/>
      <origin xyz="0 0 0"/>
      <inertia ixx="0.0333333333333" ixy="0" ixz="0" iyy="0.0333333333333" iyz="0" izz="0.0333333333333"/>
    </inertial>
    <visual>
      <origin rpy="0 0 0" xyz="0 0 -0.065"/>
      <geometry>
        <cylinder length="0.09" radius="0.025"/>
      </geometry>
      <material name="Grey"/>
    </visual>
    <visual>
      <origin rpy="0 0 0" xyz="0 0 -0.016"/>
      <geometry>
        <cylinder length="0.032" radius="0.0375"/>
      </geometry>
      <material name="Grey"/>
    </visual>
    <visual>
      <origin rpy="0 0 0" xyz="0 0 0.01"/>
      <geometry>
        <cylinder length="0.02" radius="0.0375"/>
      </geometry>
      <material name="Grey"/>
    </visual>
  </link>
  <gazebo reference="force_torque_sensor">
    <gravity>false</gravity>
  </gazebo>
  <joint name="force_torque_sensor_mount" type="fixed">
    <origin rpy="0 0 0.22" xyz="0 0 0.102"/>
    <parent link="lwr_arm_7_link"/>
    <child link="force_torque_sensor"/>
  </joint>
  <link name="contact_point">
    <visual>
      <origin rpy="0 0 0" xyz="0 0 0"/>
      <geometry>
        <sphere radius="0.0375"/>
      </geometry>
      <material name="Grey"/>
    </visual>
  </link>
  <joint name="contact_point_joint" type="fixed">
    <origin rpy="0 0 -0.22" xyz="0 0 0.03"/>
    <parent link="force_torque_sensor"/>
    <child link="contact_point"/>
  </joint>-->
</robot>

