<robot name="BI-kuka-lwr-4plus-triangle-tilted-bh8-setup" xmlns:controller="http://playerstage.sourceforge.net/gazebo/xmlschema/#controller" xmlns:interface="http://playerstage.sourceforge.net/gazebo/xmlschema/#interface" xmlns:sensor="http://playerstage.sourceforge.net/gazebo/xmlschema/#sensor" xmlns:xacro="http://www.ros.org/wiki/xacro">
    <material name="DarkGrey">
        <color rgba="0.3 0.3 0.3 1.0" />
    </material>
    <material name="Red">
        <color rgba="0.3 0.3 0.3 1.0" />
    </material>
    <material name="Black">
        <color rgba="0 0 0 1.0" />
    </material>
    <material name="Orange">
        <color rgba="1.0 0.487 0 1.0" />
    </material>
    <material name="Silver">
        <color rgba="1.0 1.0 1.0 1.0" />
    </material>
    <material name="Grey">
        <color rgba="0.7 0.7 0.7 1.0" />
    </material>
    <material name="Blue">
        <color rgba="0.0 0.0 0.8 1.0" />
    </material>
    <material name="HandGray">
        <color rgba="0.953 0.996 0.694 1.0" />
    </material>
    <material name="SickBlue">
        <color rgba="0.3058 0.5921 0.7294 1.0" />
    </material>
    <link name="world" />
    <joint name="left_arm_world_joint" type="fixed">
        <origin rpy="0.46365 0.25268 2.6779" xyz="0 0.15 0.01" />
        <!-- <origin rpy="0.46373 0.25255 2.6780" xyz="0 0.15 0.01"/> -->
        <parent link="world" />
        <child link="left_lwr_arm_base_link" />
    </joint>
    <!--link name="world_link"> 
    <inertial>
      <mass value="50.0"/>
      <com xyz="0 0 0"/>
      <inertia ixx="0.01" ixy="0.00" ixz="0.00" iyy="0.01" iyz="0.00" izz="0.01"/>
    </inertial>
    <visual>
      <origin rpy="0 0 0" xyz="0 0 0.95"/>
      <geometry>
        <box size="0.5 0.5 0.05"/>
      </geometry>
    </visual>
    <collision>
      <origin rpy="0 0 0" xyz="0 0 0.50"/>
      <geometry>
        <box size="0.5 0.5 0.05"/>
      </geometry>
    </collision>
  </link-->
    <!-- First (shoulder) element of the arm. Fixed to its parent. -->
    <!--joint name="world_left_lwr_arm_base_joint" type="fixed">
    <origin rpy="0 0 0" xyz="0 0 1.1"/>
    <parent link="world_link"/>
    <child link="left_lwr_arm_base_link"/>
  </joint-->
    <link name="left_lwr_arm_base_link">
        <inertial>
            <mass value="1.2" />
            <origin rpy="0 0 0" xyz="0 0 0.055" />
            <inertia ixx="0.00229" ixy="0" ixz="0" iyy="0.00216" iyz="0" izz="0.00229" />
        </inertial>
        <visual>
            <origin rpy="0 0 0" xyz="0 0 0" />
            <geometry>
                <mesh filename="model://kuka-lwr-4plus/meshes/arm_base.dae" scale="100 100 100" />
            </geometry>
            <material name="Orange" />
        </visual>
        <!--collision>
            <origin rpy="0 0 0" xyz="0 0 0.01" />
            <geometry>
                <mesh filename="model://kuka-lwr-4plus/meshes/convex/arm_base_convex.stl" scale="0.9 0.9 0.9" />
            </geometry>
        </collision-->
    </link>
    <gazebo reference="left_lwr_arm_base_link">
        <!--<material value="kuka-lwr.material"/>-->
    </gazebo>
    <joint name="left_lwr_arm_0_joint" type="revolute">
        <origin rpy="0 0 0" xyz="0 0 0.11" />
        <axis xyz="0 0 1" />
        <limit effort="204" lower="-2.96705972839" upper="2.96705972839" velocity="1.91986217719" />
        <safety_controller k_position="100" k_velocity="2" soft_lower_limit="-2.93215314335" soft_upper_limit="2.93215314335" />
        <dynamics damping="5.0" />
        <parent link="left_lwr_arm_base_link" />
        <child link="left_lwr_arm_1_link" />
    </joint>
    <gazebo reference="left_lwr_arm_0_joint">
        <provideFeedback>1</provideFeedback>
        <implicitSpringDamper>1</implicitSpringDamper>
    </gazebo>
    <transmission name="left_lwr_arm_0_trans" type="SimpleTransmission">
        <actuator name="left_lwr_arm_0_motor" />
        <joint name="left_lwr_arm_0_joint" />
        <mechanicalReduction>1.0</mechanicalReduction>
    </transmission>
    <link name="left_lwr_arm_1_link">
        <inertial>
            <mass value="2.0" />
            <origin rpy="0 0 0" xyz="0 0 0.130" />
            <inertia ixx="0.0136666666667" ixy="0" ixz="0" iyy="0.0118666666667" iyz="0" izz="0.003" />
        </inertial>
        <visual>
            <origin rpy="0 0 3.14159265359" xyz="0 0 0" />
            <geometry>
                <mesh filename="model://kuka-lwr-4plus/meshes/arm_segment_a.dae" scale="100 100 100" />
            </geometry>
            <material name="Orange" />
        </visual>
        <collision>
            <origin rpy="0 0 3.14159265359" xyz="0 0 0" />
            <geometry>
                <mesh filename="model://kuka-lwr-4plus/meshes/convex/arm_segment_a_convex.stl" scale="1.0 1.0 1.0" />
            </geometry>
        </collision>
    </link>
    <gazebo reference="left_lwr_arm_1_link">
        <!--<material value="kuka-lwr.material"/>-->
    </gazebo>
    <joint name="left_lwr_arm_1_joint" type="revolute">
        <origin rpy="0 0 0" xyz="0 0 0.20" />
        <axis xyz="0 -1 0" />
        <limit effort="306" lower="-2.09439510239" upper="2.09439510239" velocity="1.91986217719" />
        <safety_controller k_position="100" k_velocity="2" soft_lower_limit="-2.05948851735" soft_upper_limit="2.05948851735" />
        <dynamics damping="5.0" />
        <parent link="left_lwr_arm_1_link" />
        <child link="left_lwr_arm_2_link" />
    </joint>
    <gazebo reference="left_lwr_arm_1_joint">
        <provideFeedback>1</provideFeedback>
        <implicitSpringDamper>1</implicitSpringDamper>
    </gazebo>
    <transmission name="left_lwr_arm_1_trans" type="pr2_mechanism_model/SimpleTransmission">
        <actuator name="left_lwr_arm_1_motor" />
        <joint name="left_lwr_arm_1_joint" />
        <mechanicalReduction>1.0</mechanicalReduction>
    </transmission>
    <link name="left_lwr_arm_2_link">
        <inertial>
            <mass value="2.0" />
            <origin rpy="0 0 0" xyz="0 -0.06 0.07" />
            <inertia ixx="0.0136666666667" ixy="0" ixz="0" iyy="0.0118666666667" iyz="0" izz="0.003" />
        </inertial>
        <visual>
            <origin rpy="3.14159265359 0 3.14159265359" xyz="0 0 0.2" />
            <geometry>
                <mesh filename="model://kuka-lwr-4plus/meshes/arm_segment_b.dae" scale="100 100 100" />
            </geometry>
            <material name="Orange" />
        </visual>
        <collision>
            <origin rpy="3.14159265359 0 3.14159265359" xyz="0 0 0.2" />
            <geometry>
                <mesh filename="model://kuka-lwr-4plus/meshes/convex/arm_segment_b_convex.stl" scale="1.0 1.0 1.0" />
            </geometry>
        </collision>
    </link>
    <gazebo reference="left_lwr_arm_2_link">
        <!--<material value="kuka-lwr.material"/>-->
    </gazebo>
    <joint name="left_lwr_arm_2_joint" type="revolute">
        <origin rpy="0 0 0" xyz="0 0 0.20" />
        <axis xyz="0 0 1" />
        <limit effort="204" lower="-2.96705972839" upper="2.96705972839" velocity="2.26892802759" />
        <safety_controller k_position="100" k_velocity="2" soft_lower_limit="-2.93215314335" soft_upper_limit="2.93215314335" />
        <dynamics damping="3.0" />
        <parent link="left_lwr_arm_2_link" />
        <child link="left_lwr_arm_3_link" />
    </joint>
    <gazebo reference="left_lwr_arm_2_joint">
        <provideFeedback>1</provideFeedback>
        <implicitSpringDamper>1</implicitSpringDamper>
    </gazebo>
    <transmission name="left_lwr_arm_2_trans" type="SimpleTransmission">
        <actuator name="left_lwr_arm_2_motor" />
        <joint name="left_lwr_arm_2_joint" />
        <mechanicalReduction>1.0</mechanicalReduction>
    </transmission>
    <link name="left_lwr_arm_3_link">
        <inertial>
            <mass value="2.0" />
            <origin rpy="0 0 0" xyz="0 -0.06 0.130" />
            <inertia ixx="0.0136666666667" ixy="0" ixz="0" iyy="0.0118666666667" iyz="0" izz="0.003" />
        </inertial>
        <visual>
            <origin rpy="0 0 0" xyz="0 0 0" />
            <geometry>
                <mesh filename="model://kuka-lwr-4plus/meshes/arm_segment_a.dae" scale="100 100 100" />
            </geometry>
            <material name="Orange" />
        </visual>
        <collision>
            <origin rpy="0 0 0" xyz="0 0 0" />
            <geometry>
                <mesh filename="model://kuka-lwr-4plus/meshes/convex/arm_segment_a_convex.stl" scale="1.0 1.0 1.0" />
            </geometry>
        </collision>
    </link>
    <gazebo reference="left_lwr_arm_3_link">
        <!--<material value="kuka-lwr.material"/>-->
    </gazebo>
    <joint name="left_lwr_arm_3_joint" type="revolute">
        <origin rpy="0 0 0" xyz="0 0 0.20" />
        <axis xyz="0 1 0" />
        <limit effort="306" lower="-2.09439510239" upper="2.09439510239" velocity="2.26892802759" />
        <safety_controller k_position="100" k_velocity="2" soft_lower_limit="-2.05948851735" soft_upper_limit="2.05948851735" />
        <dynamics damping="3.0" />
        <parent link="left_lwr_arm_3_link" />
        <child link="left_lwr_arm_4_link" />
    </joint>
    <gazebo reference="left_lwr_arm_3_joint">
        <provideFeedback>1</provideFeedback>
        <implicitSpringDamper>1</implicitSpringDamper>
    </gazebo>
    <transmission name="left_lwr_arm_3_trans" type="SimpleTransmission">
        <actuator name="left_lwr_arm_3_motor" />
        <joint name="left_lwr_arm_3_joint" />
        <mechanicalReduction>1.0</mechanicalReduction>
    </transmission>
    <link name="left_lwr_arm_4_link">
        <inertial>
            <mass value="2.0" />
            <origin rpy="0 0 0" xyz="0 0.06 0.07" />
            <inertia ixx="0.0136666666667" ixy="0" ixz="0" iyy="0.0118666666667" iyz="0" izz="0.003" />
        </inertial>
        <visual>
            <origin rpy="0 3.14159265359 3.14159265359" xyz="0 0 0.2" />
            <geometry>
                <mesh filename="model://kuka-lwr-4plus/meshes/arm_segment_b.dae" scale="100 100 100" />
            </geometry>
            <material name="Orange" />
        </visual>
        <collision>
            <origin rpy="0 3.14159265359 3.14159265359" xyz="0 0 0.2" />
            <geometry>
                <mesh filename="model://kuka-lwr-4plus/meshes/convex/arm_segment_b_convex.stl" scale="1.0 1.0 1.0" />
            </geometry>
        </collision>
    </link>
    <gazebo reference="left_lwr_arm_4_link">
        <!--<material value="kuka-lwr.material"/>-->
    </gazebo>
    <joint name="left_lwr_arm_4_joint" type="revolute">
        <origin rpy="0 0 0" xyz="0 0 0.20" />
        <axis xyz="0 0 1" />
        <limit effort="204" lower="-2.96705972839" upper="2.96705972839" velocity="2.26892802759" />
        <safety_controller k_position="100" k_velocity="2" soft_lower_limit="-2.93215314335" soft_upper_limit="2.93215314335" />
        <dynamics damping="1.0" />
        <parent link="left_lwr_arm_4_link" />
        <child link="left_lwr_arm_5_link" />
    </joint>
    <gazebo reference="left_lwr_arm_4_joint">
        <provideFeedback>1</provideFeedback>
        <implicitSpringDamper>1</implicitSpringDamper>
    </gazebo>
    <transmission name="left_lwr_arm_4_trans" type="SimpleTransmission">
        <actuator name="left_lwr_arm_4_motor" />
        <joint name="left_lwr_arm_4_joint" />
        <mechanicalReduction>1.0</mechanicalReduction>
    </transmission>
    <link name="left_lwr_arm_5_link">
        <inertial>
            <mass value="2.0" />
            <origin rpy="0 0 0" xyz="0 0 0.124" />
            <inertia ixx="0.0126506666667" ixy="0" ixz="0" iyy="0.0108506666667" iyz="0" izz="0.003" />
        </inertial>
        <visual>
            <origin rpy="0 0 3.14159265359" xyz="0 0 0" />
            <geometry name="left_lwr_arm_5_geom">
                <mesh filename="model://kuka-lwr-4plus/meshes/arm_segment_last.dae" scale="100 100 100" />
            </geometry>
            <material name="Orange" />
        </visual>
        <collision>
            <origin rpy="0 0 3.14159265359" xyz="0 0 0" />
            <geometry>
                <mesh filename="model://kuka-lwr-4plus/meshes/convex/arm_segment_last_convex.stl" scale="1.0 1.0 1.0" />
            </geometry>
        </collision>
    </link>
    <gazebo reference="left_lwr_arm_5_link">
        <!--<material value="kuka-lwr.material"/>-->
    </gazebo>
    <joint name="left_lwr_arm_5_joint" type="revolute">
        <origin rpy="0 0 0" xyz="0 0 0.19" />
        <axis xyz="0 -1 0" />
        <limit effort="306" lower="-2.09439510239" upper="2.09439510239" velocity="3.14159265359" />
        <safety_controller k_position="100" k_velocity="2" soft_lower_limit="-2.05948851735" soft_upper_limit="2.05948851735" />
        <dynamics damping="1.0" />
        <parent link="left_lwr_arm_5_link" />
        <child link="left_lwr_arm_6_link" />
    </joint>
    <gazebo reference="left_lwr_arm_5_joint">
        <provideFeedback>1</provideFeedback>
        <implicitSpringDamper>1</implicitSpringDamper>
    </gazebo>
    <transmission name="left_lwr_arm_5_trans" type="SimpleTransmission">
        <actuator name="left_lwr_arm_5_motor" />
        <joint name="left_lwr_arm_5_joint" />
        <mechanicalReduction>1.0</mechanicalReduction>
    </transmission>
    <link name="left_lwr_arm_6_link">
        <inertial>
            <mass value="1.0" />
            <origin rpy="0 0 0" xyz="0 0 0.0" />
            <inertia ixx="0.00260416666667" ixy="0" ixz="0" iyy="0.00260416666667" iyz="0" izz="0.00260416666667" />
        </inertial>
        <visual>
            <origin rpy="0 0 3.14159265359" xyz="0 0 0" />
            <geometry>
                <mesh filename="model://kuka-lwr-4plus/meshes/arm_wrist.dae" scale="100 100 100" />
            </geometry>
            <material name="Grey" />
        </visual>
        <collision>
            <origin rpy="0 0 3.14159265359" xyz="0 0 0" />
            <geometry>
                <mesh filename="model://kuka-lwr-4plus/meshes/convex/arm_wrist_convex.stl" scale="1.0 1.0 1.0" />
            </geometry>
        </collision>
    </link>
    <gazebo reference="left_lwr_arm_6_link">
        <!--<material value="kuka-lwr.material"/>-->
    </gazebo>
    <joint name="left_lwr_arm_6_joint" type="revolute">
        <origin rpy="0 0 0" xyz="0 0 0.078" />
        <axis xyz="0 0 1" />
        <limit effort="204" lower="-2.96705972839" upper="2.96705972839" velocity="3.14159265359" />
        <safety_controller k_position="100" k_velocity="2" soft_lower_limit="-2.93215314335" soft_upper_limit="2.93215314335" />
        <dynamics damping="1.0" />
        <parent link="left_lwr_arm_6_link" />
        <child link="left_lwr_arm_7_link" />
    </joint>
    <gazebo reference="left_lwr_arm_6_joint">
        <provideFeedback>1</provideFeedback>
        <implicitSpringDamper>1</implicitSpringDamper>
    </gazebo>
    <transmission name="left_lwr_arm_6_trans" type="SimpleTransmission">
        <actuator name="left_lwr_arm_6_motor" />
        <joint name="left_lwr_arm_6_joint" />
        <mechanicalReduction>1.0</mechanicalReduction>
    </transmission>
    <link name="left_lwr_arm_7_link">
        <inertial>
            <mass value="0.2" />
            <origin xyz="0 0 0" />
            <inertia ixx="6.66666666667e-05" ixy="0" ixz="0" iyy="6.66666666667e-05" iyz="0" izz="0.00012" />
        </inertial>
        <visual>
            <origin rpy="0 0 0" xyz="0 0 0" />
            <geometry>
                <mesh filename="model://kuka-lwr-4plus/meshes/arm_flanche.dae" scale="100 100 100" />
            </geometry>
            <material name="Grey" />
        </visual>
        <collision>
            <origin rpy="0 0 0" xyz="0 0 0" />
            <geometry>
                <!--mesh filename="model://kuka-lwr-4plus/meshes/convex/arm_flanche_convex.stl" scale="1.0 1.0 1.0"/-->
                <mesh filename="model://kuka-lwr-4plus/meshes/arm_flanche.dae" scale="100 100 100" />
            </geometry>
            <surface>
                <friction>
                    <ode>
                        <mu>0.0</mu>
                        <mu2>0.0</mu2>
                    </ode>
                </friction>
            </surface>
        </collision>
    </link>
    <gazebo reference="left_lwr_arm_7_link">
        <!--<material value="kuka-lwr.material"/>-->
    </gazebo>
<joint name="left_lwr_arm_7_tool_joint" type="fixed">
	<origin rpy="0 0 0" xyz="0 0 0" />
	<!-- 3.141592 1.5707 -->
	<limit effort="0" lower="0" upper="0" velocity="0" />
    <parent link="left_lwr_arm_7_link"/>
    <child link="left/bhand_palm_link"/>
</joint>
<gazebo reference="left_lwr_arm_7_tool_joint">
<provideFeedback>1</provideFeedback>
    <provideFeedback>1</provideFeedback>
    <preserveFixedJoint>true</preserveFixedJoint>
    <sensor name="left_force_torque" type="force_torque">
      <always_on>true</always_on>
      <visualize>true</visualize>
      <update_rate>100</update_rate>
       <force_torque>
        <frame>child</frame>
        <measure_direction>child_to_parent</measure_direction>
      </force_torque>
    </sensor>
</gazebo>

<!-- left hand start -->
  <gazebo reference="left/bhand_palm_link">
    <mu1>1</mu1><!-- 0.5 -->
    <mu2>1</mu2>
    <maxContacts>3</maxContacts>
    <visual name="visual_shiny">
      <material>
        <script>
          <uri>/home/dwigand/code/cogimon/CoSimA/repos/cogimon-gazebo-models/barrett-bh8/materials/barrett.material</uri>
          <name>BHand/BlueAluminum</name>
        </script>
      </material>
    </visual>
  </gazebo>
  <link name="left/bhand_palm_link">
    <inertial>
      <origin xyz="-5.1098e-005 0.0050433 0.036671" rpy="0 0 0"/>
      <mass value="0.50573"/>
      <inertia ixx="3.8374e-005" ixy="-5.604e-008" ixz="-4.2034e-005" iyy="0.00022405" iyz="1.3283e-007" izz="0.00020045"/>
    </inertial>
    <visual>
      <!--<material name="WAMGrey">-->
      <!--<color rgba="0.9 0.9 0.9 0.0"/>-->
      <!--</material>-->
      <geometry>
        <mesh filename="/home/dwigand/code/cogimon/CoSimA/repos/ROS_WORKSPACE/src/barrett_model/models/sw_meshes/bhand/bhand_palm_fine.stl"/>
      </geometry>
    </visual>
    <!-- wrist -->
    <collision>
      <origin xyz="0 0 0.02029"/>
      <geometry>
        <cylinder length="0.042" radius="0.045"/>
      </geometry>
    </collision>
    <!-- spine -->
    <collision>
      <origin xyz="0 0.01105 0.05768"/>
      <geometry>
        <box size="0.024 0.108 0.033"/>
      </geometry>
    </collision>
    <!-- palm -->
    <collision>
      <origin xyz="0 0 0.07243"/>
      <geometry>
        <box size="0.076 0.046 0.012"/>
      </geometry>
      <surface>
        <friction>
          <ode>
            <mu>1</mu>
            <mu2>1</mu2>
          </ode>
        </friction>
      </surface>
    </collision>
    <!-- F1 knuckle -->
    <collision>
      <origin rpy="0 1.5707 0" xyz="0 0.05 0.07527"/>
      <geometry>
        <cylinder length="0.024" radius="0.015"/>
      </geometry>
    </collision>
  </link>
  <joint name="left_bhand_palm_surface_joint" type="fixed">
    <parent link="left/bhand_palm_link"/>
    <child link="left_bhand_palm_surface_link"/>
    <origin rpy="0 0 0" xyz="0 0 0.08"/>
    <limit effort="30" lower="0" upper="3.14159265359" velocity="5.0"/>
  </joint>
  <!-- <gazebo reference="left_bhand_palm_surface_joint">
    <preserveFixedJoint>true</preserveFixedJoint>
  </gazebo> -->
  <link name="left_bhand_palm_surface_link">
    <inertial>
      <mass value="0.00001"/>
      <inertia ixx="0.000001" ixy="0.0" ixz="0.0" iyy="0.000001" iyz="0.0" izz="0.000001"/>
    </inertial>
  </link>
  <joint name="left_bhand_grasp_joint" type="fixed">
    <parent link="left/bhand_palm_link"/>
    <child link="left_bhand_grasp_link"/>
    <origin rpy="0 0 0" xyz="0 0 0.12"/>
    <limit effort="30" lower="0" upper="3.14159265359" velocity="5.0"/>
  </joint>
  <link name="left_bhand_grasp_link">
    <collision>
      <!-- https://github.com/ros-planning/moveit_core/issues/158 -->
      <origin rpy="0 0 0" xyz="0 0 -0.13"/>
      <geometry>
        <sphere radius="0.001"/>
      </geometry>
    </collision>
    <inertial>
      <mass value="0.00001"/>
      <inertia ixx="0.000001" ixy="0.0" ixz="0.0" iyy="0.000001" iyz="0.0" izz="0.000001"/>
    </inertial>
  </link>
  <joint name="left/finger_1/prox_joint" type="revolute">
    <parent link="left/bhand_palm_link"/>
    <child link="left/finger_1/prox_link"/>
    <origin rpy="0 0 -1.57079632679" xyz="-0.025 0.0 0.0415"/>
    <axis xyz="0 0 -1"/>
    <limit effort="5" lower="0" upper="3.14159265359" velocity="10.0"/>
    <dynamics damping="0.35" friction="0"/>
  </joint>
  <gazebo reference="left/finger_1/prox_joint">
    <provideFeedback>true</provideFeedback>
    <!--<implicitSpringDamper>true</implicitSpringDamper>-->
    <!--<kp>100</kp>-->
    <!--<kd>0.01</kd>-->
    <!--<kp>0.001</kp>-->
    <!--<kd>0.01</kd>-->
    <!--<stopCfm>0.5</stopCfm>-->
    <!--<stopErp>0.5</stopErp>-->
    <implicitSpringDamper>true</implicitSpringDamper>
  </gazebo>
  <gazebo reference="left/finger_1/prox_link">
    <mu1>0.5</mu1>
    <mu2>0.5</mu2>
    <maxContacts>1</maxContacts>
    <visual name="visual_shiny">
      <material>
        <script>
          <uri>/home/dwigand/code/cogimon/CoSimA/repos/ROS_WORKSPACE/src/barrett_model/materials/barrett.material</uri>
          <name>BHand/BlueAluminum</name>
        </script>
      </material>
    </visual>
  </gazebo>
  <link name="left/finger_1/prox_link">
    <inertial>
      <origin xyz="0.023133 0.00078642 0.00052792"/>
      <mass value="0.14109"/>
      <inertia ixx="4.872e-006" ixy="1.7103e-006" ixz="3.4041e-008" iyy="7.6588e-005" iyz="2.3133e-008" izz="7.7733e-005"/>
    </inertial>
    <visual>
      <material name="WAMGrey">
        <color rgba="0.9 0.9 0.9 0.0"/>
      </material>
      <geometry>
        <mesh filename="/home/dwigand/code/cogimon/CoSimA/repos/ROS_WORKSPACE/src/barrett_model/models/sw_meshes/bhand/bhand_finger_prox_link_fine.stl"/>
      </geometry>
    </visual>
    <!-- base -->
    <collision>
      <origin xyz="0.03217 0.0 0.01674"/>
      <geometry>
        <box size="0.066 0.024 0.033"/>
      </geometry>
    </collision>
    <!-- F2/F3 knuckle -->
    <collision>
      <origin rpy="1.5707 0 0" xyz="0.05 0.0 0.034"/>
      <geometry>
        <cylinder length="0.024" radius="0.015"/>
      </geometry>
    </collision>
  </link>
  <joint name="left/finger_1/med_joint" type="revolute">
    <parent link="left/finger_1/prox_link"/>
    <child link="left/finger_1/med_link"/>
    <origin rpy="1.57079632679 0 0" xyz="0.05 0.0 0.03390"/>
    <axis xyz="0 0 1"/>
    <limit effort="30" lower="0" upper="2.44346095279" velocity="10.00"/>
    <dynamics damping="0.35" friction="0"/>
  </joint>
  <gazebo reference="left/finger_1/med_joint">
    <provideFeedback>true</provideFeedback>
    <!--<implicitSpringDamper>true</implicitSpringDamper>-->
    <!--<kp>100</kp>-->
    <!--<kd>0.01</kd>-->
    <!--<kp>0.001</kp>-->
    <!--<kd>0.01</kd>-->
    <!--<stopCfm>0.5</stopCfm>-->
    <!--<stopErp>0.5</stopErp>-->
    <implicitSpringDamper>true</implicitSpringDamper>
  </gazebo>
  <gazebo reference="left/finger_1/med_link">
    <mu1>1</mu1><!-- 0.5 -->
    <mu2>1</mu2>
    <maxContacts>1</maxContacts>
    <!--<kp>5000</kp>-->
    <!--<kd>0.02</kd>-->
    <!--<kp>3000</kp>-->
    <kd>0.1</kd>
    <visual name="visual_shiny">
      <material>
        <script>
          <uri>/home/dwigand/code/cogimon/CoSimA/repos/ROS_WORKSPACE/src/barrett_model/materials/barrett.material</uri>
          <name>Wam/Aluminum</name>
        </script>
      </material>
    </visual>
  </gazebo>
  <link name="left/finger_1/med_link">
    <inertial>
      <origin xyz="0.023133 0.00078642 0.00052792"/>
      <mass value="0.062139"/>
      <inertia ixx="4.872e-006" ixy="1.7103e-006" ixz="3.4041e-008" iyy="7.6588e-005" iyz="2.3133e-008" izz="7.7733e-005"/>
    </inertial>
    <visual>
      <material name="WAMGrey">
        <color rgba="0.9 0.9 0.9 0.0"/>
      </material>
      <geometry>
        <mesh filename="/home/dwigand/code/cogimon/CoSimA/repos/ROS_WORKSPACE/src/barrett_model/models/sw_meshes/bhand/bhand_finger_med_link_fine.stl"/>
      </geometry>
    </visual>
    <!-- spine -->
    <collision>
      <origin xyz="0.03493 0.003 -0.0007"/>
      <geometry>
        <box size="0.07 0.019 0.006"/>
      </geometry>
    </collision>
    <!-- protrusion -->
    <collision>
      <origin xyz="0.03894 0.00376 -0.0007"/>
      <geometry>
        <box size="0.031 0.023 0.019"/>
      </geometry>
    </collision>
  </link>
  <joint name="left/finger_1/dist_joint" type="revolute">
    <parent link="left/finger_1/med_link"/>
    <child link="left/finger_1/dist_link"/>
    <origin rpy="0 0 0.785398163397" xyz="0.06994 0.003 0.0"/>
    <axis xyz="0 0 1"/>
    <limit effort="30" lower="0" upper="0.837758040957" velocity="10.00"/>
    <dynamics damping="0.35" friction="0"/>
  </joint>
  <gazebo reference="left/finger_1/dist_joint">
    <provideFeedback>true</provideFeedback>
    <!--<implicitSpringDamper>true</implicitSpringDamper>-->
    <!--<kp>100</kp>-->
    <!--<kd>0.01</kd>-->
    <!--<kp>0.001</kp>-->
    <!--<kd>0.01</kd>-->
    <!--<stopCfm>0.5</stopCfm>-->
    <!--<stopErp>0.5</stopErp>-->
    <implicitSpringDamper>true</implicitSpringDamper>
  </gazebo>
  <gazebo reference="left/finger_1/dist_link">
    <mu1>1</mu1><!-- 0.5 -->
    <mu2>1</mu2>
    <maxContacts>1</maxContacts>
    <selfCollide>false</selfCollide>
    <!--<kp>5000</kp>-->
    <!--<kd>0.02</kd>-->
    <!--<kp>3000</kp>-->
    <kd>0.1</kd>
    <visual name="visual_shiny">
      <material>
        <script>
          <uri>/home/dwigand/code/cogimon/CoSimA/repos/ROS_WORKSPACE/src/barrett_model/materials/barrett.material</uri>
          <name>Wam/Aluminum</name>
        </script>
      </material>
    </visual>
  </gazebo>
  <link name="left/finger_1/dist_link">
    <inertial>
      <origin rpy="0 0 0" xyz="0.022825 0.0010491 0.0004203"/>
      <mass value="0.041377"/>
      <inertia ixx="3.1582e-006" ixy="1.4308e-006" ixz="1.0106e-007" iyy="3.8376e-005" iyz="0" izz="3.7275e-005"/>
    </inertial>
    <visual>
      <origin rpy="0 0 -0.785398163397"/>
      <material name="WAMGrey">
        <color rgba="0.9 0.9 0.9 0.0"/>
      </material>
      <geometry>
        <mesh filename="/home/dwigand/code/cogimon/CoSimA/repos/ROS_WORKSPACE/src/barrett_model/models/sw_meshes/bhand/bhand_finger_dist_link_fine.stl"/>
      </geometry>
    </visual>
    <collision>
      <origin rpy="0 0 -0.785398163397"/>
      <geometry>
        <mesh filename="/home/dwigand/code/cogimon/CoSimA/repos/ROS_WORKSPACE/src/barrett_model/models/sw_meshes/bhand/bhand_finger_dist_link_convex.dae"/>
      </geometry>
      <surface>
        <friction>
          <ode>
            <mu>1</mu>
            <mu2>1</mu2>
          </ode>
        </friction>
      </surface>
    </collision>
  </link>
  <joint name="left/finger_1/tip_joint" type="fixed">
    <parent link="left/finger_1/dist_link"/>
    <child link="left/finger_1/tip_link"/>
    <origin rpy="0 0 0" xyz="0.05 0.0 0.0"/>
  </joint>
  <link name="left/finger_1/tip_link">
    <inertial>
      <mass value="1E-6"/>
      <inertia ixx="1E-6" ixy="0" ixz="0" iyy="1E-6" iyz="0" izz="1E-6"/>
    </inertial>
  </link>
  <joint name="left/finger_2/prox_joint" type="revolute">
    <parent link="left/bhand_palm_link"/>
    <child link="left/finger_2/prox_link"/>
    <origin rpy="0 0 -1.57079632679" xyz="0.025 0.0 0.0415"/>
    <axis xyz="0 0 1"/>
    <limit effort="5" lower="0" upper="3.14159265359" velocity="10.0"/>
    <!-- Change the damping to influence the spread behavior -->
    <dynamics damping="0.35" friction="0"/>
  </joint>
  <gazebo reference="left/finger_2/prox_joint">
    <provideFeedback>true</provideFeedback>
    <!--<implicitSpringDamper>true</implicitSpringDamper>-->
    <!--<kp>100</kp>-->
    <!--<kd>0.01</kd>-->
    <!--<kp>0.001</kp>-->
    <!--<kd>0.01</kd>-->
    <!--<stopCfm>0.5</stopCfm>-->
    <!--<stopErp>0.5</stopErp>-->
    <implicitSpringDamper>true</implicitSpringDamper>
  </gazebo>
  <gazebo reference="left/finger_2/prox_link">
    <mu1>0.5</mu1>
    <mu2>0.5</mu2>
    <maxContacts>1</maxContacts>
    <visual name="visual_shiny">
      <material>
        <script>
          <uri>/home/dwigand/code/cogimon/CoSimA/repos/ROS_WORKSPACE/src/barrett_model/materials/barrett.material</uri>
          <name>BHand/BlueAluminum</name>
        </script>
      </material>
    </visual>
  </gazebo>
  <link name="left/finger_2/prox_link">
    <inertial>
      <origin xyz="0.023133 0.00078642 0.00052792"/>
      <mass value="0.14109"/>
      <inertia ixx="4.872e-006" ixy="1.7103e-006" ixz="3.4041e-008" iyy="7.6588e-005" iyz="2.3133e-008" izz="7.7733e-005"/>
    </inertial>
    <visual>
      <material name="WAMGrey">
        <color rgba="0.9 0.9 0.9 0.0"/>
      </material>
      <geometry>
        <mesh filename="/home/dwigand/code/cogimon/CoSimA/repos/ROS_WORKSPACE/src/barrett_model/models/sw_meshes/bhand/bhand_finger_prox_link_fine.stl"/>
      </geometry>
    </visual>
    <!-- base -->
    <collision>
      <origin xyz="0.03217 0.0 0.01674"/>
      <geometry>
        <box size="0.066 0.024 0.033"/>
      </geometry>
    </collision>
    <!-- F2/F3 knuckle -->
    <collision>
      <origin rpy="1.5707 0 0" xyz="0.05 0.0 0.034"/>
      <geometry>
        <cylinder length="0.024" radius="0.015"/>
      </geometry>
    </collision>
  </link>
  <joint name="left/finger_2/med_joint" type="revolute">
    <parent link="left/finger_2/prox_link"/>
    <child link="left/finger_2/med_link"/>
    <origin rpy="1.57079632679 0 0" xyz="0.05 0.0 0.03390"/>
    <axis xyz="0 0 1"/>
    <limit effort="30" lower="0" upper="2.44346095279" velocity="10.00"/>
    <dynamics damping="0.35" friction="0"/>
  </joint>
  <gazebo reference="left/finger_2/med_joint">
    <provideFeedback>true</provideFeedback>
    <!--<implicitSpringDamper>true</implicitSpringDamper>-->
    <!--<kp>100</kp>-->
    <!--<kd>0.01</kd>-->
    <!--<kp>0.001</kp>-->
    <!--<kd>0.01</kd>-->
    <!--<stopCfm>0.5</stopCfm>-->
    <!--<stopErp>0.5</stopErp>-->
    <implicitSpringDamper>true</implicitSpringDamper>
  </gazebo>
  <gazebo reference="left/finger_2/med_link">
    <mu1>1</mu1><!-- 0.5 -->
    <mu2>1</mu2>
    <maxContacts>1</maxContacts>
    <!--<kp>5000</kp>-->
    <!--<kd>0.02</kd>-->
    <!--<kp>3000</kp>-->
    <kd>0.1</kd>
    <visual name="visual_shiny">
      <material>
        <script>
          <uri>/home/dwigand/code/cogimon/CoSimA/repos/ROS_WORKSPACE/src/barrett_model/materials/barrett.material</uri>
          <name>Wam/Aluminum</name>
        </script>
      </material>
    </visual>
  </gazebo>
  <link name="left/finger_2/med_link">
    <inertial>
      <origin xyz="0.023133 0.00078642 0.00052792"/>
      <mass value="0.062139"/>
      <inertia ixx="4.872e-006" ixy="1.7103e-006" ixz="3.4041e-008" iyy="7.6588e-005" iyz="2.3133e-008" izz="7.7733e-005"/>
    </inertial>
    <visual>
      <material name="WAMGrey">
        <color rgba="0.9 0.9 0.9 0.0"/>
      </material>
      <geometry>
        <mesh filename="/home/dwigand/code/cogimon/CoSimA/repos/ROS_WORKSPACE/src/barrett_model/models/sw_meshes/bhand/bhand_finger_med_link_fine.stl"/>
      </geometry>
    </visual>
    <!-- spine -->
    <collision>
      <origin xyz="0.03493 0.003 -0.0007"/>
      <geometry>
        <box size="0.07 0.019 0.006"/>
      </geometry>
    </collision>
    <!-- protrusion -->
    <collision>
      <origin xyz="0.03894 0.00376 -0.0007"/>
      <geometry>
        <box size="0.031 0.023 0.019"/>
      </geometry>
      <surface>
        <friction>
          <ode>
            <mu>1</mu>
            <mu2>1</mu2>
          </ode>
        </friction>
      </surface>
    </collision>
  </link>
  <joint name="left/finger_2/dist_joint" type="revolute">
    <parent link="left/finger_2/med_link"/>
    <child link="left/finger_2/dist_link"/>
    <origin rpy="0 0 0.785398163397" xyz="0.06994 0.003 0.0"/>
    <axis xyz="0 0 1"/>
    <limit effort="30" lower="0" upper="0.837758040957" velocity="10.00"/>
    <dynamics damping="0.35" friction="0"/>
  </joint>
  <gazebo reference="left/finger_2/dist_joint">
    <provideFeedback>true</provideFeedback>
    <!--<implicitSpringDamper>true</implicitSpringDamper>-->
    <!--<kp>100</kp>-->
    <!--<kd>0.01</kd>-->
    <!--<kp>0.001</kp>-->
    <!--<kd>0.01</kd>-->
    <!--<stopCfm>0.5</stopCfm>-->
    <!--<stopErp>0.5</stopErp>-->
    <implicitSpringDamper>true</implicitSpringDamper>
  </gazebo>
  <gazebo reference="left/finger_2/dist_link">
    <mu1>1</mu1><!-- 0.5 -->
    <mu2>1</mu2>
    <maxContacts>1</maxContacts>
    <selfCollide>false</selfCollide>
    <!--<kp>5000</kp>-->
    <!--<kd>0.02</kd>-->
    <!--<kp>3000</kp>-->
    <kd>0.1</kd>
    <visual name="visual_shiny">
      <material>
        <script>
          <uri>/home/dwigand/code/cogimon/CoSimA/repos/ROS_WORKSPACE/src/barrett_model/materials/barrett.material</uri>
          <name>Wam/Aluminum</name>
        </script>
      </material>
    </visual>
  </gazebo>
  <link name="left/finger_2/dist_link">
    <inertial>
      <origin rpy="0 0 0" xyz="0.022825 0.0010491 0.0004203"/>
      <mass value="0.041377"/>
      <inertia ixx="3.1582e-006" ixy="1.4308e-006" ixz="1.0106e-007" iyy="3.8376e-005" iyz="0" izz="3.7275e-005"/>
    </inertial>
    <visual>
      <origin rpy="0 0 -0.785398163397"/>
      <material name="WAMGrey">
        <color rgba="0.9 0.9 0.9 0.0"/>
      </material>
      <geometry>
        <mesh filename="/home/dwigand/code/cogimon/CoSimA/repos/ROS_WORKSPACE/src/barrett_model/models/sw_meshes/bhand/bhand_finger_dist_link_fine.stl"/>
      </geometry>
    </visual>
    <collision>
      <origin rpy="0 0 -0.785398163397"/>
      <geometry>
        <mesh filename="/home/dwigand/code/cogimon/CoSimA/repos/ROS_WORKSPACE/src/barrett_model/models/sw_meshes/bhand/bhand_finger_dist_link_convex.dae"/>
      </geometry>
      <surface>
        <friction>
          <ode>
            <mu>1</mu>
            <mu2>1</mu2>
          </ode>
        </friction>
      </surface>
    </collision>
  </link>
  <joint name="left/finger_2/tip_joint" type="fixed">
    <parent link="left/finger_2/dist_link"/>
    <child link="left/finger_2/tip_link"/>
    <origin rpy="0 0 0" xyz="0.05 0.0 0.0"/>
  </joint>
  <link name="left/finger_2/tip_link">
    <inertial>
      <mass value="1E-6"/>
      <inertia ixx="1E-6" ixy="0" ixz="0" iyy="1E-6" iyz="0" izz="1E-6"/>
    </inertial>
  </link>
  <joint name="left/finger_3/med_joint" type="revolute">
    <parent link="left/bhand_palm_link"/>
    <child link="left/finger_3/med_link"/>
    <origin rpy="1.57079632679 0 1.57079632679" xyz="0 0.05 0.0754"/>
    <axis xyz="0 0 1"/>
    <limit effort="30" lower="0" upper="2.44346095279" velocity="10.00"/>
    <dynamics damping="0.35" friction="0"/>
  </joint>
  <gazebo reference="left/finger_3/med_joint">
    <provideFeedback>true</provideFeedback>
    <!--<implicitSpringDamper>true</implicitSpringDamper>-->
    <!--<kp>100</kp>-->
    <!--<kd>0.01</kd>-->
    <!--<kp>0.001</kp>-->
    <!--<kd>0.01</kd>-->
    <!--<stopCfm>0.5</stopCfm>-->
    <!--<stopErp>0.5</stopErp>-->
    <implicitSpringDamper>true</implicitSpringDamper>
  </gazebo>
  <gazebo reference="left/finger_3/med_link">
    <mu1>1</mu1><!-- 0.5 -->
    <mu2>1</mu2>
    <maxContacts>1</maxContacts>
    <!--<kp>5000</kp>-->
    <!--<kd>0.02</kd>-->
    <!--<kp>3000</kp>-->
    <kd>0.1</kd>
    <visual name="visual_shiny">
      <material>
        <script>
          <uri>/home/dwigand/code/cogimon/CoSimA/repos/ROS_WORKSPACE/src/barrett_model/materials/barrett.material</uri>
          <name>Wam/Aluminum</name>
        </script>
      </material>
    </visual>
  </gazebo>
  <link name="left/finger_3/med_link">
    <inertial>
      <origin xyz="0.023133 0.00078642 0.00052792"/>
      <mass value="0.062139"/>
      <inertia ixx="4.872e-006" ixy="1.7103e-006" ixz="3.4041e-008" iyy="7.6588e-005" iyz="2.3133e-008" izz="7.7733e-005"/>
    </inertial>
    <visual>
      <material name="WAMGrey">
        <color rgba="0.9 0.9 0.9 0.0"/>
      </material>
      <geometry>
        <mesh filename="/home/dwigand/code/cogimon/CoSimA/repos/ROS_WORKSPACE/src/barrett_model/models/sw_meshes/bhand/bhand_finger_med_link_fine.stl"/>
      </geometry>
    </visual>
    <!-- spine -->
    <collision>
      <origin xyz="0.03493 0.003 -0.0007"/>
      <geometry>
        <box size="0.07 0.019 0.006"/>
      </geometry>
    </collision>
    <!-- protrusion -->
    <collision>
      <origin xyz="0.03894 0.00376 -0.0007"/>
      <geometry>
        <box size="0.031 0.023 0.019"/>
      </geometry>
      <surface>
        <friction>
          <ode>
            <mu>1</mu>
            <mu2>1</mu2>
          </ode>
        </friction>
      </surface>
    </collision>
  </link>
  <joint name="left/finger_3/dist_joint" type="revolute">
    <parent link="left/finger_3/med_link"/>
    <child link="left/finger_3/dist_link"/>
    <origin rpy="0 0 0.785398163397" xyz="0.06994 0.003 0.0"/>
    <axis xyz="0 0 1"/>
    <limit effort="30" lower="0" upper="0.837758040957" velocity="10.00"/>
    <dynamics damping="0.35" friction="0"/>
  </joint>
  <gazebo reference="left/finger_3/dist_joint">
    <provideFeedback>true</provideFeedback>
    <!--<implicitSpringDamper>true</implicitSpringDamper>-->
    <!--<kp>100</kp>-->
    <!--<kd>0.01</kd>-->
    <!--<kp>0.001</kp>-->
    <!--<kd>0.01</kd>-->
    <!--<stopCfm>0.5</stopCfm>-->
    <!--<stopErp>0.5</stopErp>-->
    <implicitSpringDamper>true</implicitSpringDamper>
  </gazebo>
  <gazebo reference="left/finger_3/dist_link">
    <mu1>1</mu1><!-- 0.5 -->
    <mu2>1</mu2>
    <maxContacts>1</maxContacts>
    <selfCollide>false</selfCollide>
    <!--<kp>5000</kp>-->
    <!--<kd>0.02</kd>-->
    <!--<kp>3000</kp>-->
    <kd>0.1</kd>
    <visual name="visual_shiny">
      <material>
        <script>
          <uri>/home/dwigand/code/cogimon/CoSimA/repos/ROS_WORKSPACE/src/barrett_model/materials/barrett.material</uri>
          <name>Wam/Aluminum</name>
        </script>
      </material>
    </visual>
  </gazebo>
  <link name="left/finger_3/dist_link">
    <inertial>
      <origin rpy="0 0 0" xyz="0.022825 0.0010491 0.0004203"/>
      <mass value="0.041377"/>
      <inertia ixx="3.1582e-006" ixy="1.4308e-006" ixz="1.0106e-007" iyy="3.8376e-005" iyz="0" izz="3.7275e-005"/>
    </inertial>
    <visual>
      <origin rpy="0 0 -0.785398163397"/>
      <material name="WAMGrey">
        <color rgba="0.9 0.9 0.9 0.0"/>
      </material>
      <geometry>
        <mesh filename="/home/dwigand/code/cogimon/CoSimA/repos/ROS_WORKSPACE/src/barrett_model/models/sw_meshes/bhand/bhand_finger_dist_link_fine.stl"/>
      </geometry>
    </visual>
    <collision>
      <origin rpy="0 0 -0.785398163397"/>
      <geometry>
        <mesh filename="/home/dwigand/code/cogimon/CoSimA/repos/ROS_WORKSPACE/src/barrett_model/models/sw_meshes/bhand/bhand_finger_dist_link_convex.dae"/>
      </geometry>
      <surface>
        <friction>
          <ode>
            <mu>1</mu>
            <mu2>1</mu2>
          </ode>
        </friction>
      </surface>
    </collision>
  </link>
  <joint name="left/finger_3/tip_joint" type="fixed">
    <parent link="left/finger_3/dist_link"/>
    <child link="left/finger_3/tip_link"/>
    <origin rpy="0 0 0" xyz="0.05 0.0 0.0"/>
  </joint>
  <link name="left/finger_3/tip_link">
    <inertial>
      <mass value="1E-6"/>
      <inertia ixx="1E-6" ixy="0" ixz="0" iyy="1E-6" iyz="0" izz="1E-6"/>
    </inertial>
  </link>

  <joint name="left/compliance_joint" type="fixed">
    <parent link="left/bhand_palm_link"/>
    <child link="left/compliance_link"/>
    <origin rpy="0 0 0" xyz="0.0 0.0 0.18"/>
  </joint>

   <link name="left/compliance_link">
    <inertial>
      <origin xyz="0 0 0" rpy="0 0 0"/>
      <mass value="0.01"/>
      <inertia ixx="4e-6" ixy="0" ixz="0" iyy="4e-6" iyz="0" izz="4e-6"/>
      <!-- <mass value="1E-6"/> -->
      <!-- <inertia ixx="1E-6" ixy="0" ixz="0" iyy="1E-6" iyz="0" izz="1E-6"/> -->
    </inertial>
    <visual>
      <geometry>
         <sphere radius="0.01"/>
      </geometry>
    </visual>
    <!--collision>
      <geometry>
        <sphere radius="0.00001"/>
      </geometry>
    </collision> -->
  </link>

  <gazebo reference="left/compliance_joint">
    <preserveFixedJoint>true</preserveFixedJoint>
  </gazebo>
  <!-- <link name="left/compliance_link">
    <inertial>
      <mass value="1E-6"/>
      <inertia ixx="1E-6" ixy="0" ixz="0" iyy="1E-6" iyz="0" izz="1E-6"/>
    </inertial>
    <visual>
      <origin rpy="0 0 0"/>
      <geometry>
        <sphere>
            <radius>0.5</radius>
        </sphere>
      </geometry>
    </visual>
  </link> -->
<!-- left hand end -->

<joint name="right_arm_world_joint" type="fixed">
        <origin rpy="-0.46365 0.25268 -2.6779" xyz="0 -0.15 0.01" />
        <parent link="world" />
        <child link="right_lwr_arm_base_link" />
</joint>
    <!--link name="world_link"> 
    <inertial>
      <mass value="50.0"/>
      <com xyz="0 0 0"/>
      <inertia ixx="0.01" ixy="0.00" ixz="0.00" iyy="0.01" iyz="0.00" izz="0.01"/>
    </inertial>
    <visual>
      <origin rpy="0 0 0" xyz="0 0 0.95"/>
      <geometry>
        <box size="0.5 0.5 0.05"/>
      </geometry>
    </visual>
    <collision>
      <origin rpy="0 0 0" xyz="0 0 0.50"/>
      <geometry>
        <box size="0.5 0.5 0.05"/>
      </geometry>
    </collision>
  </link-->
    <!-- First (shoulder) element of the arm. Fixed to its parent. -->
    <!--joint name="world_right_lwr_arm_base_joint" type="fixed">
    <origin rpy="0 0 0" xyz="0 0 1.1"/>
    <parent link="world_link"/>
    <child link="right_lwr_arm_base_link"/>
  </joint-->
    <link name="right_lwr_arm_base_link">
        <inertial>
            <mass value="1.2" />
            <origin rpy="0 0 0" xyz="0 0 0.055" />
            <inertia ixx="0.00229" ixy="0" ixz="0" iyy="0.00216" iyz="0" izz="0.00229" />
        </inertial>
        <visual>
            <origin rpy="0 0 0" xyz="0 0 0" />
            <geometry>
                <mesh filename="model://kuka-lwr-4plus/meshes/arm_base.dae" scale="100 100 100" />
            </geometry>
            <material name="Orange" />
        </visual>
        <!--collision>
            <origin rpy="0 0 0" xyz="0 0 0.01" />
            <geometry>
                <mesh filename="model://kuka-lwr-4plus/meshes/convex/arm_base_convex.stl" scale="0.9 0.9 0.9" />
            </geometry>
        </collision-->
    </link>
    <gazebo reference="right_lwr_arm_base_link">
        <!--<material value="kuka-lwr.material"/>-->
    </gazebo>
    <joint name="right_lwr_arm_0_joint" type="revolute">
        <origin rpy="0 0 0" xyz="0 0 0.11" />
        <axis xyz="0 0 1" />
        <limit effort="204" lower="-2.96705972839" upper="2.96705972839" velocity="1.91986217719" />
        <safety_controller k_position="100" k_velocity="2" soft_lower_limit="-2.93215314335" soft_upper_limit="2.93215314335" />
        <dynamics damping="5.0" />
        <parent link="right_lwr_arm_base_link" />
        <child link="right_lwr_arm_1_link" />
    </joint>
    <gazebo reference="right_lwr_arm_0_joint">
        <provideFeedback>1</provideFeedback>
        <implicitSpringDamper>1</implicitSpringDamper>
    </gazebo>
    <transmission name="right_lwr_arm_0_trans" type="SimpleTransmission">
        <actuator name="right_lwr_arm_0_motor" />
        <joint name="right_lwr_arm_0_joint" />
        <mechanicalReduction>1.0</mechanicalReduction>
    </transmission>
    <link name="right_lwr_arm_1_link">
        <inertial>
            <mass value="2.0" />
            <origin rpy="0 0 0" xyz="0 0 0.130" />
            <inertia ixx="0.0136666666667" ixy="0" ixz="0" iyy="0.0118666666667" iyz="0" izz="0.003" />
        </inertial>
        <visual>
            <origin rpy="0 0 3.14159265359" xyz="0 0 0" />
            <geometry>
                <mesh filename="model://kuka-lwr-4plus/meshes/arm_segment_a.dae" scale="100 100 100" />
            </geometry>
            <material name="Orange" />
        </visual>
        <collision>
            <origin rpy="0 0 3.14159265359" xyz="0 0 0" />
            <geometry>
                <mesh filename="model://kuka-lwr-4plus/meshes/convex/arm_segment_a_convex.stl" scale="1.0 1.0 1.0" />
            </geometry>
        </collision>
    </link>
    <gazebo reference="right_lwr_arm_1_link">
        <!--<material value="kuka-lwr.material"/>-->
    </gazebo>
    <joint name="right_lwr_arm_1_joint" type="revolute">
        <origin rpy="0 0 0" xyz="0 0 0.20" />
        <axis xyz="0 -1 0" />
        <limit effort="306" lower="-2.09439510239" upper="2.09439510239" velocity="1.91986217719" />
        <safety_controller k_position="100" k_velocity="2" soft_lower_limit="-2.05948851735" soft_upper_limit="2.05948851735" />
        <dynamics damping="5.0" />
        <parent link="right_lwr_arm_1_link" />
        <child link="right_lwr_arm_2_link" />
    </joint>
    <gazebo reference="right_lwr_arm_1_joint">
        <provideFeedback>1</provideFeedback>
        <implicitSpringDamper>1</implicitSpringDamper>
    </gazebo>
    <transmission name="right_lwr_arm_1_trans" type="pr2_mechanism_model/SimpleTransmission">
        <actuator name="right_lwr_arm_1_motor" />
        <joint name="right_lwr_arm_1_joint" />
        <mechanicalReduction>1.0</mechanicalReduction>
    </transmission>
    <link name="right_lwr_arm_2_link">
        <inertial>
            <mass value="2.0" />
            <origin rpy="0 0 0" xyz="0 -0.06 0.07" />
            <inertia ixx="0.0136666666667" ixy="0" ixz="0" iyy="0.0118666666667" iyz="0" izz="0.003" />
        </inertial>
        <visual>
            <origin rpy="3.14159265359 0 3.14159265359" xyz="0 0 0.2" />
            <geometry>
                <mesh filename="model://kuka-lwr-4plus/meshes/arm_segment_b.dae" scale="100 100 100" />
            </geometry>
            <material name="Orange" />
        </visual>
        <collision>
            <origin rpy="3.14159265359 0 3.14159265359" xyz="0 0 0.2" />
            <geometry>
                <mesh filename="model://kuka-lwr-4plus/meshes/convex/arm_segment_b_convex.stl" scale="1.0 1.0 1.0" />
            </geometry>
        </collision>
    </link>
    <gazebo reference="right_lwr_arm_2_link">
        <!--<material value="kuka-lwr.material"/>-->
    </gazebo>
    <joint name="right_lwr_arm_2_joint" type="revolute">
        <origin rpy="0 0 0" xyz="0 0 0.20" />
        <axis xyz="0 0 1" />
        <limit effort="204" lower="-2.96705972839" upper="2.96705972839" velocity="2.26892802759" />
        <safety_controller k_position="100" k_velocity="2" soft_lower_limit="-2.93215314335" soft_upper_limit="2.93215314335" />
        <dynamics damping="3.0" />
        <parent link="right_lwr_arm_2_link" />
        <child link="right_lwr_arm_3_link" />
    </joint>
    <gazebo reference="right_lwr_arm_2_joint">
        <provideFeedback>1</provideFeedback>
        <implicitSpringDamper>1</implicitSpringDamper>
    </gazebo>
    <transmission name="right_lwr_arm_2_trans" type="SimpleTransmission">
        <actuator name="right_lwr_arm_2_motor" />
        <joint name="right_lwr_arm_2_joint" />
        <mechanicalReduction>1.0</mechanicalReduction>
    </transmission>
    <link name="right_lwr_arm_3_link">
        <inertial>
            <mass value="2.0" />
            <origin rpy="0 0 0" xyz="0 -0.06 0.130" />
            <inertia ixx="0.0136666666667" ixy="0" ixz="0" iyy="0.0118666666667" iyz="0" izz="0.003" />
        </inertial>
        <visual>
            <origin rpy="0 0 0" xyz="0 0 0" />
            <geometry>
                <mesh filename="model://kuka-lwr-4plus/meshes/arm_segment_a.dae" scale="100 100 100" />
            </geometry>
            <material name="Orange" />
        </visual>
        <collision>
            <origin rpy="0 0 0" xyz="0 0 0" />
            <geometry>
                <mesh filename="model://kuka-lwr-4plus/meshes/convex/arm_segment_a_convex.stl" scale="1.0 1.0 1.0" />
            </geometry>
        </collision>
    </link>
    <gazebo reference="right_lwr_arm_3_link">
        <!--<material value="kuka-lwr.material"/>-->
    </gazebo>
    <joint name="right_lwr_arm_3_joint" type="revolute">
        <origin rpy="0 0 0" xyz="0 0 0.20" />
        <axis xyz="0 1 0" />
        <limit effort="306" lower="-2.09439510239" upper="2.09439510239" velocity="2.26892802759" />
        <safety_controller k_position="100" k_velocity="2" soft_lower_limit="-2.05948851735" soft_upper_limit="2.05948851735" />
        <dynamics damping="3.0" />
        <parent link="right_lwr_arm_3_link" />
        <child link="right_lwr_arm_4_link" />
    </joint>
    <gazebo reference="right_lwr_arm_3_joint">
        <provideFeedback>1</provideFeedback>
        <implicitSpringDamper>1</implicitSpringDamper>
    </gazebo>
    <transmission name="right_lwr_arm_3_trans" type="SimpleTransmission">
        <actuator name="right_lwr_arm_3_motor" />
        <joint name="right_lwr_arm_3_joint" />
        <mechanicalReduction>1.0</mechanicalReduction>
    </transmission>
    <link name="right_lwr_arm_4_link">
        <inertial>
            <mass value="2.0" />
            <origin rpy="0 0 0" xyz="0 0.06 0.07" />
            <inertia ixx="0.0136666666667" ixy="0" ixz="0" iyy="0.0118666666667" iyz="0" izz="0.003" />
        </inertial>
        <visual>
            <origin rpy="0 3.14159265359 3.14159265359" xyz="0 0 0.2" />
            <geometry>
                <mesh filename="model://kuka-lwr-4plus/meshes/arm_segment_b.dae" scale="100 100 100" />
            </geometry>
            <material name="Orange" />
        </visual>
        <collision>
            <origin rpy="0 3.14159265359 3.14159265359" xyz="0 0 0.2" />
            <geometry>
                <mesh filename="model://kuka-lwr-4plus/meshes/convex/arm_segment_b_convex.stl" scale="1.0 1.0 1.0" />
            </geometry>
        </collision>
    </link>
    <gazebo reference="right_lwr_arm_4_link">
        <!--<material value="kuka-lwr.material"/>-->
    </gazebo>
    <joint name="right_lwr_arm_4_joint" type="revolute">
        <origin rpy="0 0 0" xyz="0 0 0.20" />
        <axis xyz="0 0 1" />
        <limit effort="204" lower="-2.96705972839" upper="2.96705972839" velocity="2.26892802759" />
        <safety_controller k_position="100" k_velocity="2" soft_lower_limit="-2.93215314335" soft_upper_limit="2.93215314335" />
        <dynamics damping="1.0" />
        <parent link="right_lwr_arm_4_link" />
        <child link="right_lwr_arm_5_link" />
    </joint>
    <gazebo reference="right_lwr_arm_4_joint">
        <provideFeedback>1</provideFeedback>
        <implicitSpringDamper>1</implicitSpringDamper>
    </gazebo>
    <transmission name="right_lwr_arm_4_trans" type="SimpleTransmission">
        <actuator name="right_lwr_arm_4_motor" />
        <joint name="right_lwr_arm_4_joint" />
        <mechanicalReduction>1.0</mechanicalReduction>
    </transmission>
    <link name="right_lwr_arm_5_link">
        <inertial>
            <mass value="2.0" />
            <origin rpy="0 0 0" xyz="0 0 0.124" />
            <inertia ixx="0.0126506666667" ixy="0" ixz="0" iyy="0.0108506666667" iyz="0" izz="0.003" />
        </inertial>
        <visual>
            <origin rpy="0 0 3.14159265359" xyz="0 0 0" />
            <geometry name="right_lwr_arm_5_geom">
                <mesh filename="model://kuka-lwr-4plus/meshes/arm_segment_last.dae" scale="100 100 100" />
            </geometry>
            <material name="Orange" />
        </visual>
        <collision>
            <origin rpy="0 0 3.14159265359" xyz="0 0 0" />
            <geometry>
                <mesh filename="model://kuka-lwr-4plus/meshes/convex/arm_segment_last_convex.stl" scale="1.0 1.0 1.0" />
            </geometry>
        </collision>
    </link>
    <gazebo reference="right_lwr_arm_5_link">
        <!--<material value="kuka-lwr.material"/>-->
    </gazebo>
    <joint name="right_lwr_arm_5_joint" type="revolute">
        <origin rpy="0 0 0" xyz="0 0 0.19" />
        <axis xyz="0 -1 0" />
        <limit effort="306" lower="-2.09439510239" upper="2.09439510239" velocity="3.14159265359" />
        <safety_controller k_position="100" k_velocity="2" soft_lower_limit="-2.05948851735" soft_upper_limit="2.05948851735" />
        <dynamics damping="1.0" />
        <parent link="right_lwr_arm_5_link" />
        <child link="right_lwr_arm_6_link" />
    </joint>
    <gazebo reference="right_lwr_arm_5_joint">
        <provideFeedback>1</provideFeedback>
        <implicitSpringDamper>1</implicitSpringDamper>
    </gazebo>
    <transmission name="right_lwr_arm_5_trans" type="SimpleTransmission">
        <actuator name="right_lwr_arm_5_motor" />
        <joint name="right_lwr_arm_5_joint" />
        <mechanicalReduction>1.0</mechanicalReduction>
    </transmission>
    <link name="right_lwr_arm_6_link">
        <inertial>
            <mass value="1.0" />
            <origin rpy="0 0 0" xyz="0 0 0.0" />
            <inertia ixx="0.00260416666667" ixy="0" ixz="0" iyy="0.00260416666667" iyz="0" izz="0.00260416666667" />
        </inertial>
        <visual>
            <origin rpy="0 0 3.14159265359" xyz="0 0 0" />
            <geometry>
                <mesh filename="model://kuka-lwr-4plus/meshes/arm_wrist.dae" scale="100 100 100" />
            </geometry>
            <material name="Grey" />
        </visual>
        <collision>
            <origin rpy="0 0 3.14159265359" xyz="0 0 0" />
            <geometry>
                <mesh filename="model://kuka-lwr-4plus/meshes/convex/arm_wrist_convex.stl" scale="1.0 1.0 1.0" />
            </geometry>
        </collision>
    </link>
    <gazebo reference="right_lwr_arm_6_link">
        <!--<material value="kuka-lwr.material"/>-->
    </gazebo>
    <joint name="right_lwr_arm_6_joint" type="revolute">
        <origin rpy="0 0 0" xyz="0 0 0.078" />
        <axis xyz="0 0 1" />
        <limit effort="204" lower="-2.96705972839" upper="2.96705972839" velocity="3.14159265359" />
        <safety_controller k_position="100" k_velocity="2" soft_lower_limit="-2.93215314335" soft_upper_limit="2.93215314335" />
        <dynamics damping="1.0" />
        <parent link="right_lwr_arm_6_link" />
        <child link="right_lwr_arm_7_link" />
    </joint>
    <gazebo reference="right_lwr_arm_6_joint">
        <provideFeedback>1</provideFeedback>
        <implicitSpringDamper>1</implicitSpringDamper>
    </gazebo>
    <transmission name="right_lwr_arm_6_trans" type="SimpleTransmission">
        <actuator name="right_lwr_arm_6_motor" />
        <joint name="right_lwr_arm_6_joint" />
        <mechanicalReduction>1.0</mechanicalReduction>
    </transmission>
    <link name="right_lwr_arm_7_link">
        <inertial>
            <mass value="0.2" />
            <origin xyz="0 0 0" />
            <inertia ixx="6.66666666667e-05" ixy="0" ixz="0" iyy="6.66666666667e-05" iyz="0" izz="0.00012" />
        </inertial>
        <visual>
            <origin rpy="0 0 0" xyz="0 0 0" />
            <geometry>
                <mesh filename="model://kuka-lwr-4plus/meshes/arm_flanche.dae" scale="100 100 100" />
            </geometry>
            <material name="Grey" />
        </visual>
        <collision>
            <origin rpy="0 0 0" xyz="0 0 0" />
            <geometry>
                <!--mesh filename="model://kuka-lwr-4plus/meshes/convex/arm_flanche_convex.stl" scale="1.0 1.0 1.0"/-->
                <mesh filename="model://kuka-lwr-4plus/meshes/arm_flanche.dae" scale="100 100 100" />
            </geometry>
            <!-- <surface>
                <friction>
                    <ode>
                        <mu>0.0</mu>
                        <mu2>0.0</mu2>
                    </ode>
                </friction>
            </surface> -->
        </collision>
    </link>
    <gazebo reference="right_lwr_arm_7_link">
        <!--<material value="kuka-lwr.material"/>-->
    </gazebo>
<joint name="right_lwr_arm_7_tool_joint" type="fixed">
    <origin rpy="0 0 0" xyz="0 0 0" />
    <!-- 3.141592 -->
    <limit effort="0" lower="0" upper="0" velocity="0" />
    <parent link="right_lwr_arm_7_link"/>
    <child link="right/bhand_palm_link"/>
</joint>
<gazebo reference="right_lwr_arm_7_tool_joint">
    <provideFeedback>1</provideFeedback>
    <preserveFixedJoint>true</preserveFixedJoint>
    <sensor name="right_force_torque" type="force_torque">
      <always_on>true</always_on>
      <visualize>true</visualize>
      <update_rate>100</update_rate>
       <force_torque>
        <frame>child</frame>
        <measure_direction>child_to_parent</measure_direction>
      </force_torque>
    </sensor>
</gazebo>

<!-- right hand start -->
  <gazebo reference="right/bhand_palm_link">
    <mu1>1</mu1><!-- 0.5 -->
    <mu2>1</mu2>
    <maxContacts>3</maxContacts>
    <visual name="visual_shiny">
      <material>
        <script>
          <uri>/home/dwigand/code/cogimon/CoSimA/repos/cogimon-gazebo-models/barrett-bh8/materials/barrett.material</uri>
          <name>BHand/BlueAluminum</name>
        </script>
      </material>
    </visual>
  </gazebo>
  <link name="right/bhand_palm_link">
    <inertial>
      <origin xyz="-5.1098e-005 0.0050433 0.036671"/>
      <mass value="0.50573"/>
      <inertia ixx="3.8374e-005" ixy="-5.604e-008" ixz="-4.2034e-005" iyy="0.00022405" iyz="1.3283e-007" izz="0.00020045"/>
    </inertial>
    <visual>
      <!--<material name="WAMGrey">-->
      <!--<color rgba="0.9 0.9 0.9 0.0"/>-->
      <!--</material>-->
      <geometry>
        <mesh filename="/home/dwigand/code/cogimon/CoSimA/repos/ROS_WORKSPACE/src/barrett_model/models/sw_meshes/bhand/bhand_palm_fine.stl"/>
      </geometry>
    </visual>
    <!-- wrist -->
    <collision>
      <origin xyz="0 0 0.02029"/>
      <geometry>
        <cylinder length="0.042" radius="0.045"/>
      </geometry>
    </collision>
    <!-- spine -->
    <collision>
      <origin xyz="0 0.01105 0.05768"/>
      <geometry>
        <box size="0.024 0.108 0.033"/>
      </geometry>
    </collision>
    <!-- palm -->
    <collision>
      <origin xyz="0 0 0.07243"/>
      <geometry>
        <box size="0.076 0.046 0.012"/>
      </geometry>
      <surface>
        <friction>
          <ode>
            <mu>1</mu>
            <mu2>1</mu2>
          </ode>
        </friction>
      </surface>
    </collision>
    <!-- F1 knuckle -->
    <collision>
      <origin rpy="0 1.5707 0" xyz="0 0.05 0.07527"/>
      <geometry>
        <cylinder length="0.024" radius="0.015"/>
      </geometry>
    </collision>
  </link>
  <joint name="right_bhand_palm_surface_joint" type="fixed">
    <parent link="right/bhand_palm_link"/>
    <child link="right_bhand_palm_surface_link"/>
    <origin rpy="0 0 0" xyz="0 0 0.08"/>
    <limit effort="30" lower="0" upper="3.14159265359" velocity="5.0"/>
  </joint>
  <link name="right_bhand_palm_surface_link">
    <inertial>
      <mass value="0.00001"/>
      <inertia ixx="0.000001" ixy="0.0" ixz="0.0" iyy="0.000001" iyz="0.0" izz="0.000001"/>
    </inertial>
  </link>
  <joint name="right_bhand_grasp_joint" type="fixed">
    <parent link="right/bhand_palm_link"/>
    <child link="right_bhand_grasp_link"/>
    <origin rpy="0 0 0" xyz="0 0 0.12"/>
    <limit effort="30" lower="0" upper="3.14159265359" velocity="5.0"/>
  </joint>
  <link name="right_bhand_grasp_link">
    <collision>
      <!-- https://github.com/ros-planning/moveit_core/issues/158 -->
      <origin rpy="0 0 0" xyz="0 0 -0.13"/>
      <geometry>
        <sphere radius="0.001"/>
      </geometry>
    </collision>
    <inertial>
      <mass value="0.00001"/>
      <inertia ixx="0.000001" ixy="0.0" ixz="0.0" iyy="0.000001" iyz="0.0" izz="0.000001"/>
    </inertial>
  </link>
  <joint name="right/finger_1/prox_joint" type="revolute">
    <parent link="right/bhand_palm_link"/>
    <child link="right/finger_1/prox_link"/>
    <origin rpy="0 0 -1.57079632679" xyz="-0.025 0.0 0.0415"/>
    <axis xyz="0 0 -1"/>
    <limit effort="5" lower="0" upper="3.14159265359" velocity="10.0"/>
    <dynamics damping="0.35" friction="0"/>
  </joint>
  <gazebo reference="right/finger_1/prox_joint">
    <provideFeedback>true</provideFeedback>
    <!--<implicitSpringDamper>true</implicitSpringDamper>-->
    <!--<kp>100</kp>-->
    <!--<kd>0.01</kd>-->
    <!--<kp>0.001</kp>-->
    <!--<kd>0.01</kd>-->
    <!--<stopCfm>0.5</stopCfm>-->
    <!--<stopErp>0.5</stopErp>-->
    <implicitSpringDamper>true</implicitSpringDamper>
  </gazebo>
  <gazebo reference="right/finger_1/prox_link">
    <mu1>0.5</mu1>
    <mu2>0.5</mu2>
    <maxContacts>1</maxContacts>
    <visual name="visual_shiny">
      <material>
        <script>
          <uri>/home/dwigand/code/cogimon/CoSimA/repos/ROS_WORKSPACE/src/barrett_model/materials/barrett.material</uri>
          <name>BHand/BlueAluminum</name>
        </script>
      </material>
    </visual>
  </gazebo>
  <link name="right/finger_1/prox_link">
    <inertial>
      <origin xyz="0.023133 0.00078642 0.00052792"/>
      <mass value="0.14109"/>
      <inertia ixx="4.872e-006" ixy="1.7103e-006" ixz="3.4041e-008" iyy="7.6588e-005" iyz="2.3133e-008" izz="7.7733e-005"/>
    </inertial>
    <visual>
      <material name="WAMGrey">
        <color rgba="0.9 0.9 0.9 0.0"/>
      </material>
      <geometry>
        <mesh filename="/home/dwigand/code/cogimon/CoSimA/repos/ROS_WORKSPACE/src/barrett_model/models/sw_meshes/bhand/bhand_finger_prox_link_fine.stl"/>
      </geometry>
    </visual>
    <!-- base -->
    <collision>
      <origin xyz="0.03217 0.0 0.01674"/>
      <geometry>
        <box size="0.066 0.024 0.033"/>
      </geometry>
    </collision>
    <!-- F2/F3 knuckle -->
    <collision>
      <origin rpy="1.5707 0 0" xyz="0.05 0.0 0.034"/>
      <geometry>
        <cylinder length="0.024" radius="0.015"/>
      </geometry>
    </collision>
  </link>
  <joint name="right/finger_1/med_joint" type="revolute">
    <parent link="right/finger_1/prox_link"/>
    <child link="right/finger_1/med_link"/>
    <origin rpy="1.57079632679 0 0" xyz="0.05 0.0 0.03390"/>
    <axis xyz="0 0 1"/>
    <limit effort="30" lower="0" upper="2.44346095279" velocity="10.00"/>
    <dynamics damping="0.35" friction="0"/>
  </joint>
  <gazebo reference="right/finger_1/med_joint">
    <provideFeedback>true</provideFeedback>
    <!--<implicitSpringDamper>true</implicitSpringDamper>-->
    <!--<kp>100</kp>-->
    <!--<kd>0.01</kd>-->
    <!--<kp>0.001</kp>-->
    <!--<kd>0.01</kd>-->
    <!--<stopCfm>0.5</stopCfm>-->
    <!--<stopErp>0.5</stopErp>-->
    <implicitSpringDamper>true</implicitSpringDamper>
  </gazebo>
  <gazebo reference="right/finger_1/med_link">
    <mu1>1</mu1><!-- 0.5 -->
    <mu2>1</mu2>
    <maxContacts>1</maxContacts>
    <!--<kp>5000</kp>-->
    <!--<kd>0.02</kd>-->
    <!--<kp>3000</kp>-->
    <kd>0.1</kd>
    <visual name="visual_shiny">
      <material>
        <script>
          <uri>/home/dwigand/code/cogimon/CoSimA/repos/ROS_WORKSPACE/src/barrett_model/materials/barrett.material</uri>
          <name>Wam/Aluminum</name>
        </script>
      </material>
    </visual>
  </gazebo>
  <link name="right/finger_1/med_link">
    <inertial>
      <origin xyz="0.023133 0.00078642 0.00052792"/>
      <mass value="0.062139"/>
      <inertia ixx="4.872e-006" ixy="1.7103e-006" ixz="3.4041e-008" iyy="7.6588e-005" iyz="2.3133e-008" izz="7.7733e-005"/>
    </inertial>
    <visual>
      <material name="WAMGrey">
        <color rgba="0.9 0.9 0.9 0.0"/>
      </material>
      <geometry>
        <mesh filename="/home/dwigand/code/cogimon/CoSimA/repos/ROS_WORKSPACE/src/barrett_model/models/sw_meshes/bhand/bhand_finger_med_link_fine.stl"/>
      </geometry>
    </visual>
    <!-- spine -->
    <collision>
      <origin xyz="0.03493 0.003 -0.0007"/>
      <geometry>
        <box size="0.07 0.019 0.006"/>
      </geometry>
    </collision>
    <!-- protrusion -->
    <collision>
      <origin xyz="0.03894 0.00376 -0.0007"/>
      <geometry>
        <box size="0.031 0.023 0.019"/>
      </geometry>
      <surface>
        <friction>
          <ode>
            <mu>1</mu>
            <mu2>1</mu2>
          </ode>
        </friction>
      </surface>
    </collision>
  </link>
  <joint name="right/finger_1/dist_joint" type="revolute">
    <parent link="right/finger_1/med_link"/>
    <child link="right/finger_1/dist_link"/>
    <origin rpy="0 0 0.785398163397" xyz="0.06994 0.003 0.0"/>
    <axis xyz="0 0 1"/>
    <limit effort="30" lower="0" upper="0.837758040957" velocity="10.00"/>
    <dynamics damping="0.35" friction="0"/>
  </joint>
  <gazebo reference="right/finger_1/dist_joint">
    <provideFeedback>true</provideFeedback>
    <!--<implicitSpringDamper>true</implicitSpringDamper>-->
    <!--<kp>100</kp>-->
    <!--<kd>0.01</kd>-->
    <!--<kp>0.001</kp>-->
    <!--<kd>0.01</kd>-->
    <!--<stopCfm>0.5</stopCfm>-->
    <!--<stopErp>0.5</stopErp>-->
    <implicitSpringDamper>true</implicitSpringDamper>
  </gazebo>
  <gazebo reference="right/finger_1/dist_link">
    <mu1>1</mu1><!-- 0.5 -->
    <mu2>1</mu2>
    <maxContacts>1</maxContacts>
    <selfCollide>false</selfCollide>
    <!--<kp>5000</kp>-->
    <!--<kd>0.02</kd>-->
    <!--<kp>3000</kp>-->
    <kd>0.1</kd>
    <visual name="visual_shiny">
      <material>
        <script>
          <uri>/home/dwigand/code/cogimon/CoSimA/repos/ROS_WORKSPACE/src/barrett_model/materials/barrett.material</uri>
          <name>Wam/Aluminum</name>
        </script>
      </material>
    </visual>
  </gazebo>
  <link name="right/finger_1/dist_link">
    <inertial>
      <origin rpy="0 0 0" xyz="0.022825 0.0010491 0.0004203"/>
      <mass value="0.041377"/>
      <inertia ixx="3.1582e-006" ixy="1.4308e-006" ixz="1.0106e-007" iyy="3.8376e-005" iyz="0" izz="3.7275e-005"/>
    </inertial>
    <visual>
      <origin rpy="0 0 -0.785398163397"/>
      <material name="WAMGrey">
        <color rgba="0.9 0.9 0.9 0.0"/>
      </material>
      <geometry>
        <mesh filename="/home/dwigand/code/cogimon/CoSimA/repos/ROS_WORKSPACE/src/barrett_model/models/sw_meshes/bhand/bhand_finger_dist_link_fine.stl"/>
      </geometry>
    </visual>
    <collision>
      <origin rpy="0 0 -0.785398163397"/>
      <geometry>
        <mesh filename="/home/dwigand/code/cogimon/CoSimA/repos/ROS_WORKSPACE/src/barrett_model/models/sw_meshes/bhand/bhand_finger_dist_link_convex.dae"/>
      </geometry>
      <surface>
        <friction>
          <ode>
            <mu>1</mu>
            <mu2>1</mu2>
          </ode>
        </friction>
      </surface>
    </collision>
  </link>
  <joint name="right/finger_1/tip_joint" type="fixed">
    <parent link="right/finger_1/dist_link"/>
    <child link="right/finger_1/tip_link"/>
    <origin rpy="0 0 0" xyz="0.05 0.0 0.0"/>
  </joint>
  <link name="right/finger_1/tip_link">
    <inertial>
      <mass value="1E-6"/>
      <inertia ixx="1E-6" ixy="0" ixz="0" iyy="1E-6" iyz="0" izz="1E-6"/>
    </inertial>
  </link>
  <joint name="right/finger_2/prox_joint" type="revolute">
    <parent link="right/bhand_palm_link"/>
    <child link="right/finger_2/prox_link"/>
    <origin rpy="0 0 -1.57079632679" xyz="0.025 0.0 0.0415"/>
    <axis xyz="0 0 1"/>
    <limit effort="5" lower="0" upper="3.14159265359" velocity="10.0"/>
    <!-- Change the damping to influence the spread behavior -->
    <dynamics damping="0.35" friction="0"/>
  </joint>
  <gazebo reference="right/finger_2/prox_joint">
    <provideFeedback>true</provideFeedback>
    <!--<implicitSpringDamper>true</implicitSpringDamper>-->
    <!--<kp>100</kp>-->
    <!--<kd>0.01</kd>-->
    <!--<kp>0.001</kp>-->
    <!--<kd>0.01</kd>-->
    <!--<stopCfm>0.5</stopCfm>-->
    <!--<stopErp>0.5</stopErp>-->
    <implicitSpringDamper>true</implicitSpringDamper>
  </gazebo>
  <gazebo reference="right/finger_2/prox_link">
    <mu1>0.5</mu1>
    <mu2>0.5</mu2>
    <maxContacts>1</maxContacts>
    <visual name="visual_shiny">
      <material>
        <script>
          <uri>/home/dwigand/code/cogimon/CoSimA/repos/ROS_WORKSPACE/src/barrett_model/materials/barrett.material</uri>
          <name>BHand/BlueAluminum</name>
        </script>
      </material>
    </visual>
  </gazebo>
  <link name="right/finger_2/prox_link">
    <inertial>
      <origin xyz="0.023133 0.00078642 0.00052792"/>
      <mass value="0.14109"/>
      <inertia ixx="4.872e-006" ixy="1.7103e-006" ixz="3.4041e-008" iyy="7.6588e-005" iyz="2.3133e-008" izz="7.7733e-005"/>
    </inertial>
    <visual>
      <material name="WAMGrey">
        <color rgba="0.9 0.9 0.9 0.0"/>
      </material>
      <geometry>
        <mesh filename="/home/dwigand/code/cogimon/CoSimA/repos/ROS_WORKSPACE/src/barrett_model/models/sw_meshes/bhand/bhand_finger_prox_link_fine.stl"/>
      </geometry>
    </visual>
    <!-- base -->
    <collision>
      <origin xyz="0.03217 0.0 0.01674"/>
      <geometry>
        <box size="0.066 0.024 0.033"/>
      </geometry>
    </collision>
    <!-- F2/F3 knuckle -->
    <collision>
      <origin rpy="1.5707 0 0" xyz="0.05 0.0 0.034"/>
      <geometry>
        <cylinder length="0.024" radius="0.015"/>
      </geometry>
    </collision>
  </link>
  <joint name="right/finger_2/med_joint" type="revolute">
    <parent link="right/finger_2/prox_link"/>
    <child link="right/finger_2/med_link"/>
    <origin rpy="1.57079632679 0 0" xyz="0.05 0.0 0.03390"/>
    <axis xyz="0 0 1"/>
    <limit effort="30" lower="0" upper="2.44346095279" velocity="10.00"/>
    <dynamics damping="0.35" friction="0"/>
  </joint>
  <gazebo reference="right/finger_2/med_joint">
    <provideFeedback>true</provideFeedback>
    <!--<implicitSpringDamper>true</implicitSpringDamper>-->
    <!--<kp>100</kp>-->
    <!--<kd>0.01</kd>-->
    <!--<kp>0.001</kp>-->
    <!--<kd>0.01</kd>-->
    <!--<stopCfm>0.5</stopCfm>-->
    <!--<stopErp>0.5</stopErp>-->
    <implicitSpringDamper>true</implicitSpringDamper>
  </gazebo>
  <gazebo reference="right/finger_2/med_link">
    <mu1>1</mu1><!-- 0.5 -->
    <mu2>1</mu2>
    <maxContacts>1</maxContacts>
    <!--<kp>5000</kp>-->
    <!--<kd>0.02</kd>-->
    <!--<kp>3000</kp>-->
    <kd>0.1</kd>
    <visual name="visual_shiny">
      <material>
        <script>
          <uri>/home/dwigand/code/cogimon/CoSimA/repos/ROS_WORKSPACE/src/barrett_model/materials/barrett.material</uri>
          <name>Wam/Aluminum</name>
        </script>
      </material>
    </visual>
  </gazebo>
  <link name="right/finger_2/med_link">
    <inertial>
      <origin xyz="0.023133 0.00078642 0.00052792"/>
      <mass value="0.062139"/>
      <inertia ixx="4.872e-006" ixy="1.7103e-006" ixz="3.4041e-008" iyy="7.6588e-005" iyz="2.3133e-008" izz="7.7733e-005"/>
    </inertial>
    <visual>
      <material name="WAMGrey">
        <color rgba="0.9 0.9 0.9 0.0"/>
      </material>
      <geometry>
        <mesh filename="/home/dwigand/code/cogimon/CoSimA/repos/ROS_WORKSPACE/src/barrett_model/models/sw_meshes/bhand/bhand_finger_med_link_fine.stl"/>
      </geometry>
    </visual>
    <!-- spine -->
    <collision>
      <origin xyz="0.03493 0.003 -0.0007"/>
      <geometry>
        <box size="0.07 0.019 0.006"/>
      </geometry>
    </collision>
    <!-- protrusion -->
    <collision>
      <origin xyz="0.03894 0.00376 -0.0007"/>
      <geometry>
        <box size="0.031 0.023 0.019"/>
      </geometry>
      <surface>
        <friction>
          <ode>
            <mu>1</mu>
            <mu2>1</mu2>
          </ode>
        </friction>
      </surface>
    </collision>
  </link>
  <joint name="right/finger_2/dist_joint" type="revolute">
    <parent link="right/finger_2/med_link"/>
    <child link="right/finger_2/dist_link"/>
    <origin rpy="0 0 0.785398163397" xyz="0.06994 0.003 0.0"/>
    <axis xyz="0 0 1"/>
    <limit effort="30" lower="0" upper="0.837758040957" velocity="10.00"/>
    <dynamics damping="0.35" friction="0"/>
  </joint>
  <gazebo reference="right/finger_2/dist_joint">
    <provideFeedback>true</provideFeedback>
    <!--<implicitSpringDamper>true</implicitSpringDamper>-->
    <!--<kp>100</kp>-->
    <!--<kd>0.01</kd>-->
    <!--<kp>0.001</kp>-->
    <!--<kd>0.01</kd>-->
    <!--<stopCfm>0.5</stopCfm>-->
    <!--<stopErp>0.5</stopErp>-->
    <implicitSpringDamper>true</implicitSpringDamper>
  </gazebo>
  <gazebo reference="right/finger_2/dist_link">
    <mu1>1</mu1><!-- 0.5 -->
    <mu2>1</mu2>
    <maxContacts>1</maxContacts>
    <selfCollide>false</selfCollide>
    <!--<kp>5000</kp>-->
    <!--<kd>0.02</kd>-->
    <!--<kp>3000</kp>-->
    <kd>0.1</kd>
    <visual name="visual_shiny">
      <material>
        <script>
          <uri>/home/dwigand/code/cogimon/CoSimA/repos/ROS_WORKSPACE/src/barrett_model/materials/barrett.material</uri>
          <name>Wam/Aluminum</name>
        </script>
      </material>
    </visual>
  </gazebo>
  <link name="right/finger_2/dist_link">
    <inertial>
      <origin rpy="0 0 0" xyz="0.022825 0.0010491 0.0004203"/>
      <mass value="0.041377"/>
      <inertia ixx="3.1582e-006" ixy="1.4308e-006" ixz="1.0106e-007" iyy="3.8376e-005" iyz="0" izz="3.7275e-005"/>
    </inertial>
    <visual>
      <origin rpy="0 0 -0.785398163397"/>
      <material name="WAMGrey">
        <color rgba="0.9 0.9 0.9 0.0"/>
      </material>
      <geometry>
        <mesh filename="/home/dwigand/code/cogimon/CoSimA/repos/ROS_WORKSPACE/src/barrett_model/models/sw_meshes/bhand/bhand_finger_dist_link_fine.stl"/>
      </geometry>
    </visual>
    <collision>
      <origin rpy="0 0 -0.785398163397"/>
      <geometry>
        <mesh filename="/home/dwigand/code/cogimon/CoSimA/repos/ROS_WORKSPACE/src/barrett_model/models/sw_meshes/bhand/bhand_finger_dist_link_convex.dae"/>
      </geometry>
      <surface>
        <friction>
          <ode>
            <mu>1</mu>
            <mu2>1</mu2>
          </ode>
        </friction>
      </surface>
    </collision>
  </link>
  <joint name="right/finger_2/tip_joint" type="fixed">
    <parent link="right/finger_2/dist_link"/>
    <child link="right/finger_2/tip_link"/>
    <origin rpy="0 0 0" xyz="0.05 0.0 0.0"/>
  </joint>
  <link name="right/finger_2/tip_link">
    <inertial>
      <mass value="1E-6"/>
      <inertia ixx="1E-6" ixy="0" ixz="0" iyy="1E-6" iyz="0" izz="1E-6"/>
    </inertial>
  </link>
  <joint name="right/finger_3/med_joint" type="revolute">
    <parent link="right/bhand_palm_link"/>
    <child link="right/finger_3/med_link"/>
    <origin rpy="1.57079632679 0 1.57079632679" xyz="0 0.05 0.0754"/>
    <axis xyz="0 0 1"/>
    <limit effort="30" lower="0" upper="2.44346095279" velocity="10.00"/>
    <dynamics damping="0.35" friction="0"/>
  </joint>
  <gazebo reference="right/finger_3/med_joint">
    <provideFeedback>true</provideFeedback>
    <!--<implicitSpringDamper>true</implicitSpringDamper>-->
    <!--<kp>100</kp>-->
    <!--<kd>0.01</kd>-->
    <!--<kp>0.001</kp>-->
    <!--<kd>0.01</kd>-->
    <!--<stopCfm>0.5</stopCfm>-->
    <!--<stopErp>0.5</stopErp>-->
    <implicitSpringDamper>true</implicitSpringDamper>
  </gazebo>
  <gazebo reference="right/finger_3/med_link">
    <mu1>1</mu1><!-- 0.5 -->
    <mu2>1</mu2>
    <maxContacts>1</maxContacts>
    <!--<kp>5000</kp>-->
    <!--<kd>0.02</kd>-->
    <!--<kp>3000</kp>-->
    <kd>0.1</kd>
    <visual name="visual_shiny">
      <material>
        <script>
          <uri>/home/dwigand/code/cogimon/CoSimA/repos/ROS_WORKSPACE/src/barrett_model/materials/barrett.material</uri>
          <name>Wam/Aluminum</name>
        </script>
      </material>
    </visual>
  </gazebo>
  <link name="right/finger_3/med_link">
    <inertial>
      <origin xyz="0.023133 0.00078642 0.00052792"/>
      <mass value="0.062139"/>
      <inertia ixx="4.872e-006" ixy="1.7103e-006" ixz="3.4041e-008" iyy="7.6588e-005" iyz="2.3133e-008" izz="7.7733e-005"/>
    </inertial>
    <visual>
      <material name="WAMGrey">
        <color rgba="0.9 0.9 0.9 0.0"/>
      </material>
      <geometry>
        <mesh filename="/home/dwigand/code/cogimon/CoSimA/repos/ROS_WORKSPACE/src/barrett_model/models/sw_meshes/bhand/bhand_finger_med_link_fine.stl"/>
      </geometry>
    </visual>
    <!-- spine -->
    <collision>
      <origin xyz="0.03493 0.003 -0.0007"/>
      <geometry>
        <box size="0.07 0.019 0.006"/>
      </geometry>
    </collision>
    <!-- protrusion -->
    <collision>
      <origin xyz="0.03894 0.00376 -0.0007"/>
      <geometry>
        <box size="0.031 0.023 0.019"/>
      </geometry>
      <surface>
        <friction>
          <ode>
            <mu>1</mu>
            <mu2>1</mu2>
          </ode>
        </friction>
      </surface>
    </collision>
  </link>
  <joint name="right/finger_3/dist_joint" type="revolute">
    <parent link="right/finger_3/med_link"/>
    <child link="right/finger_3/dist_link"/>
    <origin rpy="0 0 0.785398163397" xyz="0.06994 0.003 0.0"/>
    <axis xyz="0 0 1"/>
    <limit effort="30" lower="0" upper="0.837758040957" velocity="10.00"/>
    <dynamics damping="0.35" friction="0"/>
  </joint>
  <gazebo reference="right/finger_3/dist_joint">
    <provideFeedback>true</provideFeedback>
    <!--<implicitSpringDamper>true</implicitSpringDamper>-->
    <!--<kp>100</kp>-->
    <!--<kd>0.01</kd>-->
    <!--<kp>0.001</kp>-->
    <!--<kd>0.01</kd>-->
    <!--<stopCfm>0.5</stopCfm>-->
    <!--<stopErp>0.5</stopErp>-->
    <implicitSpringDamper>true</implicitSpringDamper>
  </gazebo>
  <gazebo reference="right/finger_3/dist_link">
    <mu1>1</mu1><!-- 0.5 -->
    <mu2>1</mu2>
    <maxContacts>1</maxContacts>
    <selfCollide>false</selfCollide>
    <!--<kp>5000</kp>-->
    <!--<kd>0.02</kd>-->
    <!--<kp>3000</kp>-->
    <kd>0.1</kd>
    <visual name="visual_shiny">
      <material>
        <script>
          <uri>/home/dwigand/code/cogimon/CoSimA/repos/ROS_WORKSPACE/src/barrett_model/materials/barrett.material</uri>
          <name>Wam/Aluminum</name>
        </script>
      </material>
    </visual>
  </gazebo>
  <link name="right/finger_3/dist_link">
    <inertial>
      <origin rpy="0 0 0" xyz="0.022825 0.0010491 0.0004203"/>
      <mass value="0.041377"/>
      <inertia ixx="3.1582e-006" ixy="1.4308e-006" ixz="1.0106e-007" iyy="3.8376e-005" iyz="0" izz="3.7275e-005"/>
    </inertial>
    <visual>
      <origin rpy="0 0 -0.785398163397"/>
      <material name="WAMGrey">
        <color rgba="0.9 0.9 0.9 0.0"/>
      </material>
      <geometry>
        <mesh filename="/home/dwigand/code/cogimon/CoSimA/repos/ROS_WORKSPACE/src/barrett_model/models/sw_meshes/bhand/bhand_finger_dist_link_fine.stl"/>
      </geometry>
    </visual>
    <collision>
      <origin rpy="0 0 -0.785398163397"/>
      <geometry>
        <mesh filename="/home/dwigand/code/cogimon/CoSimA/repos/ROS_WORKSPACE/src/barrett_model/models/sw_meshes/bhand/bhand_finger_dist_link_convex.dae"/>
      </geometry>
      <surface>
        <friction>
          <ode>
            <mu>1</mu>
            <mu2>1</mu2>
          </ode>
        </friction>
      </surface>
    </collision>
  </link>
  <joint name="right/finger_3/tip_joint" type="fixed">
    <parent link="right/finger_3/dist_link"/>
    <child link="right/finger_3/tip_link"/>
    <origin rpy="0 0 0" xyz="0.05 0.0 0.0"/>
  </joint>
  <link name="right/finger_3/tip_link">
    <inertial>
      <mass value="1E-6"/>
      <inertia ixx="1E-6" ixy="0" ixz="0" iyy="1E-6" iyz="0" izz="1E-6"/>
    </inertial>
  </link>
<!-- right hand end -->

</robot>